Workbook
Name AN_Vorhaben1: #REF!
Name AN_Vorhaben2: #REF!
Name AN_Vorhaben3: #REF!
Name AN_Vorhaben4: #REF!
Name AN_Vorhaben5: #REF!
Name AN_Vorhaben6: #REF!
Name AN_Vorhaben7: #REF!
Name BeantrFZ2020: #REF!
Name BeantrFZ2021: #REF!
Name BeantrFZ2022: #REF!
Name BeantrFZ2023: #REF!
Name BeantrFZ2024: #REF!
Name BeantrFZ2025: #REF!
Name Bundesland: #REF!
Name CountLines: _xlfn.LAMBDA(_xlpm.Zelle,LEN(_xlpm.Zelle)-LEN(SUBSTITUTE(_xlpm.Zelle,CHAR(10),""))+1)
Name Display_Week: Arbeitsplan!$D$4
Name GetAGBeitrag: _xlfn.LAMBDA(_xlpm.links,_xlpm.rechts,IF(CountLines(_xlpm.links)+CountLines(_xlpm.rechts)=6,GetSteuerbruttoZ3(_xlpm.links)&","&GetSteuerbruttoZ3(_xlpm.rechts),""))
Name GetColOfAry: _xlfn.LAMBDA(_xlpm.targetcol,_xlpm.ary, _xlfn.TAKE(_xlfn.TAKE(_xlpm.ary,,_xlpm.targetcol),,-1) )
Name GetNumbers: _xlfn.LAMBDA(_xlpm.Zelle,SUM(MID(0&_xlpm.Zelle,LARGE(INDEX(ISNUMBER(--MID(_xlpm.Zelle,ROW(#REF!),1))*ROW(#REF!),),ROW(#REF!))+1,1)*10^ROW(#REF!)/10))
Name GewählterMA: #REF!
Name GewähltesVorhaben: #REF!
Name Jahr1: #REF!
Name Jahr2: #REF!
Name Jahr3: #REF!
Name Jahr4: #REF!
Name Jahr5: #REF!
Name Jahr6: #REF!
Name Kosten2020: #REF!
Name Kosten2021: #REF!
Name Kosten2022: #REF!
Name Kosten2023: #REF!
Name Kosten2024: #REF!
Name Kosten2025: #REF!
Name Mitarbeiter: _xlfn.ANCHORARRAY(#REF!)
Name Proj1: #REF!
Name Proj2: #REF!
Name Proj3: #REF!
Name Proj4: #REF!
Name Proj5: #REF!
Name Proj6: #REF!
Name Proj7: #REF!
Name Project_Start: Arbeitsplan!$D$3
Name Steuerland: #REF!
Name Steuernummer_kurz: #REF!
Name Steuernummer_lang: #REF!
Name task_end: #REF!
Name task_start: #REF!
Name WJ: #REF!
Name WJ_2020: #REF!
Name WJ_2021: #REF!
Name WJ_2022: #REF!
Name WJ_2023: #REF!
Name WJ_2024: #REF!
Name WJ_2025: #REF!
Name Year_Valid_V1: #REF!
Name Year_Valid_V2: #REF!
Name Year_Valid_V3: #REF!
Name Year_Valid_V4: #REF!
Name Year_Valid_V5: #REF!
Name Year_Valid_V6: #REF!

Sheet Arbeitsplan
D1: Unternehmen | T1: =D1 -> Unternehmen | U1: Auftragnehmer 1
A3: Markiere UAPs mit "x". | B3: Anzahl Zeichen (max. 150) | C3: AP Nr. (vorlaufend) (je Projektjahr max. 10) | D3: 46024 | AF3: 1 | AG3: 2 | AH3: 3 | AI3: 4 | AJ3: 5 | AK3: 6 | AL3: 7 | AM3: 8 | AN3: 9 | AO3: 10 | AP3: 11 | AQ3: 12 | AR3: 13 | AS3: 14 | AT3: 15 | AU3: 16 | AV3: 17 | AW3: 18 | AX3: 19 | AY3: 20 | AZ3: 21 | BA3: 22 | BB3: 23 | BC3: 24 | BD3: 25 | BE3: 26 | BF3: 27 | BG3: 28 | BH3: 29 | BI3: 30 | BJ3: 31 | BK3: 32 | BL3: 33 | BM3: 34 | BN3: 35 | BO3: 36 | BP3: 37 | BQ3: 38 | BR3: 39 | BS3: 40 | BT3: 41 | BU3: 42 | BV3: 43 | BW3: 44 | BX3: 45 | BY3: 46 | BZ3: 47 | CA3: 48 | CB3: 49 | CC3: 50 | CD3: 51 | CE3: 52 | CF3: 53 | CG3: 54 | CH3: 55 | CI3: 56 | CJ3: 57 | CK3: 58 | CL3: 59 | CM3: 60 | CN3: 61 | CO3: 62 | CP3: 63 | CQ3: 64 | CR3: 65 | CS3: 66 | CT3: 67 | CU3: 68 | CV3: 69 | CW3: 70 | CX3: 71 | CY3: 72 | CZ3: 73 | DA3: 74 | DB3: 75 | DC3: 76 | DD3: 77 | DE3: 78 | DF3: 79 | DG3: 80 | DH3: 81 | DI3: 82 | DJ3: 83 | DK3: 84 | DO3: Nebenrechnungen für Gewichtungen Mitarbeiter (nicht anfassen) | EQ3: Nebenrechnungen für Gewichtungen Eigenleistung (nicht anfassen)
D4: Blau: Arbeitspakete (AP X) werden nicht eingereicht Grau: Unterarbeitspakete (UAP X.X) werden eingereicht | F4: Projektlaufzeit in Monaten | I4: Projektlaufzeit als Datum | L4: Personalaufwand in PM (1 PM=142h) | P4: Eigenleistungen in h | AF4: =YEAR(AF5) -> 2026 | AG4: =YEAR(AG5) -> 2026 | AH4: =YEAR(AH5) -> 2026 | AI4: =YEAR(AI5) -> 2026 | AJ4: =YEAR(AJ5) -> 2026 | AK4: =YEAR(AK5) -> 2026 | AL4: =YEAR(AL5) -> 2026 | AM4: =YEAR(AM5) -> 2026 | ... DK4: =YEAR(DK5) -> 2032 | DO4: Anzahl Monate je AP und Jahresscheibe | DX4: Anzahl Monate je UAP und Jahresscheibe | EG4: UAP gewichtet nach AP-Aufwand | EQ4: Anzahl Monate je AP und Jahresscheibe | EZ4: Anzahl Monate je UAP und Jahresscheibe | FI4: UAP gewichtet nach AP-Aufwand
D5: PROGRAMM / PHASE | F5: START Monat | G5: ENDE Monat | I5: START Datum | J5: ENDE Datum | L5: Gewicht | M5: PM | N5: Prozent | P5: Gewicht | Q5: h | R5: Prozent | AF5: =DATE(YEAR(Project_Start),MONTH(Project_Start),1) -> 46023 | AG5: =EOMONTH(AF5,0)+1 -> 46054 | AH5: =EOMONTH(AG5,0)+1 -> 46082 | AI5: =EOMONTH(AH5,0)+1 -> 46113 | AJ5: =EOMONTH(AI5,0)+1 -> 46143 | AK5: =EOMONTH(AJ5,0)+1 -> 46174 | AL5: =EOMONTH(AK5,0)+1 -> 46204 | AM5: =EOMONTH(AL5,0)+1 -> 46235 | AN5: =EOMONTH(AM5,0)+1 -> 46266 | ... DK5: =EOMONTH(DJ5,0)+1 -> 48549 | DP5: =Jahresscheiben!C$2 -> 2026 | DQ5: =Jahresscheiben!D$2 -> 2027 | DR5: =Jahresscheiben!E$2 -> 2028 | DS5: =Jahresscheiben!F$2 -> 2029 | DT5: =Jahresscheiben!G$2 -> 2030 | DU5: =Jahresscheiben!H$2 -> 2031 | DV5: =Jahresscheiben!I$2 -> 2032 | DY5: =Jahresscheiben!C$2 -> 2026 | DZ5: =Jahresscheiben!D$2 -> 2027 | EA5: =Jahresscheiben!E$2 -> 2028 | EB5: =Jahresscheiben!F$2 -> 2029 | EC5: =Jahresscheiben!G$2 -> 2030 | ED5: =Jahresscheiben!H$2 -> 2031 | EE5: =Jahresscheiben!I$2 -> 2032 | EH5: =Jahresscheiben!C$2 -> 2026 | EI5: =Jahresscheiben!D$2 -> 2027 | EJ5: =Jahresscheiben!E$2 -> 2028 | EK5: =Jahresscheiben!F$2 -> 2029 | EL5: =Jahresscheiben!G$2 -> 2030 | EM5: =Jahresscheiben!H$2 -> 2031 | EN5: =Jahresscheiben!I$2 -> 2032 | ER5: =Jahresscheiben!C$2 -> 2026 | ES5: =Jahresscheiben!D$2 -> 2027 | ET5: =Jahresscheiben!E$2 -> 2028 | EU5: =Jahresscheiben!F$2 -> 2029 | EV5: =Jahresscheiben!G$2 -> 2030 | EW5: =Jahresscheiben!H$2 -> 2031 | EX5: =Jahresscheiben!I$2 -> 2032 | FA5: =Jahresscheiben!C$2 -> 2026 | FB5: =Jahresscheiben!D$2 -> 2027 | FC5: =Jahresscheiben!E$2 -> 2028 | FD5: =Jahresscheiben!F$2 -> 2029 | FE5: =Jahresscheiben!G$2 -> 2030 | FF5: =Jahresscheiben!H$2 -> 2031 | FG5: =Jahresscheiben!I$2 -> 2032 | FJ5: =Jahresscheiben!C$2 -> 2026 | FK5: =Jahresscheiben!D$2 -> 2027 | FL5: =Jahresscheiben!E$2 -> 2028 | FM5: =Jahresscheiben!F$2 -> 2029 | FN5: =Jahresscheiben!G$2 -> 2030 | FO5: =Jahresscheiben!H$2 -> 2031 | FP5: =Jahresscheiben!I$2 -> 2032
B6: =LEN(D6) -> 133 | C6: =ROW()-5 -> 1 | D6: AP1 Systemarchitektur und Versuchsrahmen für den Funktionsprototyp durch die Projektleitung mit messbaren Zielgrenzen (Systemanalyse) | F6: 1 | G6: 5 | I6: =IF(F6=0,"",EOMONTH(Project_Start,F6-1)) -> 46053 | J6: =IF(G6=0,"",EOMONTH(Project_Start,G6-1)) -> 46173 | L6: 5 | M6: {=_xlfn.LET( _xlpm.Z, _xlfn._xlws.FILTER($DY$6:$EE$65,$DX$6:$DX$65=C6), _xlpm.Q,_xlfn._xlws.FILTER($DP$6:$DV$65,$DO$6:$DO$65=C6), IF($A6="x",SUMPRODUCT(_xlpm.Z,$DY$73:$EE$73,EH6:EN6),SUMPRODUCT(_xlpm.Q,$DP$73:$DV$73)))} -> 0 | N6: {=_xlfn.LET( _xlpm.Z, SUM(IF($A6="x",_xlfn._xlws.FILTER($M$6:$M$65,$A$6:$A$65="x"),_xlfn._xlws.FILTER($M$6:$M$65,$A$6:$A$65<>"x"))), IF(_xlpm.Z<>0,M6/_xlpm.Z,""))} | P6: =L6 -> 5 | Q6: {=_xlfn.LET( _xlpm.Z, _xlfn._xlws.FILTER($FA$6:$FG$65,$EZ$6:$EZ$65=C6), _xlpm.Q,_xlfn._xlws.FILTER($ER$6:$EX$65,$EQ$6:$EQ$65=C6), IF($A6="x",SUMPRODUCT(_xlpm.Z,$FA$73:$FG$73,FJ6:FP6),SUMPRODUCT(_xlpm.Q,$ER$73:$EX$73)))} -> 0 | R6: {=_xlfn.LET( _xlpm.Z, SUM(IF($A6="x",_xlfn._xlws.FILTER($Q$6:$Q$65,$A$6:$A$65="x"),_xlfn._xlws.FILTER($Q$6:$Q$65,$A$6:$A$65<>"x"))), IF(_xlpm.Z<>0,Q6/_xlpm.Z,""))} | AF6: =_xlfn.LET( _xlpm.project_monat,AF$3, _xlpm.start_monat,$F6, _xlpm.ende_monat,$G6, IF(AND(_xlpm.project_monat>=_xlpm.start_monat,_xlpm.project_monat<=_xlpm.ende_monat),IF($A6="x",2,1),"")) -> 1 | AG6: =_xlfn.LET( _xlpm.project_monat,AG$3, _xlpm.start_monat,$F6, _xlpm.ende_monat,$G6, IF(AND(_xlpm.project_monat>=_xlpm.start_monat,_xlpm.project_monat<=_xlpm.ende_monat),IF($A6="x",2,1),"")) -> 1 | AH6: =_xlfn.LET( _xlpm.project_monat,AH$3, _xlpm.start_monat,$F6, _xlpm.ende_monat,$G6, IF(AND(_xlpm.project_monat>=_xlpm.start_monat,_xlpm.project_monat<=_xlpm.ende_monat),IF($A6="x",2,1),"")) -> 1 | AI6: =_xlfn.LET( _xlpm.project_monat,AI$3, _xlpm.start_monat,$F6, _xlpm.ende_monat,$G6, IF(AND(_xlpm.project_monat>=_xlpm.start_monat,_xlpm.project_monat<=_xlpm.ende_monat),IF($A6="x",2,1),"")) -> 1 | AJ6: =_xlfn.LET( _xlpm.project_monat,AJ$3, _xlpm.start_monat,$F6, _xlpm.ende_monat,$G6, IF(AND(_xlpm.project_monat>=_xlpm.start_monat,_xlpm.project_monat<=_xlpm.ende_monat),IF($A6="x",2,1),"")) -> 1 | AK6: =_xlfn.LET( _xlpm.project_monat,AK$3, _xlpm.start_monat,$F6, _xlpm.ende_monat,$G6, IF(AND(_xlpm.project_monat>=_xlpm.start_monat,_xlpm.project_monat<=_xlpm.ende_monat),IF($A6="x",2,1),"")) | AL6: =_xlfn.LET( _xlpm.project_monat,AL$3, _xlpm.start_monat,$F6, _xlpm.ende_monat,$G6, IF(AND(_xlpm.project_monat>=_xlpm.start_monat,_xlpm.project_monat<=_xlpm.ende_monat),IF($A6="x",2,1),"")) | AM6: =_xlfn.LET( _xlpm.project_monat,AM$3, _xlpm.start_monat,$F6, _xlpm.ende_monat,$G6, IF(AND(_xlpm.project_monat>=_xlpm.start_monat,_xlpm.project_monat<=_xlpm.ende_monat),IF($A6="x",2,1),"")) | ... DK6: =_xlfn.LET( _xlpm.project_monat,DK$3, _xlpm.start_monat,$F6, _xlpm.ende_monat,$G6, IF(AND(_xlpm.project_monat>=_xlpm.start_monat,_xlpm.project_monat<=_xlpm.ende_monat),IF($A6="x",2,1),"")) | DO6: =$C6 -> 1 | DP6: =IF($A6<>"x",$L6*SUMIFS($AF6:$DK6,$AF$4:$DK$4,Jahresscheiben!C$2),0) -> 25 | DQ6: =IF($A6<>"x",$L6*SUMIFS($AF6:$DK6,$AF$4:$DK$4,Jahresscheiben!D$2),0) -> 0 | DR6: =IF($A6<>"x",$L6*SUMIFS($AF6:$DK6,$AF$4:$DK$4,Jahresscheiben!E$2),0) -> 0 | DS6: =IF($A6<>"x",$L6*SUMIFS($AF6:$DK6,$AF$4:$DK$4,Jahresscheiben!F$2),0) -> 0 | DT6: =IF($A6<>"x",$L6*SUMIFS($AF6:$DK6,$AF$4:$DK$4,Jahresscheiben!G$2),0) -> 0 | DU6: =IF($A6<>"x",$L6*SUMIFS($AF6:$DK6,$AF$4:$DK$4,Jahresscheiben!H$2),0) -> 0 | DV6: =IF($A6<>"x",$L6*SUMIFS($AF6:$DK6,$AF$4:$DK$4,Jahresscheiben!I$2),0) -> 0 | DX6: =$C6 -> 1 | DY6: =IF($A6="x",$L6*SUMIFS($AF6:$DK6,$AF$4:$DK$4,Jahresscheiben!C$2)/2,0) -> 0 | DZ6: =IF($A6="x",$L6*SUMIFS($AF6:$DK6,$AF$4:$DK$4,Jahresscheiben!D$2)/2,0) -> 0 | EA6: =IF($A6="x",$L6*SUMIFS($AF6:$DK6,$AF$4:$DK$4,Jahresscheiben!E$2)/2,0) -> 0 | EB6: =IF($A6="x",$L6*SUMIFS($AF6:$DK6,$AF$4:$DK$4,Jahresscheiben!F$2)/2,0) -> 0 | EC6: =IF($A6="x",$L6*SUMIFS($AF6:$DK6,$AF$4:$DK$4,Jahresscheiben!G$2)/2,0) -> 0 | ED6: =IF($A6="x",$L6*SUMIFS($AF6:$DK6,$AF$4:$DK$4,Jahresscheiben!H$2)/2,0) -> 0 | EE6: =IF($A6="x",$L6*SUMIFS($AF6:$DK6,$AF$4:$DK$4,Jahresscheiben!I$2)/2,0) -> 0 | EG6: =$C6 -> 1 | EH6: {=_xlfn.LET(_xlpm.r,ROW($A$6:$A$65), _xlpm.i,ROW(), _xlpm.top,MAX(_xlfn._xlws.FILTER(_xlpm.r,($A$6:$A$65<>"x")*(_xlpm.r<=_xlpm.i))), _xlpm.tmp,MIN(_xlfn._xlws.FILTER(_xlpm.r,($A$6:$A$65<>"x")*(_xlpm.r>=_xlpm.i))), _xlpm.bot,IF(ISERROR(_xlpm.tmp),MAX(_xlpm.r),_xlpm.tmp), IF(_xlpm.bot=_xlpm.top,0,IF(DP$72,IF(SUM(_xlfn._xlws.FILTER(DY$6:DY$65,(_xlpm.r>_xlpm.top)*(_xlpm.r<_xlpm.bot))),1/SUM(_xlfn._xlws.FILTER(DY$6:DY$65,(_xlpm.r>_xlpm.top)*(_xlpm.r<_xlpm.bot)))*DY$72*INDEX(DP:DP,_xlpm.top)/DP$72,0),0)))} -> 0 | EI6: {=_xlfn.LET(_xlpm.r,ROW($A$6:$A$65), _xlpm.i,ROW(), _xlpm.top,MAX(_xlfn._xlws.FILTER(_xlpm.r,($A$6:$A$65<>"x")*(_xlpm.r<=_xlpm.i))), _xlpm.tmp,MIN(_xlfn._xlws.FILTER(_xlpm.r,($A$6:$A$65<>"x")*(_xlpm.r>=_xlpm.i))), _xlpm.bot,IF(ISERROR(_xlpm.tmp),MAX(_xlpm.r),_xlpm.tmp), IF(_xlpm.bot=_xlpm.top,0,IF(DQ$72,IF(SUM(_xlfn._xlws.FILTER(DZ$6:DZ$65,(_xlpm.r>_xlpm.top)*(_xlpm.r<_xlpm.bot))),1/SUM(_xlfn._xlws.FILTER(DZ$6:DZ$65,(_xlpm.r>_xlpm.top)*(_xlpm.r<_xlpm.bot)))*DZ$72*INDEX(DQ:DQ,_xlpm.top)/DQ$72,0),0)))} -> 0 | EJ6: {=_xlfn.LET(_xlpm.r,ROW($A$6:$A$65), _xlpm.i,ROW(), _xlpm.top,MAX(_xlfn._xlws.FILTER(_xlpm.r,($A$6:$A$65<>"x")*(_xlpm.r<=_xlpm.i))), _xlpm.tmp,MIN(_xlfn._xlws.FILTER(_xlpm.r,($A$6:$A$65<>"x")*(_xlpm.r>=_xlpm.i))), _xlpm.bot,IF(ISERROR(_xlpm.tmp),MAX(_xlpm.r),_xlpm.tmp), IF(_xlpm.bot=_xlpm.top,0,IF(DR$72,IF(SUM(_xlfn._xlws.FILTER(EA$6:EA$65,(_xlpm.r>_xlpm.top)*(_xlpm.r<_xlpm.bot))),1/SUM(_xlfn._xlws.FILTER(EA$6:EA$65,(_xlpm.r>_xlpm.top)*(_xlpm.r<_xlpm.bot)))*EA$72*INDEX(DR:DR,_xlpm.top)/DR$72,0),0)))} -> 0 | EK6: {=_xlfn.LET(_xlpm.r,ROW($A$6:$A$65), _xlpm.i,ROW(), _xlpm.top,MAX(_xlfn._xlws.FILTER(_xlpm.r,($A$6:$A$65<>"x")*(_xlpm.r<=_xlpm.i))), _xlpm.tmp,MIN(_xlfn._xlws.FILTER(_xlpm.r,($A$6:$A$65<>"x")*(_xlpm.r>=_xlpm.i))), _xlpm.bot,IF(ISERROR(_xlpm.tmp),MAX(_xlpm.r),_xlpm.tmp), IF(_xlpm.bot=_xlpm.top,0,IF(DS$72,IF(SUM(_xlfn._xlws.FILTER(EB$6:EB$65,(_xlpm.r>_xlpm.top)*(_xlpm.r<_xlpm.bot))),1/SUM(_xlfn._xlws.FILTER(EB$6:EB$65,(_xlpm.r>_xlpm.top)*(_xlpm.r<_xlpm.bot)))*EB$72*INDEX(DS:DS,_xlpm.top)/DS$72,0),0)))} -> 0 | EL6: {=_xlfn.LET(_xlpm.r,ROW($A$6:$A$65), _xlpm.i,ROW(), _xlpm.top,MAX(_xlfn._xlws.FILTER(_xlpm.r,($A$6:$A$65<>"x")*(_xlpm.r<=_xlpm.i))), _xlpm.tmp,MIN(_xlfn._xlws.FILTER(_xlpm.r,($A$6:$A$65<>"x")*(_xlpm.r>=_xlpm.i))), _xlpm.bot,IF(ISERROR(_xlpm.tmp),MAX(_xlpm.r),_xlpm.tmp), IF(_xlpm.bot=_xlpm.top,0,IF(DT$72,IF(SUM(_xlfn._xlws.FILTER(EC$6:EC$65,(_xlpm.r>_xlpm.top)*(_xlpm.r<_xlpm.bot))),1/SUM(_xlfn._xlws.FILTER(EC$6:EC$65,(_xlpm.r>_xlpm.top)*(_xlpm.r<_xlpm.bot)))*EC$72*INDEX(DT:DT,_xlpm.top)/DT$72,0),0)))} -> 0 | EM6: {=_xlfn.LET(_xlpm.r,ROW($A$6:$A$65), _xlpm.i,ROW(), _xlpm.top,MAX(_xlfn._xlws.FILTER(_xlpm.r,($A$6:$A$65<>"x")*(_xlpm.r<=_xlpm.i))), _xlpm.tmp,MIN(_xlfn._xlws.FILTER(_xlpm.r,($A$6:$A$65<>"x")*(_xlpm.r>=_xlpm.i))), _xlpm.bot,IF(ISERROR(_xlpm.tmp),MAX(_xlpm.r),_xlpm.tmp), IF(_xlpm.bot=_xlpm.top,0,IF(DU$72,IF(SUM(_xlfn._xlws.FILTER(ED$6:ED$65,(_xlpm.r>_xlpm.top)*(_xlpm.r<_xlpm.bot))),1/SUM(_xlfn._xlws.FILTER(ED$6:ED$65,(_xlpm.r>_xlpm.top)*(_xlpm.r<_xlpm.bot)))*ED$72*INDEX(DU:DU,_xlpm.top)/DU$72,0),0)))} -> 0 | EN6: {=_xlfn.LET(_xlpm.r,ROW($A$6:$A$65), _xlpm.i,ROW(), _xlpm.top,MAX(_xlfn._xlws.FILTER(_xlpm.r,($A$6:$A$65<>"x")*(_xlpm.r<=_xlpm.i))), _xlpm.tmp,MIN(_xlfn._xlws.FILTER(_xlpm.r,($A$6:$A$65<>"x")*(_xlpm.r>=_xlpm.i))), _xlpm.bot,IF(ISERROR(_xlpm.tmp),MAX(_xlpm.r),_xlpm.tmp), IF(_xlpm.bot=_xlpm.top,0,IF(DV$72,IF(SUM(_xlfn._xlws.FILTER(EE$6:EE$65,(_xlpm.r>_xlpm.top)*(_xlpm.r<_xlpm.bot))),1/SUM(_xlfn._xlws.FILTER(EE$6:EE$65,(_xlpm.r>_xlpm.top)*(_xlpm.r<_xlpm.bot)))*EE$72*INDEX(DV:DV,_xlpm.top)/DV$72,0),0)))} -> 0 | EQ6: =$C6 -> 1 | ER6: =IF($A6<>"x",$P6*SUMIFS($AF6:$DK6,$AF$4:$DK$4,Jahresscheiben!C$2),0) -> 25 | ES6: =IF($A6<>"x",$P6*SUMIFS($AF6:$DK6,$AF$4:$DK$4,Jahresscheiben!D$2),0) -> 0 | ET6: =IF($A6<>"x",$P6*SUMIFS($AF6:$DK6,$AF$4:$DK$4,Jahresscheiben!E$2),0) -> 0 | EU6: =IF($A6<>"x",$P6*SUMIFS($AF6:$DK6,$AF$4:$DK$4,Jahresscheiben!F$2),0) -> 0 | EV6: =IF($A6<>"x",$P6*SUMIFS($AF6:$DK6,$AF$4:$DK$4,Jahresscheiben!G$2),0) -> 0 | EW6: =IF($A6<>"x",$P6*SUMIFS($AF6:$DK6,$AF$4:$DK$4,Jahresscheiben!H$2),0) -> 0 | EX6: =IF($A6<>"x",$P6*SUMIFS($AF6:$DK6,$AF$4:$DK$4,Jahresscheiben!I$2),0) -> 0 | EZ6: =$C6 -> 1 | FA6: =IF($A6="x",$P6*SUMIFS($AF6:$DK6,$AF$4:$DK$4,Jahresscheiben!C$2)/2,0) -> 0 | FB6: =IF($A6="x",$P6*SUMIFS($AF6:$DK6,$AF$4:$DK$4,Jahresscheiben!D$2)/2,0) -> 0 | FC6: =IF($A6="x",$P6*SUMIFS($AF6:$DK6,$AF$4:$DK$4,Jahresscheiben!E$2)/2,0) -> 0 | FD6: =IF($A6="x",$P6*SUMIFS($AF6:$DK6,$AF$4:$DK$4,Jahresscheiben!F$2)/2,0) -> 0 | FE6: =IF($A6="x",$P6*SUMIFS($AF6:$DK6,$AF$4:$DK$4,Jahresscheiben!G$2)/2,0) -> 0 | FF6: =IF($A6="x",$P6*SUMIFS($AF6:$DK6,$AF$4:$DK$4,Jahresscheiben!H$2)/2,0) -> 0 | FG6: =IF($A6="x",$P6*SUMIFS($AF6:$DK6,$AF$4:$DK$4,Jahresscheiben!I$2)/2,0) -> 0 | FI6: =$C6 -> 1 | FJ6: {=_xlfn.LET(_xlpm.r,ROW($A$6:$A$65), _xlpm.i,ROW(), _xlpm.top,MAX(_xlfn._xlws.FILTER(_xlpm.r,($A$6:$A$65<>"x")*(_xlpm.r<=_xlpm.i))), _xlpm.tmp,MIN(_xlfn._xlws.FILTER(_xlpm.r,($A$6:$A$65<>"x")*(_xlpm.r>=_xlpm.i))), _xlpm.bot,IF(ISERROR(_xlpm.tmp),MAX(_xlpm.r),_xlpm.tmp), IF(_xlpm.bot=_xlpm.top,0,IF(ER$72,IF(SUM(_xlfn._xlws.FILTER(FA$6:FA$65,(_xlpm.r>_xlpm.top)*(_xlpm.r<_xlpm.bot))),1/SUM(_xlfn._xlws.FILTER(FA$6:FA$65,(_xlpm.r>_xlpm.top)*(_xlpm.r<_xlpm.bot)))*FA$72*INDEX(ER:ER,_xlpm.top)/ER$72,0),0)))} -> 0 | FK6: {=_xlfn.LET(_xlpm.r,ROW($A$6:$A$65), _xlpm.i,ROW(), _xlpm.top,MAX(_xlfn._xlws.FILTER(_xlpm.r,($A$6:$A$65<>"x")*(_xlpm.r<=_xlpm.i))), _xlpm.tmp,MIN(_xlfn._xlws.FILTER(_xlpm.r,($A$6:$A$65<>"x")*(_xlpm.r>=_xlpm.i))), _xlpm.bot,IF(ISERROR(_xlpm.tmp),MAX(_xlpm.r),_xlpm.tmp), IF(_xlpm.bot=_xlpm.top,0,IF(ES$72,IF(SUM(_xlfn._xlws.FILTER(FB$6:FB$65,(_xlpm.r>_xlpm.top)*(_xlpm.r<_xlpm.bot))),1/SUM(_xlfn._xlws.FILTER(FB$6:FB$65,(_xlpm.r>_xlpm.top)*(_xlpm.r<_xlpm.bot)))*FB$72*INDEX(ES:ES,_xlpm.top)/ES$72,0),0)))} -> 0 | FL6: {=_xlfn.LET(_xlpm.r,ROW($A$6:$A$65), _xlpm.i,ROW(), _xlpm.top,MAX(_xlfn._xlws.FILTER(_xlpm.r,($A$6:$A$65<>"x")*(_xlpm.r<=_xlpm.i))), _xlpm.tmp,MIN(_xlfn._xlws.FILTER(_xlpm.r,($A$6:$A$65<>"x")*(_xlpm.r>=_xlpm.i))), _xlpm.bot,IF(ISERROR(_xlpm.tmp),MAX(_xlpm.r),_xlpm.tmp), IF(_xlpm.bot=_xlpm.top,0,IF(ET$72,IF(SUM(_xlfn._xlws.FILTER(FC$6:FC$65,(_xlpm.r>_xlpm.top)*(_xlpm.r<_xlpm.bot))),1/SUM(_xlfn._xlws.FILTER(FC$6:FC$65,(_xlpm.r>_xlpm.top)*(_xlpm.r<_xlpm.bot)))*FC$72*INDEX(ET:ET,_xlpm.top)/ET$72,0),0)))} -> 0 | FM6: {=_xlfn.LET(_xlpm.r,ROW($A$6:$A$65), _xlpm.i,ROW(), _xlpm.top,MAX(_xlfn._xlws.FILTER(_xlpm.r,($A$6:$A$65<>"x")*(_xlpm.r<=_xlpm.i))), _xlpm.tmp,MIN(_xlfn._xlws.FILTER(_xlpm.r,($A$6:$A$65<>"x")*(_xlpm.r>=_xlpm.i))), _xlpm.bot,IF(ISERROR(_xlpm.tmp),MAX(_xlpm.r),_xlpm.tmp), IF(_xlpm.bot=_xlpm.top,0,IF(EU$72,IF(SUM(_xlfn._xlws.FILTER(FD$6:FD$65,(_xlpm.r>_xlpm.top)*(_xlpm.r<_xlpm.bot))),1/SUM(_xlfn._xlws.FILTER(FD$6:FD$65,(_xlpm.r>_xlpm.top)*(_xlpm.r<_xlpm.bot)))*FD$72*INDEX(EU:EU,_xlpm.top)/EU$72,0),0)))} -> 0 | FN6: {=_xlfn.LET(_xlpm.r,ROW($A$6:$A$65), _xlpm.i,ROW(), _xlpm.top,MAX(_xlfn._xlws.FILTER(_xlpm.r,($A$6:$A$65<>"x")*(_xlpm.r<=_xlpm.i))), _xlpm.tmp,MIN(_xlfn._xlws.FILTER(_xlpm.r,($A$6:$A$65<>"x")*(_xlpm.r>=_xlpm.i))), _xlpm.bot,IF(ISERROR(_xlpm.tmp),MAX(_xlpm.r),_xlpm.tmp), IF(_xlpm.bot=_xlpm.top,0,IF(EV$72,IF(SUM(_xlfn._xlws.FILTER(FE$6:FE$65,(_xlpm.r>_xlpm.top)*(_xlpm.r<_xlpm.bot))),1/SUM(_xlfn._xlws.FILTER(FE$6:FE$65,(_xlpm.r>_xlpm.top)*(_xlpm.r<_xlpm.bot)))*FE$72*INDEX(EV:EV,_xlpm.top)/EV$72,0),0)))} -> 0 | FO6: {=_xlfn.LET(_xlpm.r,ROW($A$6:$A$65), _xlpm.i,ROW(), _xlpm.top,MAX(_xlfn._xlws.FILTER(_xlpm.r,($A$6:$A$65<>"x")*(_xlpm.r<=_xlpm.i))), _xlpm.tmp,MIN(_xlfn._xlws.FILTER(_xlpm.r,($A$6:$A$65<>"x")*(_xlpm.r>=_xlpm.i))), _xlpm.bot,IF(ISERROR(_xlpm.tmp),MAX(_xlpm.r),_xlpm.tmp), IF(_xlpm.bot=_xlpm.top,0,IF(EW$72,IF(SUM(_xlfn._xlws.FILTER(FF$6:FF$65,(_xlpm.r>_xlpm.top)*(_xlpm.r<_xlpm.bot))),1/SUM(_xlfn._xlws.FILTER(FF$6:FF$65,(_xlpm.r>_xlpm.top)*(_xlpm.r<_xlpm.bot)))*FF$72*INDEX(EW:EW,_xlpm.top)/EW$72,0),0)))} -> 0 | FP6: {=_xlfn.LET(_xlpm.r,ROW($A$6:$A$65), _xlpm.i,ROW(), _xlpm.top,MAX(_xlfn._xlws.FILTER(_xlpm.r,($A$6:$A$65<>"x")*(_xlpm.r<=_xlpm.i))), _xlpm.tmp,MIN(_xlfn._xlws.FILTER(_xlpm.r,($A$6:$A$65<>"x")*(_xlpm.r>=_xlpm.i))), _xlpm.bot,IF(ISERROR(_xlpm.tmp),MAX(_xlpm.r),_xlpm.tmp), IF(_xlpm.bot=_xlpm.top,0,IF(EX$72,IF(SUM(_xlfn._xlws.FILTER(FG$6:FG$65,(_xlpm.r>_xlpm.top)*(_xlpm.r<_xlpm.bot))),1/SUM(_xlfn._xlws.FILTER(FG$6:FG$65,(_xlpm.r>_xlpm.top)*(_xlpm.r<_xlpm.bot)))*FG$72*INDEX(EX:EX,_xlpm.top)/EX$72,0),0)))} -> 0
A7: x | B7: =LEN(D7) -> 145 | C7: =ROW()-5 -> 2 | D7: 1.1 Ableitung von Zielwerten für Erkennungsquote, Sammelrate, Kollisionsabstand, Laufzeit und Gewicht aus Nutzungsszenarien (Anforderungsanalyse) | F7: 1 | G7: 2 | I7: =IF(F7=0,"",EOMONTH(Project_Start,F7-1)) -> 46053 | J7: =IF(G7=0,"",EOMONTH(Project_Start,G7-1)) -> 46081 | L7: 4 | M7: {=_xlfn.LET( _xlpm.Z, _xlfn._xlws.FILTER($DY$6:$EE$65,$DX$6:$DX$65=C7), _xlpm.Q,_xlfn._xlws.FILTER($DP$6:$DV$65,$DO$6:$DO$65=C7), IF($A7="x",SUMPRODUCT(_xlpm.Z,$DY$73:$EE$73,EH7:EN7),SUMPRODUCT(_xlpm.Q,$DP$73:$DV$73)))} -> 0 | N7: {=_xlfn.LET( _xlpm.Z, SUM(IF($A7="x",_xlfn._xlws.FILTER($M$6:$M$65,$A$6:$A$65="x"),_xlfn._xlws.FILTER($M$6:$M$65,$A$6:$A$65<>"x"))), IF(_xlpm.Z<>0,M7/_xlpm.Z,""))} | P7: =L7 -> 4 | Q7: {=_xlfn.LET( _xlpm.Z, _xlfn._xlws.FILTER($FA$6:$FG$65,$EZ$6:$EZ$65=C7), _xlpm.Q,_xlfn._xlws.FILTER($ER$6:$EX$65,$EQ$6:$EQ$65=C7), IF($A7="x",SUMPRODUCT(_xlpm.Z,$FA$73:$FG$73,FJ7:FP7),SUMPRODUCT(_xlpm.Q,$ER$73:$EX$73)))} -> 0 | R7: {=_xlfn.LET( _xlpm.Z, SUM(IF($A7="x",_xlfn._xlws.FILTER($Q$6:$Q$65,$A$6:$A$65="x"),_xlfn._xlws.FILTER($Q$6:$Q$65,$A$6:$A$65<>"x"))), IF(_xlpm.Z<>0,Q7/_xlpm.Z,""))} | AF7: =_xlfn.LET( _xlpm.project_monat,AF$3, _xlpm.start_monat,$F7, _xlpm.ende_monat,$G7, IF(AND(_xlpm.project_monat>=_xlpm.start_monat,_xlpm.project_monat<=_xlpm.ende_monat),IF($A7="x",2,1),"")) -> 2 | AG7: =_xlfn.LET( _xlpm.project_monat,AG$3, _xlpm.start_monat,$F7, _xlpm.ende_monat,$G7, IF(AND(_xlpm.project_monat>=_xlpm.start_monat,_xlpm.project_monat<=_xlpm.ende_monat),IF($A7="x",2,1),"")) -> 2 | AH7: =_xlfn.LET( _xlpm.project_monat,AH$3, _xlpm.start_monat,$F7, _xlpm.ende_monat,$G7, IF(AND(_xlpm.project_monat>=_xlpm.start_monat,_xlpm.project_monat<=_xlpm.ende_monat),IF($A7="x",2,1),"")) | AI7: =_xlfn.LET( _xlpm.project_monat,AI$3, _xlpm.start_monat,$F7, _xlpm.ende_monat,$G7, IF(AND(_xlpm.project_monat>=_xlpm.start_monat,_xlpm.project_monat<=_xlpm.ende_monat),IF($A7="x",2,1),"")) | AJ7: =_xlfn.LET( _xlpm.project_monat,AJ$3, _xlpm.start_monat,$F7, _xlpm.ende_monat,$G7, IF(AND(_xlpm.project_monat>=_xlpm.start_monat,_xlpm.project_monat<=_xlpm.ende_monat),IF($A7="x",2,1),"")) | AK7: =_xlfn.LET( _xlpm.project_monat,AK$3, _xlpm.start_monat,$F7, _xlpm.ende_monat,$G7, IF(AND(_xlpm.project_monat>=_xlpm.start_monat,_xlpm.project_monat<=_xlpm.ende_monat),IF($A7="x",2,1),"")) | AL7: =_xlfn.LET( _xlpm.project_monat,AL$3, _xlpm.start_monat,$F7, _xlpm.ende_monat,$G7, IF(AND(_xlpm.project_monat>=_xlpm.start_monat,_xlpm.project_monat<=_xlpm.ende_monat),IF($A7="x",2,1),"")) | AM7: =_xlfn.LET( _xlpm.project_monat,AM$3, _xlpm.start_monat,$F7, _xlpm.ende_monat,$G7, IF(AND(_xlpm.project_monat>=_xlpm.start_monat,_xlpm.project_monat<=_xlpm.ende_monat),IF($A7="x",2,1),"")) | ... DK7: =_xlfn.LET( _xlpm.project_monat,DK$3, _xlpm.start_monat,$F7, _xlpm.ende_monat,$G7, IF(AND(_xlpm.project_monat>=_xlpm.start_monat,_xlpm.project_monat<=_xlpm.ende_monat),IF($A7="x",2,1),"")) | DO7: =$C7 -> 2 | DP7: =IF($A7<>"x",$L7*SUMIFS($AF7:$DK7,$AF$4:$DK$4,Jahresscheiben!C$2),0) -> 0 | DQ7: =IF($A7<>"x",$L7*SUMIFS($AF7:$DK7,$AF$4:$DK$4,Jahresscheiben!D$2),0) -> 0 | DR7: =IF($A7<>"x",$L7*SUMIFS($AF7:$DK7,$AF$4:$DK$4,Jahresscheiben!E$2),0) -> 0 | DS7: =IF($A7<>"x",$L7*SUMIFS($AF7:$DK7,$AF$4:$DK$4,Jahresscheiben!F$2),0) -> 0 | DT7: =IF($A7<>"x",$L7*SUMIFS($AF7:$DK7,$AF$4:$DK$4,Jahresscheiben!G$2),0) -> 0 | DU7: =IF($A7<>"x",$L7*SUMIFS($AF7:$DK7,$AF$4:$DK$4,Jahresscheiben!H$2),0) -> 0 | DV7: =IF($A7<>"x",$L7*SUMIFS($AF7:$DK7,$AF$4:$DK$4,Jahresscheiben!I$2),0) -> 0 | DX7: =$C7 -> 2 | DY7: =IF($A7="x",$L7*SUMIFS($AF7:$DK7,$AF$4:$DK$4,Jahresscheiben!C$2)/2,0) -> 8 | DZ7: =IF($A7="x",$L7*SUMIFS($AF7:$DK7,$AF$4:$DK$4,Jahresscheiben!D$2)/2,0) -> 0 | EA7: =IF($A7="x",$L7*SUMIFS($AF7:$DK7,$AF$4:$DK$4,Jahresscheiben!E$2)/2,0) -> 0 | EB7: =IF($A7="x",$L7*SUMIFS($AF7:$DK7,$AF$4:$DK$4,Jahresscheiben!F$2)/2,0) -> 0 | EC7: =IF($A7="x",$L7*SUMIFS($AF7:$DK7,$AF$4:$DK$4,Jahresscheiben!G$2)/2,0) -> 0 | ED7: =IF($A7="x",$L7*SUMIFS($AF7:$DK7,$AF$4:$DK$4,Jahresscheiben!H$2)/2,0) -> 0 | EE7: =IF($A7="x",$L7*SUMIFS($AF7:$DK7,$AF$4:$DK$4,Jahresscheiben!I$2)/2,0) -> 0 | EG7: =$C7 -> 2 | EH7: {=_xlfn.LET(_xlpm.r,ROW($A$6:$A$65), _xlpm.i,ROW(), _xlpm.top,MAX(_xlfn._xlws.FILTER(_xlpm.r,($A$6:$A$65<>"x")*(_xlpm.r<=_xlpm.i))), _xlpm.tmp,MIN(_xlfn._xlws.FILTER(_xlpm.r,($A$6:$A$65<>"x")*(_xlpm.r>=_xlpm.i))), _xlpm.bot,IF(ISERROR(_xlpm.tmp),MAX(_xlpm.r),_xlpm.tmp), IF(_xlpm.bot=_xlpm.top,0,IF(DP$72,IF(SUM(_xlfn._xlws.FILTER(DY$6:DY$65,(_xlpm.r>_xlpm.top)*(_xlpm.r<_xlpm.bot))),1/SUM(_xlfn._xlws.FILTER(DY$6:DY$65,(_xlpm.r>_xlpm.top)*(_xlpm.r<_xlpm.bot)))*DY$72*INDEX(DP:DP,_xlpm.top)/DP$72,0),0)))} -> 0.86076298 | EI7: {=_xlfn.LET(_xlpm.r,ROW($A$6:$A$65), _xlpm.i,ROW(), _xlpm.top,MAX(_xlfn._xlws.FILTER(_xlpm.r,($A$6:$A$65<>"x")*(_xlpm.r<=_xlpm.i))), _xlpm.tmp,MIN(_xlfn._xlws.FILTER(_xlpm.r,($A$6:$A$65<>"x")*(_xlpm.r>=_xlpm.i))), _xlpm.bot,IF(ISERROR(_xlpm.tmp),MAX(_xlpm.r),_xlpm.tmp), IF(_xlpm.bot=_xlpm.top,0,IF(DQ$72,IF(SUM(_xlfn._xlws.FILTER(DZ$6:DZ$65,(_xlpm.r>_xlpm.top)*(_xlpm.r<_xlpm.bot))),1/SUM(_xlfn._xlws.FILTER(DZ$6:DZ$65,(_xlpm.r>_xlpm.top)*(_xlpm.r<_xlpm.bot)))*DZ$72*INDEX(DQ:DQ,_xlpm.top)/DQ$72,0),0)))} -> 0 | EJ7: {=_xlfn.LET(_xlpm.r,ROW($A$6:$A$65), _xlpm.i,ROW(), _xlpm.top,MAX(_xlfn._xlws.FILTER(_xlpm.r,($A$6:$A$65<>"x")*(_xlpm.r<=_xlpm.i))), _xlpm.tmp,MIN(_xlfn._xlws.FILTER(_xlpm.r,($A$6:$A$65<>"x")*(_xlpm.r>=_xlpm.i))), _xlpm.bot,IF(ISERROR(_xlpm.tmp),MAX(_xlpm.r),_xlpm.tmp), IF(_xlpm.bot=_xlpm.top,0,IF(DR$72,IF(SUM(_xlfn._xlws.FILTER(EA$6:EA$65,(_xlpm.r>_xlpm.top)*(_xlpm.r<_xlpm.bot))),1/SUM(_xlfn._xlws.FILTER(EA$6:EA$65,(_xlpm.r>_xlpm.top)*(_xlpm.r<_xlpm.bot)))*EA$72*INDEX(DR:DR,_xlpm.top)/DR$72,0),0)))} -> 0 | EK7: {=_xlfn.LET(_xlpm.r,ROW($A$6:$A$65), _xlpm.i,ROW(), _xlpm.top,MAX(_xlfn._xlws.FILTER(_xlpm.r,($A$6:$A$65<>"x")*(_xlpm.r<=_xlpm.i))), _xlpm.tmp,MIN(_xlfn._xlws.FILTER(_xlpm.r,($A$6:$A$65<>"x")*(_xlpm.r>=_xlpm.i))), _xlpm.bot,IF(ISERROR(_xlpm.tmp),MAX(_xlpm.r),_xlpm.tmp), IF(_xlpm.bot=_xlpm.top,0,IF(DS$72,IF(SUM(_xlfn._xlws.FILTER(EB$6:EB$65,(_xlpm.r>_xlpm.top)*(_xlpm.r<_xlpm.bot))),1/SUM(_xlfn._xlws.FILTER(EB$6:EB$65,(_xlpm.r>_xlpm.top)*(_xlpm.r<_xlpm.bot)))*EB$72*INDEX(DS:DS,_xlpm.top)/DS$72,0),0)))} -> 0 | EL7: {=_xlfn.LET(_xlpm.r,ROW($A$6:$A$65), _xlpm.i,ROW(), _xlpm.top,MAX(_xlfn._xlws.FILTER(_xlpm.r,($A$6:$A$65<>"x")*(_xlpm.r<=_xlpm.i))), _xlpm.tmp,MIN(_xlfn._xlws.FILTER(_xlpm.r,($A$6:$A$65<>"x")*(_xlpm.r>=_xlpm.i))), _xlpm.bot,IF(ISERROR(_xlpm.tmp),MAX(_xlpm.r),_xlpm.tmp), IF(_xlpm.bot=_xlpm.top,0,IF(DT$72,IF(SUM(_xlfn._xlws.FILTER(EC$6:EC$65,(_xlpm.r>_xlpm.top)*(_xlpm.r<_xlpm.bot))),1/SUM(_xlfn._xlws.FILTER(EC$6:EC$65,(_xlpm.r>_xlpm.top)*(_xlpm.r<_xlpm.bot)))*EC$72*INDEX(DT:DT,_xlpm.top)/DT$72,0),0)))} -> 0 | EM7: {=_xlfn.LET(_xlpm.r,ROW($A$6:$A$65), _xlpm.i,ROW(), _xlpm.top,MAX(_xlfn._xlws.FILTER(_xlpm.r,($A$6:$A$65<>"x")*(_xlpm.r<=_xlpm.i))), _xlpm.tmp,MIN(_xlfn._xlws.FILTER(_xlpm.r,($A$6:$A$65<>"x")*(_xlpm.r>=_xlpm.i))), _xlpm.bot,IF(ISERROR(_xlpm.tmp),MAX(_xlpm.r),_xlpm.tmp), IF(_xlpm.bot=_xlpm.top,0,IF(DU$72,IF(SUM(_xlfn._xlws.FILTER(ED$6:ED$65,(_xlpm.r>_xlpm.top)*(_xlpm.r<_xlpm.bot))),1/SUM(_xlfn._xlws.FILTER(ED$6:ED$65,(_xlpm.r>_xlpm.top)*(_xlpm.r<_xlpm.bot)))*ED$72*INDEX(DU:DU,_xlpm.top)/DU$72,0),0)))} -> 0 | EN7: {=_xlfn.LET(_xlpm.r,ROW($A$6:$A$65), _xlpm.i,ROW(), _xlpm.top,MAX(_xlfn._xlws.FILTER(_xlpm.r,($A$6:$A$65<>"x")*(_xlpm.r<=_xlpm.i))), _xlpm.tmp,MIN(_xlfn._xlws.FILTER(_xlpm.r,($A$6:$A$65<>"x")*(_xlpm.r>=_xlpm.i))), _xlpm.bot,IF(ISERROR(_xlpm.tmp),MAX(_xlpm.r),_xlpm.tmp), IF(_xlpm.bot=_xlpm.top,0,IF(DV$72,IF(SUM(_xlfn._xlws.FILTER(EE$6:EE$65,(_xlpm.r>_xlpm.top)*(_xlpm.r<_xlpm.bot))),1/SUM(_xlfn._xlws.FILTER(EE$6:EE$65,(_xlpm.r>_xlpm.top)*(_xlpm.r<_xlpm.bot)))*EE$72*INDEX(DV:DV,_xlpm.top)/DV$72,0),0)))} -> 0 | EQ7: =$C7 -> 2 | ER7: =IF($A7<>"x",$P7*SUMIFS($AF7:$DK7,$AF$4:$DK$4,Jahresscheiben!C$2),0) -> 0 | ES7: =IF($A7<>"x",$P7*SUMIFS($AF7:$DK7,$AF$4:$DK$4,Jahresscheiben!D$2),0) -> 0 | ET7: =IF($A7<>"x",$P7*SUMIFS($AF7:$DK7,$AF$4:$DK$4,Jahresscheiben!E$2),0) -> 0 | EU7: =IF($A7<>"x",$P7*SUMIFS($AF7:$DK7,$AF$4:$DK$4,Jahresscheiben!F$2),0) -> 0 | EV7: =IF($A7<>"x",$P7*SUMIFS($AF7:$DK7,$AF$4:$DK$4,Jahresscheiben!G$2),0) -> 0 | EW7: =IF($A7<>"x",$P7*SUMIFS($AF7:$DK7,$AF$4:$DK$4,Jahresscheiben!H$2),0) -> 0 | EX7: =IF($A7<>"x",$P7*SUMIFS($AF7:$DK7,$AF$4:$DK$4,Jahresscheiben!I$2),0) -> 0 | EZ7: =$C7 -> 2 | FA7: =IF($A7="x",$P7*SUMIFS($AF7:$DK7,$AF$4:$DK$4,Jahresscheiben!C$2)/2,0) -> 8 | FB7: =IF($A7="x",$P7*SUMIFS($AF7:$DK7,$AF$4:$DK$4,Jahresscheiben!D$2)/2,0) -> 0 | FC7: =IF($A7="x",$P7*SUMIFS($AF7:$DK7,$AF$4:$DK$4,Jahresscheiben!E$2)/2,0) -> 0 | FD7: =IF($A7="x",$P7*SUMIFS($AF7:$DK7,$AF$4:$DK$4,Jahresscheiben!F$2)/2,0) -> 0 | FE7: =IF($A7="x",$P7*SUMIFS($AF7:$DK7,$AF$4:$DK$4,Jahresscheiben!G$2)/2,0) -> 0 | FF7: =IF($A7="x",$P7*SUMIFS($AF7:$DK7,$AF$4:$DK$4,Jahresscheiben!H$2)/2,0) -> 0 | FG7: =IF($A7="x",$P7*SUMIFS($AF7:$DK7,$AF$4:$DK$4,Jahresscheiben!I$2)/2,0) -> 0 | FI7: =$C7 -> 2 | FJ7: {=_xlfn.LET(_xlpm.r,ROW($A$6:$A$65), _xlpm.i,ROW(), _xlpm.top,MAX(_xlfn._xlws.FILTER(_xlpm.r,($A$6:$A$65<>"x")*(_xlpm.r<=_xlpm.i))), _xlpm.tmp,MIN(_xlfn._xlws.FILTER(_xlpm.r,($A$6:$A$65<>"x")*(_xlpm.r>=_xlpm.i))), _xlpm.bot,IF(ISERROR(_xlpm.tmp),MAX(_xlpm.r),_xlpm.tmp), IF(_xlpm.bot=_xlpm.top,0,IF(ER$72,IF(SUM(_xlfn._xlws.FILTER(FA$6:FA$65,(_xlpm.r>_xlpm.top)*(_xlpm.r<_xlpm.bot))),1/SUM(_xlfn._xlws.FILTER(FA$6:FA$65,(_xlpm.r>_xlpm.top)*(_xlpm.r<_xlpm.bot)))*FA$72*INDEX(ER:ER,_xlpm.top)/ER$72,0),0)))} -> 0.86076298 | FK7: {=_xlfn.LET(_xlpm.r,ROW($A$6:$A$65), _xlpm.i,ROW(), _xlpm.top,MAX(_xlfn._xlws.FILTER(_xlpm.r,($A$6:$A$65<>"x")*(_xlpm.r<=_xlpm.i))), _xlpm.tmp,MIN(_xlfn._xlws.FILTER(_xlpm.r,($A$6:$A$65<>"x")*(_xlpm.r>=_xlpm.i))), _xlpm.bot,IF(ISERROR(_xlpm.tmp),MAX(_xlpm.r),_xlpm.tmp), IF(_xlpm.bot=_xlpm.top,0,IF(ES$72,IF(SUM(_xlfn._xlws.FILTER(FB$6:FB$65,(_xlpm.r>_xlpm.top)*(_xlpm.r<_xlpm.bot))),1/SUM(_xlfn._xlws.FILTER(FB$6:FB$65,(_xlpm.r>_xlpm.top)*(_xlpm.r<_xlpm.bot)))*FB$72*INDEX(ES:ES,_xlpm.top)/ES$72,0),0)))} -> 0 | FL7: {=_xlfn.LET(_xlpm.r,ROW($A$6:$A$65), _xlpm.i,ROW(), _xlpm.top,MAX(_xlfn._xlws.FILTER(_xlpm.r,($A$6:$A$65<>"x")*(_xlpm.r<=_xlpm.i))), _xlpm.tmp,MIN(_xlfn._xlws.FILTER(_xlpm.r,($A$6:$A$65<>"x")*(_xlpm.r>=_xlpm.i))), _xlpm.bot,IF(ISERROR(_xlpm.tmp),MAX(_xlpm.r),_xlpm.tmp), IF(_xlpm.bot=_xlpm.top,0,IF(ET$72,IF(SUM(_xlfn._xlws.FILTER(FC$6:FC$65,(_xlpm.r>_xlpm.top)*(_xlpm.r<_xlpm.bot))),1/SUM(_xlfn._xlws.FILTER(FC$6:FC$65,(_xlpm.r>_xlpm.top)*(_xlpm.r<_xlpm.bot)))*FC$72*INDEX(ET:ET,_xlpm.top)/ET$72,0),0)))} -> 0 | FM7: {=_xlfn.LET(_xlpm.r,ROW($A$6:$A$65), _xlpm.i,ROW(), _xlpm.top,MAX(_xlfn._xlws.FILTER(_xlpm.r,($A$6:$A$65<>"x")*(_xlpm.r<=_xlpm.i))), _xlpm.tmp,MIN(_xlfn._xlws.FILTER(_xlpm.r,($A$6:$A$65<>"x")*(_xlpm.r>=_xlpm.i))), _xlpm.bot,IF(ISERROR(_xlpm.tmp),MAX(_xlpm.r),_xlpm.tmp), IF(_xlpm.bot=_xlpm.top,0,IF(EU$72,IF(SUM(_xlfn._xlws.FILTER(FD$6:FD$65,(_xlpm.r>_xlpm.top)*(_xlpm.r<_xlpm.bot))),1/SUM(_xlfn._xlws.FILTER(FD$6:FD$65,(_xlpm.r>_xlpm.top)*(_xlpm.r<_xlpm.bot)))*FD$72*INDEX(EU:EU,_xlpm.top)/EU$72,0),0)))} -> 0 | FN7: {=_xlfn.LET(_xlpm.r,ROW($A$6:$A$65), _xlpm.i,ROW(), _xlpm.top,MAX(_xlfn._xlws.FILTER(_xlpm.r,($A$6:$A$65<>"x")*(_xlpm.r<=_xlpm.i))), _xlpm.tmp,MIN(_xlfn._xlws.FILTER(_xlpm.r,($A$6:$A$65<>"x")*(_xlpm.r>=_xlpm.i))), _xlpm.bot,IF(ISERROR(_xlpm.tmp),MAX(_xlpm.r),_xlpm.tmp), IF(_xlpm.bot=_xlpm.top,0,IF(EV$72,IF(SUM(_xlfn._xlws.FILTER(FE$6:FE$65,(_xlpm.r>_xlpm.top)*(_xlpm.r<_xlpm.bot))),1/SUM(_xlfn._xlws.FILTER(FE$6:FE$65,(_xlpm.r>_xlpm.top)*(_xlpm.r<_xlpm.bot)))*FE$72*INDEX(EV:EV,_xlpm.top)/EV$72,0),0)))} -> 0 | FO7: {=_xlfn.LET(_xlpm.r,ROW($A$6:$A$65), _xlpm.i,ROW(), _xlpm.top,MAX(_xlfn._xlws.FILTER(_xlpm.r,($A$6:$A$65<>"x")*(_xlpm.r<=_xlpm.i))), _xlpm.tmp,MIN(_xlfn._xlws.FILTER(_xlpm.r,($A$6:$A$65<>"x")*(_xlpm.r>=_xlpm.i))), _xlpm.bot,IF(ISERROR(_xlpm.tmp),MAX(_xlpm.r),_xlpm.tmp), IF(_xlpm.bot=_xlpm.top,0,IF(EW$72,IF(SUM(_xlfn._xlws.FILTER(FF$6:FF$65,(_xlpm.r>_xlpm.top)*(_xlpm.r<_xlpm.bot))),1/SUM(_xlfn._xlws.FILTER(FF$6:FF$65,(_xlpm.r>_xlpm.top)*(_xlpm.r<_xlpm.bot)))*FF$72*INDEX(EW:EW,_xlpm.top)/EW$72,0),0)))} -> 0 | FP7: {=_xlfn.LET(_xlpm.r,ROW($A$6:$A$65), _xlpm.i,ROW(), _xlpm.top,MAX(_xlfn._xlws.FILTER(_xlpm.r,($A$6:$A$65<>"x")*(_xlpm.r<=_xlpm.i))), _xlpm.tmp,MIN(_xlfn._xlws.FILTER(_xlpm.r,($A$6:$A$65<>"x")*(_xlpm.r>=_xlpm.i))), _xlpm.bot,IF(ISERROR(_xlpm.tmp),MAX(_xlpm.r),_xlpm.tmp), IF(_xlpm.bot=_xlpm.top,0,IF(EX$72,IF(SUM(_xlfn._xlws.FILTER(FG$6:FG$65,(_xlpm.r>_xlpm.top)*(_xlpm.r<_xlpm.bot))),1/SUM(_xlfn._xlws.FILTER(FG$6:FG$65,(_xlpm.r>_xlpm.top)*(_xlpm.r<_xlpm.bot)))*FG$72*INDEX(EX:EX,_xlpm.top)/EX$72,0),0)))} -> 0
A8: x | B8: =LEN(D8) -> 146 | C8: =ROW()-5 -> 3 | D8: 1.2 Abgrenzung der Forschungsfragen zu Lichtrobustheit, Mehrballaufnahme und gleichzeitiger Erfüllung von Laufzeit und Gewicht (Hypothesenbildung) | F8: 1 | G8: 3 | I8: =IF(F8=0,"",EOMONTH(Project_Start,F8-1)) -> 46053 | J8: =IF(G8=0,"",EOMONTH(Project_Start,G8-1)) -> 46112 | L8: 4 | M8: {=_xlfn.LET( _xlpm.Z, _xlfn._xlws.FILTER($DY$6:$EE$65,$DX$6:$DX$65=C8), _xlpm.Q,_xlfn._xlws.FILTER($DP$6:$DV$65,$DO$6:$DO$65=C8), IF($A8="x",SUMPRODUCT(_xlpm.Z,$DY$73:$EE$73,EH8:EN8),SUMPRODUCT(_xlpm.Q,$DP$73:$DV$73)))} -> 0 | N8: {=_xlfn.LET( _xlpm.Z, SUM(IF($A8="x",_xlfn._xlws.FILTER($M$6:$M$65,$A$6:$A$65="x"),_xlfn._xlws.FILTER($M$6:$M$65,$A$6:$A$65<>"x"))), IF(_xlpm.Z<>0,M8/_xlpm.Z,""))} | P8: =L8 -> 4 | Q8: {=_xlfn.LET( _xlpm.Z, _xlfn._xlws.FILTER($FA$6:$FG$65,$EZ$6:$EZ$65=C8), _xlpm.Q,_xlfn._xlws.FILTER($ER$6:$EX$65,$EQ$6:$EQ$65=C8), IF($A8="x",SUMPRODUCT(_xlpm.Z,$FA$73:$FG$73,FJ8:FP8),SUMPRODUCT(_xlpm.Q,$ER$73:$EX$73)))} -> 0 | R8: {=_xlfn.LET( _xlpm.Z, SUM(IF($A8="x",_xlfn._xlws.FILTER($Q$6:$Q$65,$A$6:$A$65="x"),_xlfn._xlws.FILTER($Q$6:$Q$65,$A$6:$A$65<>"x"))), IF(_xlpm.Z<>0,Q8/_xlpm.Z,""))} | AF8: =_xlfn.LET( _xlpm.project_monat,AF$3, _xlpm.start_monat,$F8, _xlpm.ende_monat,$G8, IF(AND(_xlpm.project_monat>=_xlpm.start_monat,_xlpm.project_monat<=_xlpm.ende_monat),IF($A8="x",2,1),"")) -> 2 | AG8: =_xlfn.LET( _xlpm.project_monat,AG$3, _xlpm.start_monat,$F8, _xlpm.ende_monat,$G8, IF(AND(_xlpm.project_monat>=_xlpm.start_monat,_xlpm.project_monat<=_xlpm.ende_monat),IF($A8="x",2,1),"")) -> 2 | AH8: =_xlfn.LET( _xlpm.project_monat,AH$3, _xlpm.start_monat,$F8, _xlpm.ende_monat,$G8, IF(AND(_xlpm.project_monat>=_xlpm.start_monat,_xlpm.project_monat<=_xlpm.ende_monat),IF($A8="x",2,1),"")) -> 2 | AI8: =_xlfn.LET( _xlpm.project_monat,AI$3, _xlpm.start_monat,$F8, _xlpm.ende_monat,$G8, IF(AND(_xlpm.project_monat>=_xlpm.start_monat,_xlpm.project_monat<=_xlpm.ende_monat),IF($A8="x",2,1),"")) | AJ8: =_xlfn.LET( _xlpm.project_monat,AJ$3, _xlpm.start_monat,$F8, _xlpm.ende_monat,$G8, IF(AND(_xlpm.project_monat>=_xlpm.start_monat,_xlpm.project_monat<=_xlpm.ende_monat),IF($A8="x",2,1),"")) | AK8: =_xlfn.LET( _xlpm.project_monat,AK$3, _xlpm.start_monat,$F8, _xlpm.ende_monat,$G8, IF(AND(_xlpm.project_monat>=_xlpm.start_monat,_xlpm.project_monat<=_xlpm.ende_monat),IF($A8="x",2,1),"")) | AL8: =_xlfn.LET( _xlpm.project_monat,AL$3, _xlpm.start_monat,$F8, _xlpm.ende_monat,$G8, IF(AND(_xlpm.project_monat>=_xlpm.start_monat,_xlpm.project_monat<=_xlpm.ende_monat),IF($A8="x",2,1),"")) | AM8: =_xlfn.LET( _xlpm.project_monat,AM$3, _xlpm.start_monat,$F8, _xlpm.ende_monat,$G8, IF(AND(_xlpm.project_monat>=_xlpm.start_monat,_xlpm.project_monat<=_xlpm.ende_monat),IF($A8="x",2,1),"")) | ... DK8: =_xlfn.LET( _xlpm.project_monat,DK$3, _xlpm.start_monat,$F8, _xlpm.ende_monat,$G8, IF(AND(_xlpm.project_monat>=_xlpm.start_monat,_xlpm.project_monat<=_xlpm.ende_monat),IF($A8="x",2,1),"")) | DO8: =$C8 -> 3 | DP8: =IF($A8<>"x",$L8*SUMIFS($AF8:$DK8,$AF$4:$DK$4,Jahresscheiben!C$2),0) -> 0 | DQ8: =IF($A8<>"x",$L8*SUMIFS($AF8:$DK8,$AF$4:$DK$4,Jahresscheiben!D$2),0) -> 0 | DR8: =IF($A8<>"x",$L8*SUMIFS($AF8:$DK8,$AF$4:$DK$4,Jahresscheiben!E$2),0) -> 0 | DS8: =IF($A8<>"x",$L8*SUMIFS($AF8:$DK8,$AF$4:$DK$4,Jahresscheiben!F$2),0) -> 0 | DT8: =IF($A8<>"x",$L8*SUMIFS($AF8:$DK8,$AF$4:$DK$4,Jahresscheiben!G$2),0) -> 0 | DU8: =IF($A8<>"x",$L8*SUMIFS($AF8:$DK8,$AF$4:$DK$4,Jahresscheiben!H$2),0) -> 0 | DV8: =IF($A8<>"x",$L8*SUMIFS($AF8:$DK8,$AF$4:$DK$4,Jahresscheiben!I$2),0) -> 0 | DX8: =$C8 -> 3 | DY8: =IF($A8="x",$L8*SUMIFS($AF8:$DK8,$AF$4:$DK$4,Jahresscheiben!C$2)/2,0) -> 12 | DZ8: =IF($A8="x",$L8*SUMIFS($AF8:$DK8,$AF$4:$DK$4,Jahresscheiben!D$2)/2,0) -> 0 | EA8: =IF($A8="x",$L8*SUMIFS($AF8:$DK8,$AF$4:$DK$4,Jahresscheiben!E$2)/2,0) -> 0 | EB8: =IF($A8="x",$L8*SUMIFS($AF8:$DK8,$AF$4:$DK$4,Jahresscheiben!F$2)/2,0) -> 0 | EC8: =IF($A8="x",$L8*SUMIFS($AF8:$DK8,$AF$4:$DK$4,Jahresscheiben!G$2)/2,0) -> 0 | ED8: =IF($A8="x",$L8*SUMIFS($AF8:$DK8,$AF$4:$DK$4,Jahresscheiben!H$2)/2,0) -> 0 | EE8: =IF($A8="x",$L8*SUMIFS($AF8:$DK8,$AF$4:$DK$4,Jahresscheiben!I$2)/2,0) -> 0 | EG8: =$C8 -> 3 | EH8: {=_xlfn.LET(_xlpm.r,ROW($A$6:$A$65), _xlpm.i,ROW(), _xlpm.top,MAX(_xlfn._xlws.FILTER(_xlpm.r,($A$6:$A$65<>"x")*(_xlpm.r<=_xlpm.i))), _xlpm.tmp,MIN(_xlfn._xlws.FILTER(_xlpm.r,($A$6:$A$65<>"x")*(_xlpm.r>=_xlpm.i))), _xlpm.bot,IF(ISERROR(_xlpm.tmp),MAX(_xlpm.r),_xlpm.tmp), IF(_xlpm.bot=_xlpm.top,0,IF(DP$72,IF(SUM(_xlfn._xlws.FILTER(DY$6:DY$65,(_xlpm.r>_xlpm.top)*(_xlpm.r<_xlpm.bot))),1/SUM(_xlfn._xlws.FILTER(DY$6:DY$65,(_xlpm.r>_xlpm.top)*(_xlpm.r<_xlpm.bot)))*DY$72*INDEX(DP:DP,_xlpm.top)/DP$72,0),0)))} -> 0.86076298 | EI8: {=_xlfn.LET(_xlpm.r,ROW($A$6:$A$65), _xlpm.i,ROW(), _xlpm.top,MAX(_xlfn._xlws.FILTER(_xlpm.r,($A$6:$A$65<>"x")*(_xlpm.r<=_xlpm.i))), _xlpm.tmp,MIN(_xlfn._xlws.FILTER(_xlpm.r,($A$6:$A$65<>"x")*(_xlpm.r>=_xlpm.i))), _xlpm.bot,IF(ISERROR(_xlpm.tmp),MAX(_xlpm.r),_xlpm.tmp), IF(_xlpm.bot=_xlpm.top,0,IF(DQ$72,IF(SUM(_xlfn._xlws.FILTER(DZ$6:DZ$65,(_xlpm.r>_xlpm.top)*(_xlpm.r<_xlpm.bot))),1/SUM(_xlfn._xlws.FILTER(DZ$6:DZ$65,(_xlpm.r>_xlpm.top)*(_xlpm.r<_xlpm.bot)))*DZ$72*INDEX(DQ:DQ,_xlpm.top)/DQ$72,0),0)))} -> 0 | EJ8: {=_xlfn.LET(_xlpm.r,ROW($A$6:$A$65), _xlpm.i,ROW(), _xlpm.top,MAX(_xlfn._xlws.FILTER(_xlpm.r,($A$6:$A$65<>"x")*(_xlpm.r<=_xlpm.i))), _xlpm.tmp,MIN(_xlfn._xlws.FILTER(_xlpm.r,($A$6:$A$65<>"x")*(_xlpm.r>=_xlpm.i))), _xlpm.bot,IF(ISERROR(_xlpm.tmp),MAX(_xlpm.r),_xlpm.tmp), IF(_xlpm.bot=_xlpm.top,0,IF(DR$72,IF(SUM(_xlfn._xlws.FILTER(EA$6:EA$65,(_xlpm.r>_xlpm.top)*(_xlpm.r<_xlpm.bot))),1/SUM(_xlfn._xlws.FILTER(EA$6:EA$65,(_xlpm.r>_xlpm.top)*(_xlpm.r<_xlpm.bot)))*EA$72*INDEX(DR:DR,_xlpm.top)/DR$72,0),0)))} -> 0 | EK8: {=_xlfn.LET(_xlpm.r,ROW($A$6:$A$65), _xlpm.i,ROW(), _xlpm.top,MAX(_xlfn._xlws.FILTER(_xlpm.r,($A$6:$A$65<>"x")*(_xlpm.r<=_xlpm.i))), _xlpm.tmp,MIN(_xlfn._xlws.FILTER(_xlpm.r,($A$6:$A$65<>"x")*(_xlpm.r>=_xlpm.i))), _xlpm.bot,IF(ISERROR(_xlpm.tmp),MAX(_xlpm.r),_xlpm.tmp), IF(_xlpm.bot=_xlpm.top,0,IF(DS$72,IF(SUM(_xlfn._xlws.FILTER(EB$6:EB$65,(_xlpm.r>_xlpm.top)*(_xlpm.r<_xlpm.bot))),1/SUM(_xlfn._xlws.FILTER(EB$6:EB$65,(_xlpm.r>_xlpm.top)*(_xlpm.r<_xlpm.bot)))*EB$72*INDEX(DS:DS,_xlpm.top)/DS$72,0),0)))} -> 0 | EL8: {=_xlfn.LET(_xlpm.r,ROW($A$6:$A$65), _xlpm.i,ROW(), _xlpm.top,MAX(_xlfn._xlws.FILTER(_xlpm.r,($A$6:$A$65<>"x")*(_xlpm.r<=_xlpm.i))), _xlpm.tmp,MIN(_xlfn._xlws.FILTER(_xlpm.r,($A$6:$A$65<>"x")*(_xlpm.r>=_xlpm.i))), _xlpm.bot,IF(ISERROR(_xlpm.tmp),MAX(_xlpm.r),_xlpm.tmp), IF(_xlpm.bot=_xlpm.top,0,IF(DT$72,IF(SUM(_xlfn._xlws.FILTER(EC$6:EC$65,(_xlpm.r>_xlpm.top)*(_xlpm.r<_xlpm.bot))),1/SUM(_xlfn._xlws.FILTER(EC$6:EC$65,(_xlpm.r>_xlpm.top)*(_xlpm.r<_xlpm.bot)))*EC$72*INDEX(DT:DT,_xlpm.top)/DT$72,0),0)))} -> 0 | EM8: {=_xlfn.LET(_xlpm.r,ROW($A$6:$A$65), _xlpm.i,ROW(), _xlpm.top,MAX(_xlfn._xlws.FILTER(_xlpm.r,($A$6:$A$65<>"x")*(_xlpm.r<=_xlpm.i))), _xlpm.tmp,MIN(_xlfn._xlws.FILTER(_xlpm.r,($A$6:$A$65<>"x")*(_xlpm.r>=_xlpm.i))), _xlpm.bot,IF(ISERROR(_xlpm.tmp),MAX(_xlpm.r),_xlpm.tmp), IF(_xlpm.bot=_xlpm.top,0,IF(DU$72,IF(SUM(_xlfn._xlws.FILTER(ED$6:ED$65,(_xlpm.r>_xlpm.top)*(_xlpm.r<_xlpm.bot))),1/SUM(_xlfn._xlws.FILTER(ED$6:ED$65,(_xlpm.r>_xlpm.top)*(_xlpm.r<_xlpm.bot)))*ED$72*INDEX(DU:DU,_xlpm.top)/DU$72,0),0)))} -> 0 | EN8: {=_xlfn.LET(_xlpm.r,ROW($A$6:$A$65), _xlpm.i,ROW(), _xlpm.top,MAX(_xlfn._xlws.FILTER(_xlpm.r,($A$6:$A$65<>"x")*(_xlpm.r<=_xlpm.i))), _xlpm.tmp,MIN(_xlfn._xlws.FILTER(_xlpm.r,($A$6:$A$65<>"x")*(_xlpm.r>=_xlpm.i))), _xlpm.bot,IF(ISERROR(_xlpm.tmp),MAX(_xlpm.r),_xlpm.tmp), IF(_xlpm.bot=_xlpm.top,0,IF(DV$72,IF(SUM(_xlfn._xlws.FILTER(EE$6:EE$65,(_xlpm.r>_xlpm.top)*(_xlpm.r<_xlpm.bot))),1/SUM(_xlfn._xlws.FILTER(EE$6:EE$65,(_xlpm.r>_xlpm.top)*(_xlpm.r<_xlpm.bot)))*EE$72*INDEX(DV:DV,_xlpm.top)/DV$72,0),0)))} -> 0 | EQ8: =$C8 -> 3 | ER8: =IF($A8<>"x",$P8*SUMIFS($AF8:$DK8,$AF$4:$DK$4,Jahresscheiben!C$2),0) -> 0 | ES8: =IF($A8<>"x",$P8*SUMIFS($AF8:$DK8,$AF$4:$DK$4,Jahresscheiben!D$2),0) -> 0 | ET8: =IF($A8<>"x",$P8*SUMIFS($AF8:$DK8,$AF$4:$DK$4,Jahresscheiben!E$2),0) -> 0 | EU8: =IF($A8<>"x",$P8*SUMIFS($AF8:$DK8,$AF$4:$DK$4,Jahresscheiben!F$2),0) -> 0 | EV8: =IF($A8<>"x",$P8*SUMIFS($AF8:$DK8,$AF$4:$DK$4,Jahresscheiben!G$2),0) -> 0 | EW8: =IF($A8<>"x",$P8*SUMIFS($AF8:$DK8,$AF$4:$DK$4,Jahresscheiben!H$2),0) -> 0 | EX8: =IF($A8<>"x",$P8*SUMIFS($AF8:$DK8,$AF$4:$DK$4,Jahresscheiben!I$2),0) -> 0 | EZ8: =$C8 -> 3 | FA8: =IF($A8="x",$P8*SUMIFS($AF8:$DK8,$AF$4:$DK$4,Jahresscheiben!C$2)/2,0) -> 12 | FB8: =IF($A8="x",$P8*SUMIFS($AF8:$DK8,$AF$4:$DK$4,Jahresscheiben!D$2)/2,0) -> 0 | FC8: =IF($A8="x",$P8*SUMIFS($AF8:$DK8,$AF$4:$DK$4,Jahresscheiben!E$2)/2,0) -> 0 | FD8: =IF($A8="x",$P8*SUMIFS($AF8:$DK8,$AF$4:$DK$4,Jahresscheiben!F$2)/2,0) -> 0 | FE8: =IF($A8="x",$P8*SUMIFS($AF8:$DK8,$AF$4:$DK$4,Jahresscheiben!G$2)/2,0) -> 0 | FF8: =IF($A8="x",$P8*SUMIFS($AF8:$DK8,$AF$4:$DK$4,Jahresscheiben!H$2)/2,0) -> 0 | FG8: =IF($A8="x",$P8*SUMIFS($AF8:$DK8,$AF$4:$DK$4,Jahresscheiben!I$2)/2,0) -> 0 | FI8: =$C8 -> 3 | FJ8: {=_xlfn.LET(_xlpm.r,ROW($A$6:$A$65), _xlpm.i,ROW(), _xlpm.top,MAX(_xlfn._xlws.FILTER(_xlpm.r,($A$6:$A$65<>"x")*(_xlpm.r<=_xlpm.i))), _xlpm.tmp,MIN(_xlfn._xlws.FILTER(_xlpm.r,($A$6:$A$65<>"x")*(_xlpm.r>=_xlpm.i))), _xlpm.bot,IF(ISERROR(_xlpm.tmp),MAX(_xlpm.r),_xlpm.tmp), IF(_xlpm.bot=_xlpm.top,0,IF(ER$72,IF(SUM(_xlfn._xlws.FILTER(FA$6:FA$65,(_xlpm.r>_xlpm.top)*(_xlpm.r<_xlpm.bot))),1/SUM(_xlfn._xlws.FILTER(FA$6:FA$65,(_xlpm.r>_xlpm.top)*(_xlpm.r<_xlpm.bot)))*FA$72*INDEX(ER:ER,_xlpm.top)/ER$72,0),0)))} -> 0.86076298 | FK8: {=_xlfn.LET(_xlpm.r,ROW($A$6:$A$65), _xlpm.i,ROW(), _xlpm.top,MAX(_xlfn._xlws.FILTER(_xlpm.r,($A$6:$A$65<>"x")*(_xlpm.r<=_xlpm.i))), _xlpm.tmp,MIN(_xlfn._xlws.FILTER(_xlpm.r,($A$6:$A$65<>"x")*(_xlpm.r>=_xlpm.i))), _xlpm.bot,IF(ISERROR(_xlpm.tmp),MAX(_xlpm.r),_xlpm.tmp), IF(_xlpm.bot=_xlpm.top,0,IF(ES$72,IF(SUM(_xlfn._xlws.FILTER(FB$6:FB$65,(_xlpm.r>_xlpm.top)*(_xlpm.r<_xlpm.bot))),1/SUM(_xlfn._xlws.FILTER(FB$6:FB$65,(_xlpm.r>_xlpm.top)*(_xlpm.r<_xlpm.bot)))*FB$72*INDEX(ES:ES,_xlpm.top)/ES$72,0),0)))} -> 0 | FL8: {=_xlfn.LET(_xlpm.r,ROW($A$6:$A$65), _xlpm.i,ROW(), _xlpm.top,MAX(_xlfn._xlws.FILTER(_xlpm.r,($A$6:$A$65<>"x")*(_xlpm.r<=_xlpm.i))), _xlpm.tmp,MIN(_xlfn._xlws.FILTER(_xlpm.r,($A$6:$A$65<>"x")*(_xlpm.r>=_xlpm.i))), _xlpm.bot,IF(ISERROR(_xlpm.tmp),MAX(_xlpm.r),_xlpm.tmp), IF(_xlpm.bot=_xlpm.top,0,IF(ET$72,IF(SUM(_xlfn._xlws.FILTER(FC$6:FC$65,(_xlpm.r>_xlpm.top)*(_xlpm.r<_xlpm.bot))),1/SUM(_xlfn._xlws.FILTER(FC$6:FC$65,(_xlpm.r>_xlpm.top)*(_xlpm.r<_xlpm.bot)))*FC$72*INDEX(ET:ET,_xlpm.top)/ET$72,0),0)))} -> 0 | FM8: {=_xlfn.LET(_xlpm.r,ROW($A$6:$A$65), _xlpm.i,ROW(), _xlpm.top,MAX(_xlfn._xlws.FILTER(_xlpm.r,($A$6:$A$65<>"x")*(_xlpm.r<=_xlpm.i))), _xlpm.tmp,MIN(_xlfn._xlws.FILTER(_xlpm.r,($A$6:$A$65<>"x")*(_xlpm.r>=_xlpm.i))), _xlpm.bot,IF(ISERROR(_xlpm.tmp),MAX(_xlpm.r),_xlpm.tmp), IF(_xlpm.bot=_xlpm.top,0,IF(EU$72,IF(SUM(_xlfn._xlws.FILTER(FD$6:FD$65,(_xlpm.r>_xlpm.top)*(_xlpm.r<_xlpm.bot))),1/SUM(_xlfn._xlws.FILTER(FD$6:FD$65,(_xlpm.r>_xlpm.top)*(_xlpm.r<_xlpm.bot)))*FD$72*INDEX(EU:EU,_xlpm.top)/EU$72,0),0)))} -> 0 | FN8: {=_xlfn.LET(_xlpm.r,ROW($A$6:$A$65), _xlpm.i,ROW(), _xlpm.top,MAX(_xlfn._xlws.FILTER(_xlpm.r,($A$6:$A$65<>"x")*(_xlpm.r<=_xlpm.i))), _xlpm.tmp,MIN(_xlfn._xlws.FILTER(_xlpm.r,($A$6:$A$65<>"x")*(_xlpm.r>=_xlpm.i))), _xlpm.bot,IF(ISERROR(_xlpm.tmp),MAX(_xlpm.r),_xlpm.tmp), IF(_xlpm.bot=_xlpm.top,0,IF(EV$72,IF(SUM(_xlfn._xlws.FILTER(FE$6:FE$65,(_xlpm.r>_xlpm.top)*(_xlpm.r<_xlpm.bot))),1/SUM(_xlfn._xlws.FILTER(FE$6:FE$65,(_xlpm.r>_xlpm.top)*(_xlpm.r<_xlpm.bot)))*FE$72*INDEX(EV:EV,_xlpm.top)/EV$72,0),0)))} -> 0 | FO8: {=_xlfn.LET(_xlpm.r,ROW($A$6:$A$65), _xlpm.i,ROW(), _xlpm.top,MAX(_xlfn._xlws.FILTER(_xlpm.r,($A$6:$A$65<>"x")*(_xlpm.r<=_xlpm.i))), _xlpm.tmp,MIN(_xlfn._xlws.FILTER(_xlpm.r,($A$6:$A$65<>"x")*(_xlpm.r>=_xlpm.i))), _xlpm.bot,IF(ISERROR(_xlpm.tmp),MAX(_xlpm.r),_xlpm.tmp), IF(_xlpm.bot=_xlpm.top,0,IF(EW$72,IF(SUM(_xlfn._xlws.FILTER(FF$6:FF$65,(_xlpm.r>_xlpm.top)*(_xlpm.r<_xlpm.bot))),1/SUM(_xlfn._xlws.FILTER(FF$6:FF$65,(_xlpm.r>_xlpm.top)*(_xlpm.r<_xlpm.bot)))*FF$72*INDEX(EW:EW,_xlpm.top)/EW$72,0),0)))} -> 0 | FP8: {=_xlfn.LET(_xlpm.r,ROW($A$6:$A$65), _xlpm.i,ROW(), _xlpm.top,MAX(_xlfn._xlws.FILTER(_xlpm.r,($A$6:$A$65<>"x")*(_xlpm.r<=_xlpm.i))), _xlpm.tmp,MIN(_xlfn._xlws.FILTER(_xlpm.r,($A$6:$A$65<>"x")*(_xlpm.r>=_xlpm.i))), _xlpm.bot,IF(ISERROR(_xlpm.tmp),MAX(_xlpm.r),_xlpm.tmp), IF(_xlpm.bot=_xlpm.top,0,IF(EX$72,IF(SUM(_xlfn._xlws.FILTER(FG$6:FG$65,(_xlpm.r>_xlpm.top)*(_xlpm.r<_xlpm.bot))),1/SUM(_xlfn._xlws.FILTER(FG$6:FG$65,(_xlpm.r>_xlpm.top)*(_xlpm.r<_xlpm.bot)))*FG$72*INDEX(EX:EX,_xlpm.top)/EX$72,0),0)))} -> 0
A9: x | B9: =LEN(D9) -> 145 | C9: =ROW()-5 -> 4 | D9: 1.3 Parametrische Modellierung der Energie-, Massen- und Rechenzeitbudgets für Sensorik, Edge-KI, Antrieb und Sammelmechanik (Systemmodellierung) | F9: 2 | G9: 4 | I9: =IF(F9=0,"",EOMONTH(Project_Start,F9-1)) -> 46081 | J9: =IF(G9=0,"",EOMONTH(Project_Start,G9-1)) -> 46142 | L9: 6 | M9: {=_xlfn.LET( _xlpm.Z, _xlfn._xlws.FILTER($DY$6:$EE$65,$DX$6:$DX$65=C9), _xlpm.Q,_xlfn._xlws.FILTER($DP$6:$DV$65,$DO$6:$DO$65=C9), IF($A9="x",SUMPRODUCT(_xlpm.Z,$DY$73:$EE$73,EH9:EN9),SUMPRODUCT(_xlpm.Q,$DP$73:$DV$73)))} -> 0 | N9: {=_xlfn.LET( _xlpm.Z, SUM(IF($A9="x",_xlfn._xlws.FILTER($M$6:$M$65,$A$6:$A$65="x"),_xlfn._xlws.FILTER($M$6:$M$65,$A$6:$A$65<>"x"))), IF(_xlpm.Z<>0,M9/_xlpm.Z,""))} | P9: =L9 -> 6 | Q9: {=_xlfn.LET( _xlpm.Z, _xlfn._xlws.FILTER($FA$6:$FG$65,$EZ$6:$EZ$65=C9), _xlpm.Q,_xlfn._xlws.FILTER($ER$6:$EX$65,$EQ$6:$EQ$65=C9), IF($A9="x",SUMPRODUCT(_xlpm.Z,$FA$73:$FG$73,FJ9:FP9),SUMPRODUCT(_xlpm.Q,$ER$73:$EX$73)))} -> 0 | R9: {=_xlfn.LET( _xlpm.Z, SUM(IF($A9="x",_xlfn._xlws.FILTER($Q$6:$Q$65,$A$6:$A$65="x"),_xlfn._xlws.FILTER($Q$6:$Q$65,$A$6:$A$65<>"x"))), IF(_xlpm.Z<>0,Q9/_xlpm.Z,""))} | AF9: =_xlfn.LET( _xlpm.project_monat,AF$3, _xlpm.start_monat,$F9, _xlpm.ende_monat,$G9, IF(AND(_xlpm.project_monat>=_xlpm.start_monat,_xlpm.project_monat<=_xlpm.ende_monat),IF($A9="x",2,1),"")) | AG9: =_xlfn.LET( _xlpm.project_monat,AG$3, _xlpm.start_monat,$F9, _xlpm.ende_monat,$G9, IF(AND(_xlpm.project_monat>=_xlpm.start_monat,_xlpm.project_monat<=_xlpm.ende_monat),IF($A9="x",2,1),"")) -> 2 | AH9: =_xlfn.LET( _xlpm.project_monat,AH$3, _xlpm.start_monat,$F9, _xlpm.ende_monat,$G9, IF(AND(_xlpm.project_monat>=_xlpm.start_monat,_xlpm.project_monat<=_xlpm.ende_monat),IF($A9="x",2,1),"")) -> 2 | AI9: =_xlfn.LET( _xlpm.project_monat,AI$3, _xlpm.start_monat,$F9, _xlpm.ende_monat,$G9, IF(AND(_xlpm.project_monat>=_xlpm.start_monat,_xlpm.project_monat<=_xlpm.ende_monat),IF($A9="x",2,1),"")) -> 2 | AJ9: =_xlfn.LET( _xlpm.project_monat,AJ$3, _xlpm.start_monat,$F9, _xlpm.ende_monat,$G9, IF(AND(_xlpm.project_monat>=_xlpm.start_monat,_xlpm.project_monat<=_xlpm.ende_monat),IF($A9="x",2,1),"")) | AK9: =_xlfn.LET( _xlpm.project_monat,AK$3, _xlpm.start_monat,$F9, _xlpm.ende_monat,$G9, IF(AND(_xlpm.project_monat>=_xlpm.start_monat,_xlpm.project_monat<=_xlpm.ende_monat),IF($A9="x",2,1),"")) | AL9: =_xlfn.LET( _xlpm.project_monat,AL$3, _xlpm.start_monat,$F9, _xlpm.ende_monat,$G9, IF(AND(_xlpm.project_monat>=_xlpm.start_monat,_xlpm.project_monat<=_xlpm.ende_monat),IF($A9="x",2,1),"")) | AM9: =_xlfn.LET( _xlpm.project_monat,AM$3, _xlpm.start_monat,$F9, _xlpm.ende_monat,$G9, IF(AND(_xlpm.project_monat>=_xlpm.start_monat,_xlpm.project_monat<=_xlpm.ende_monat),IF($A9="x",2,1),"")) | ... DK9: =_xlfn.LET( _xlpm.project_monat,DK$3, _xlpm.start_monat,$F9, _xlpm.ende_monat,$G9, IF(AND(_xlpm.project_monat>=_xlpm.start_monat,_xlpm.project_monat<=_xlpm.ende_monat),IF($A9="x",2,1),"")) | DO9: =$C9 -> 4 | DP9: =IF($A9<>"x",$L9*SUMIFS($AF9:$DK9,$AF$4:$DK$4,Jahresscheiben!C$2),0) -> 0 | DQ9: =IF($A9<>"x",$L9*SUMIFS($AF9:$DK9,$AF$4:$DK$4,Jahresscheiben!D$2),0) -> 0 | DR9: =IF($A9<>"x",$L9*SUMIFS($AF9:$DK9,$AF$4:$DK$4,Jahresscheiben!E$2),0) -> 0 | DS9: =IF($A9<>"x",$L9*SUMIFS($AF9:$DK9,$AF$4:$DK$4,Jahresscheiben!F$2),0) -> 0 | DT9: =IF($A9<>"x",$L9*SUMIFS($AF9:$DK9,$AF$4:$DK$4,Jahresscheiben!G$2),0) -> 0 | DU9: =IF($A9<>"x",$L9*SUMIFS($AF9:$DK9,$AF$4:$DK$4,Jahresscheiben!H$2),0) -> 0 | DV9: =IF($A9<>"x",$L9*SUMIFS($AF9:$DK9,$AF$4:$DK$4,Jahresscheiben!I$2),0) -> 0 | DX9: =$C9 -> 4 | DY9: =IF($A9="x",$L9*SUMIFS($AF9:$DK9,$AF$4:$DK$4,Jahresscheiben!C$2)/2,0) -> 18 | DZ9: =IF($A9="x",$L9*SUMIFS($AF9:$DK9,$AF$4:$DK$4,Jahresscheiben!D$2)/2,0) -> 0 | EA9: =IF($A9="x",$L9*SUMIFS($AF9:$DK9,$AF$4:$DK$4,Jahresscheiben!E$2)/2,0) -> 0 | EB9: =IF($A9="x",$L9*SUMIFS($AF9:$DK9,$AF$4:$DK$4,Jahresscheiben!F$2)/2,0) -> 0 | EC9: =IF($A9="x",$L9*SUMIFS($AF9:$DK9,$AF$4:$DK$4,Jahresscheiben!G$2)/2,0) -> 0 | ED9: =IF($A9="x",$L9*SUMIFS($AF9:$DK9,$AF$4:$DK$4,Jahresscheiben!H$2)/2,0) -> 0 | EE9: =IF($A9="x",$L9*SUMIFS($AF9:$DK9,$AF$4:$DK$4,Jahresscheiben!I$2)/2,0) -> 0 | EG9: =$C9 -> 4 | EH9: {=_xlfn.LET(_xlpm.r,ROW($A$6:$A$65), _xlpm.i,ROW(), _xlpm.top,MAX(_xlfn._xlws.FILTER(_xlpm.r,($A$6:$A$65<>"x")*(_xlpm.r<=_xlpm.i))), _xlpm.tmp,MIN(_xlfn._xlws.FILTER(_xlpm.r,($A$6:$A$65<>"x")*(_xlpm.r>=_xlpm.i))), _xlpm.bot,IF(ISERROR(_xlpm.tmp),MAX(_xlpm.r),_xlpm.tmp), IF(_xlpm.bot=_xlpm.top,0,IF(DP$72,IF(SUM(_xlfn._xlws.FILTER(DY$6:DY$65,(_xlpm.r>_xlpm.top)*(_xlpm.r<_xlpm.bot))),1/SUM(_xlfn._xlws.FILTER(DY$6:DY$65,(_xlpm.r>_xlpm.top)*(_xlpm.r<_xlpm.bot)))*DY$72*INDEX(DP:DP,_xlpm.top)/DP$72,0),0)))} -> 0.86076298 | EI9: {=_xlfn.LET(_xlpm.r,ROW($A$6:$A$65), _xlpm.i,ROW(), _xlpm.top,MAX(_xlfn._xlws.FILTER(_xlpm.r,($A$6:$A$65<>"x")*(_xlpm.r<=_xlpm.i))), _xlpm.tmp,MIN(_xlfn._xlws.FILTER(_xlpm.r,($A$6:$A$65<>"x")*(_xlpm.r>=_xlpm.i))), _xlpm.bot,IF(ISERROR(_xlpm.tmp),MAX(_xlpm.r),_xlpm.tmp), IF(_xlpm.bot=_xlpm.top,0,IF(DQ$72,IF(SUM(_xlfn._xlws.FILTER(DZ$6:DZ$65,(_xlpm.r>_xlpm.top)*(_xlpm.r<_xlpm.bot))),1/SUM(_xlfn._xlws.FILTER(DZ$6:DZ$65,(_xlpm.r>_xlpm.top)*(_xlpm.r<_xlpm.bot)))*DZ$72*INDEX(DQ:DQ,_xlpm.top)/DQ$72,0),0)))} -> 0 | EJ9: {=_xlfn.LET(_xlpm.r,ROW($A$6:$A$65), _xlpm.i,ROW(), _xlpm.top,MAX(_xlfn._xlws.FILTER(_xlpm.r,($A$6:$A$65<>"x")*(_xlpm.r<=_xlpm.i))), _xlpm.tmp,MIN(_xlfn._xlws.FILTER(_xlpm.r,($A$6:$A$65<>"x")*(_xlpm.r>=_xlpm.i))), _xlpm.bot,IF(ISERROR(_xlpm.tmp),MAX(_xlpm.r),_xlpm.tmp), IF(_xlpm.bot=_xlpm.top,0,IF(DR$72,IF(SUM(_xlfn._xlws.FILTER(EA$6:EA$65,(_xlpm.r>_xlpm.top)*(_xlpm.r<_xlpm.bot))),1/SUM(_xlfn._xlws.FILTER(EA$6:EA$65,(_xlpm.r>_xlpm.top)*(_xlpm.r<_xlpm.bot)))*EA$72*INDEX(DR:DR,_xlpm.top)/DR$72,0),0)))} -> 0 | EK9: {=_xlfn.LET(_xlpm.r,ROW($A$6:$A$65), _xlpm.i,ROW(), _xlpm.top,MAX(_xlfn._xlws.FILTER(_xlpm.r,($A$6:$A$65<>"x")*(_xlpm.r<=_xlpm.i))), _xlpm.tmp,MIN(_xlfn._xlws.FILTER(_xlpm.r,($A$6:$A$65<>"x")*(_xlpm.r>=_xlpm.i))), _xlpm.bot,IF(ISERROR(_xlpm.tmp),MAX(_xlpm.r),_xlpm.tmp), IF(_xlpm.bot=_xlpm.top,0,IF(DS$72,IF(SUM(_xlfn._xlws.FILTER(EB$6:EB$65,(_xlpm.r>_xlpm.top)*(_xlpm.r<_xlpm.bot))),1/SUM(_xlfn._xlws.FILTER(EB$6:EB$65,(_xlpm.r>_xlpm.top)*(_xlpm.r<_xlpm.bot)))*EB$72*INDEX(DS:DS,_xlpm.top)/DS$72,0),0)))} -> 0 | EL9: {=_xlfn.LET(_xlpm.r,ROW($A$6:$A$65), _xlpm.i,ROW(), _xlpm.top,MAX(_xlfn._xlws.FILTER(_xlpm.r,($A$6:$A$65<>"x")*(_xlpm.r<=_xlpm.i))), _xlpm.tmp,MIN(_xlfn._xlws.FILTER(_xlpm.r,($A$6:$A$65<>"x")*(_xlpm.r>=_xlpm.i))), _xlpm.bot,IF(ISERROR(_xlpm.tmp),MAX(_xlpm.r),_xlpm.tmp), IF(_xlpm.bot=_xlpm.top,0,IF(DT$72,IF(SUM(_xlfn._xlws.FILTER(EC$6:EC$65,(_xlpm.r>_xlpm.top)*(_xlpm.r<_xlpm.bot))),1/SUM(_xlfn._xlws.FILTER(EC$6:EC$65,(_xlpm.r>_xlpm.top)*(_xlpm.r<_xlpm.bot)))*EC$72*INDEX(DT:DT,_xlpm.top)/DT$72,0),0)))} -> 0 | EM9: {=_xlfn.LET(_xlpm.r,ROW($A$6:$A$65), _xlpm.i,ROW(), _xlpm.top,MAX(_xlfn._xlws.FILTER(_xlpm.r,($A$6:$A$65<>"x")*(_xlpm.r<=_xlpm.i))), _xlpm.tmp,MIN(_xlfn._xlws.FILTER(_xlpm.r,($A$6:$A$65<>"x")*(_xlpm.r>=_xlpm.i))), _xlpm.bot,IF(ISERROR(_xlpm.tmp),MAX(_xlpm.r),_xlpm.tmp), IF(_xlpm.bot=_xlpm.top,0,IF(DU$72,IF(SUM(_xlfn._xlws.FILTER(ED$6:ED$65,(_xlpm.r>_xlpm.top)*(_xlpm.r<_xlpm.bot))),1/SUM(_xlfn._xlws.FILTER(ED$6:ED$65,(_xlpm.r>_xlpm.top)*(_xlpm.r<_xlpm.bot)))*ED$72*INDEX(DU:DU,_xlpm.top)/DU$72,0),0)))} -> 0 | EN9: {=_xlfn.LET(_xlpm.r,ROW($A$6:$A$65), _xlpm.i,ROW(), _xlpm.top,MAX(_xlfn._xlws.FILTER(_xlpm.r,($A$6:$A$65<>"x")*(_xlpm.r<=_xlpm.i))), _xlpm.tmp,MIN(_xlfn._xlws.FILTER(_xlpm.r,($A$6:$A$65<>"x")*(_xlpm.r>=_xlpm.i))), _xlpm.bot,IF(ISERROR(_xlpm.tmp),MAX(_xlpm.r),_xlpm.tmp), IF(_xlpm.bot=_xlpm.top,0,IF(DV$72,IF(SUM(_xlfn._xlws.FILTER(EE$6:EE$65,(_xlpm.r>_xlpm.top)*(_xlpm.r<_xlpm.bot))),1/SUM(_xlfn._xlws.FILTER(EE$6:EE$65,(_xlpm.r>_xlpm.top)*(_xlpm.r<_xlpm.bot)))*EE$72*INDEX(DV:DV,_xlpm.top)/DV$72,0),0)))} -> 0 | EQ9: =$C9 -> 4 | ER9: =IF($A9<>"x",$P9*SUMIFS($AF9:$DK9,$AF$4:$DK$4,Jahresscheiben!C$2),0) -> 0 | ES9: =IF($A9<>"x",$P9*SUMIFS($AF9:$DK9,$AF$4:$DK$4,Jahresscheiben!D$2),0) -> 0 | ET9: =IF($A9<>"x",$P9*SUMIFS($AF9:$DK9,$AF$4:$DK$4,Jahresscheiben!E$2),0) -> 0 | EU9: =IF($A9<>"x",$P9*SUMIFS($AF9:$DK9,$AF$4:$DK$4,Jahresscheiben!F$2),0) -> 0 | EV9: =IF($A9<>"x",$P9*SUMIFS($AF9:$DK9,$AF$4:$DK$4,Jahresscheiben!G$2),0) -> 0 | EW9: =IF($A9<>"x",$P9*SUMIFS($AF9:$DK9,$AF$4:$DK$4,Jahresscheiben!H$2),0) -> 0 | EX9: =IF($A9<>"x",$P9*SUMIFS($AF9:$DK9,$AF$4:$DK$4,Jahresscheiben!I$2),0) -> 0 | EZ9: =$C9 -> 4 | FA9: =IF($A9="x",$P9*SUMIFS($AF9:$DK9,$AF$4:$DK$4,Jahresscheiben!C$2)/2,0) -> 18 | FB9: =IF($A9="x",$P9*SUMIFS($AF9:$DK9,$AF$4:$DK$4,Jahresscheiben!D$2)/2,0) -> 0 | FC9: =IF($A9="x",$P9*SUMIFS($AF9:$DK9,$AF$4:$DK$4,Jahresscheiben!E$2)/2,0) -> 0 | FD9: =IF($A9="x",$P9*SUMIFS($AF9:$DK9,$AF$4:$DK$4,Jahresscheiben!F$2)/2,0) -> 0 | FE9: =IF($A9="x",$P9*SUMIFS($AF9:$DK9,$AF$4:$DK$4,Jahresscheiben!G$2)/2,0) -> 0 | FF9: =IF($A9="x",$P9*SUMIFS($AF9:$DK9,$AF$4:$DK$4,Jahresscheiben!H$2)/2,0) -> 0 | FG9: =IF($A9="x",$P9*SUMIFS($AF9:$DK9,$AF$4:$DK$4,Jahresscheiben!I$2)/2,0) -> 0 | FI9: =$C9 -> 4 | FJ9: {=_xlfn.LET(_xlpm.r,ROW($A$6:$A$65), _xlpm.i,ROW(), _xlpm.top,MAX(_xlfn._xlws.FILTER(_xlpm.r,($A$6:$A$65<>"x")*(_xlpm.r<=_xlpm.i))), _xlpm.tmp,MIN(_xlfn._xlws.FILTER(_xlpm.r,($A$6:$A$65<>"x")*(_xlpm.r>=_xlpm.i))), _xlpm.bot,IF(ISERROR(_xlpm.tmp),MAX(_xlpm.r),_xlpm.tmp), IF(_xlpm.bot=_xlpm.top,0,IF(ER$72,IF(SUM(_xlfn._xlws.FILTER(FA$6:FA$65,(_xlpm.r>_xlpm.top)*(_xlpm.r<_xlpm.bot))),1/SUM(_xlfn._xlws.FILTER(FA$6:FA$65,(_xlpm.r>_xlpm.top)*(_xlpm.r<_xlpm.bot)))*FA$72*INDEX(ER:ER,_xlpm.top)/ER$72,0),0)))} -> 0.86076298 | FK9: {=_xlfn.LET(_xlpm.r,ROW($A$6:$A$65), _xlpm.i,ROW(), _xlpm.top,MAX(_xlfn._xlws.FILTER(_xlpm.r,($A$6:$A$65<>"x")*(_xlpm.r<=_xlpm.i))), _xlpm.tmp,MIN(_xlfn._xlws.FILTER(_xlpm.r,($A$6:$A$65<>"x")*(_xlpm.r>=_xlpm.i))), _xlpm.bot,IF(ISERROR(_xlpm.tmp),MAX(_xlpm.r),_xlpm.tmp), IF(_xlpm.bot=_xlpm.top,0,IF(ES$72,IF(SUM(_xlfn._xlws.FILTER(FB$6:FB$65,(_xlpm.r>_xlpm.top)*(_xlpm.r<_xlpm.bot))),1/SUM(_xlfn._xlws.FILTER(FB$6:FB$65,(_xlpm.r>_xlpm.top)*(_xlpm.r<_xlpm.bot)))*FB$72*INDEX(ES:ES,_xlpm.top)/ES$72,0),0)))} -> 0 | FL9: {=_xlfn.LET(_xlpm.r,ROW($A$6:$A$65), _xlpm.i,ROW(), _xlpm.top,MAX(_xlfn._xlws.FILTER(_xlpm.r,($A$6:$A$65<>"x")*(_xlpm.r<=_xlpm.i))), _xlpm.tmp,MIN(_xlfn._xlws.FILTER(_xlpm.r,($A$6:$A$65<>"x")*(_xlpm.r>=_xlpm.i))), _xlpm.bot,IF(ISERROR(_xlpm.tmp),MAX(_xlpm.r),_xlpm.tmp), IF(_xlpm.bot=_xlpm.top,0,IF(ET$72,IF(SUM(_xlfn._xlws.FILTER(FC$6:FC$65,(_xlpm.r>_xlpm.top)*(_xlpm.r<_xlpm.bot))),1/SUM(_xlfn._xlws.FILTER(FC$6:FC$65,(_xlpm.r>_xlpm.top)*(_xlpm.r<_xlpm.bot)))*FC$72*INDEX(ET:ET,_xlpm.top)/ET$72,0),0)))} -> 0 | FM9: {=_xlfn.LET(_xlpm.r,ROW($A$6:$A$65), _xlpm.i,ROW(), _xlpm.top,MAX(_xlfn._xlws.FILTER(_xlpm.r,($A$6:$A$65<>"x")*(_xlpm.r<=_xlpm.i))), _xlpm.tmp,MIN(_xlfn._xlws.FILTER(_xlpm.r,($A$6:$A$65<>"x")*(_xlpm.r>=_xlpm.i))), _xlpm.bot,IF(ISERROR(_xlpm.tmp),MAX(_xlpm.r),_xlpm.tmp), IF(_xlpm.bot=_xlpm.top,0,IF(EU$72,IF(SUM(_xlfn._xlws.FILTER(FD$6:FD$65,(_xlpm.r>_xlpm.top)*(_xlpm.r<_xlpm.bot))),1/SUM(_xlfn._xlws.FILTER(FD$6:FD$65,(_xlpm.r>_xlpm.top)*(_xlpm.r<_xlpm.bot)))*FD$72*INDEX(EU:EU,_xlpm.top)/EU$72,0),0)))} -> 0 | FN9: {=_xlfn.LET(_xlpm.r,ROW($A$6:$A$65), _xlpm.i,ROW(), _xlpm.top,MAX(_xlfn._xlws.FILTER(_xlpm.r,($A$6:$A$65<>"x")*(_xlpm.r<=_xlpm.i))), _xlpm.tmp,MIN(_xlfn._xlws.FILTER(_xlpm.r,($A$6:$A$65<>"x")*(_xlpm.r>=_xlpm.i))), _xlpm.bot,IF(ISERROR(_xlpm.tmp),MAX(_xlpm.r),_xlpm.tmp), IF(_xlpm.bot=_xlpm.top,0,IF(EV$72,IF(SUM(_xlfn._xlws.FILTER(FE$6:FE$65,(_xlpm.r>_xlpm.top)*(_xlpm.r<_xlpm.bot))),1/SUM(_xlfn._xlws.FILTER(FE$6:FE$65,(_xlpm.r>_xlpm.top)*(_xlpm.r<_xlpm.bot)))*FE$72*INDEX(EV:EV,_xlpm.top)/EV$72,0),0)))} -> 0 | FO9: {=_xlfn.LET(_xlpm.r,ROW($A$6:$A$65), _xlpm.i,ROW(), _xlpm.top,MAX(_xlfn._xlws.FILTER(_xlpm.r,($A$6:$A$65<>"x")*(_xlpm.r<=_xlpm.i))), _xlpm.tmp,MIN(_xlfn._xlws.FILTER(_xlpm.r,($A$6:$A$65<>"x")*(_xlpm.r>=_xlpm.i))), _xlpm.bot,IF(ISERROR(_xlpm.tmp),MAX(_xlpm.r),_xlpm.tmp), IF(_xlpm.bot=_xlpm.top,0,IF(EW$72,IF(SUM(_xlfn._xlws.FILTER(FF$6:FF$65,(_xlpm.r>_xlpm.top)*(_xlpm.r<_xlpm.bot))),1/SUM(_xlfn._xlws.FILTER(FF$6:FF$65,(_xlpm.r>_xlpm.top)*(_xlpm.r<_xlpm.bot)))*FF$72*INDEX(EW:EW,_xlpm.top)/EW$72,0),0)))} -> 0 | FP9: {=_xlfn.LET(_xlpm.r,ROW($A$6:$A$65), _xlpm.i,ROW(), _xlpm.top,MAX(_xlfn._xlws.FILTER(_xlpm.r,($A$6:$A$65<>"x")*(_xlpm.r<=_xlpm.i))), _xlpm.tmp,MIN(_xlfn._xlws.FILTER(_xlpm.r,($A$6:$A$65<>"x")*(_xlpm.r>=_xlpm.i))), _xlpm.bot,IF(ISERROR(_xlpm.tmp),MAX(_xlpm.r),_xlpm.tmp), IF(_xlpm.bot=_xlpm.top,0,IF(EX$72,IF(SUM(_xlfn._xlws.FILTER(FG$6:FG$65,(_xlpm.r>_xlpm.top)*(_xlpm.r<_xlpm.bot))),1/SUM(_xlfn._xlws.FILTER(FG$6:FG$65,(_xlpm.r>_xlpm.top)*(_xlpm.r<_xlpm.bot)))*FG$72*INDEX(EX:EX,_xlpm.top)/EX$72,0),0)))} -> 0
