Workbook
Name AN_Vorhaben1: 'FuE Vorhaben'!$B$17:$H$26
Name AN_Vorhaben2: 'FuE Vorhaben'!#REF!
Name AN_Vorhaben3: 'FuE Vorhaben'!#REF!
Name AN_Vorhaben4: 'FuE Vorhaben'!#REF!
Name AN_Vorhaben5: 'FuE Vorhaben'!#REF!
Name AN_Vorhaben6: 'FuE Vorhaben'!#REF!
Name AN_Vorhaben7: 'FuE Vorhaben'!#REF!
Name ausschließlich_eigenbetriebliche_Nutzung?: Tabelle1!$B$2:$B$3
Name BeantrFZ2020: 'Ganzes Unternehmen'!$H$57
Name BeantrFZ2021: 'Ganzes Unternehmen'!$I$57
Name BeantrFZ2022: 'Ganzes Unternehmen'!$J$57
Name BeantrFZ2023: 'Ganzes Unternehmen'!$K$57
Name BeantrFZ2024: 'Ganzes Unternehmen'!$L$57
Name BeantrFZ2025: 'Ganzes Unternehmen'!$M$57
Name Bundesland: 'Ganzes Unternehmen'!$C$11
Name CountLines: _xlfn.LAMBDA(_xlpm.Zelle,LEN(_xlpm.Zelle)-LEN(SUBSTITUTE(_xlpm.Zelle,CHAR(10),""))+1)
Name Display_Week: Arbeitsplan!$C$4
Name GetAGBeitrag: _xlfn.LAMBDA(_xlpm.links,_xlpm.rechts,IF(CountLines(_xlpm.links)+CountLines(_xlpm.rechts)=6,GetSteuerbruttoZ3(_xlpm.links)&","&GetSteuerbruttoZ3(_xlpm.rechts),""))
Name GetColOfAry: _xlfn.LAMBDA(_xlpm.targetcol,_xlpm.ary, _xlfn.TAKE(_xlfn.TAKE(_xlpm.ary,,_xlpm.targetcol),,-1) )
Name GetNumbers: _xlfn.LAMBDA(_xlpm.Zelle,SUM(MID(0&_xlpm.Zelle,LARGE(INDEX(ISNUMBER(--MID(_xlpm.Zelle,ROW(#REF!),1))*ROW(#REF!),),ROW(#REF!))+1,1)*10^ROW(#REF!)/10))
Name GewählterMA: Stundenzettel!$C$8
Name GewähltesVorhaben: Stundenzettel!$C$9
Name Jahr1: Stundenzettel!$C$15
Name Jahr2: Stundenzettel!$C$43
Name Jahr3: Stundenzettel!$C$71
Name Jahr4: Stundenzettel!$C$99
Name Jahr5: Stundenzettel!$C$127
Name Jahr6: Stundenzettel!$C$155
Name Kosten2020: Dashboard!$E$17
Name Kosten2021: Dashboard!$F$17
Name Kosten2022: Dashboard!$G$17
Name Kosten2023: Dashboard!$H$17
Name Kosten2024: Dashboard!$I$17
Name Kosten2025: Dashboard!$J$17
Name Mitarbeiter: _xlfn.ANCHORARRAY(Personaleingabe!$AZ$11)
Name Proj1: 'Ganzes Unternehmen'!$B$16
Name Proj2: 'Ganzes Unternehmen'!$B$17
Name Proj3: 'Ganzes Unternehmen'!$B$18
Name Proj4: 'Ganzes Unternehmen'!$B$19
Name Proj5: 'Ganzes Unternehmen'!$B$20
Name Proj6: 'Ganzes Unternehmen'!$B$21
Name Proj7: 'Ganzes Unternehmen'!$B$22
Name Project_Start: Arbeitsplan!$C$3
Name Steuerland: Steuernummern!$A$3
Name Steuernummer_kurz: 'Ganzes Unternehmen'!$C$10
Name Steuernummer_lang: 'Ganzes Unternehmen'!$C$9
Name task_end: [1]ProjectSchedule!$D1
Name task_start: [1]ProjectSchedule!$C1
Name WJ: #REF!
Name WJ_2020: 'Ganzes Unternehmen'!$C$23
Name WJ_2021: 'Ganzes Unternehmen'!$D$23
Name WJ_2022: 'Ganzes Unternehmen'!$E$23
Name WJ_2023: 'Ganzes Unternehmen'!$F$23
Name WJ_2024: 'Ganzes Unternehmen'!$G$23
Name WJ_2025: 'Ganzes Unternehmen'!$H$23
Name Year_Valid_V1: 'FuE Vorhaben'!$C$9:$H$9
Name Year_Valid_V2: 'FuE Vorhaben'!#REF!
Name Year_Valid_V3: 'FuE Vorhaben'!#REF!
Name Year_Valid_V4: 'FuE Vorhaben'!#REF!
Name Year_Valid_V5: 'FuE Vorhaben'!#REF!

Sheet Ganzes Unternehmen
B5: Dieses Tabellenblatt fragt allgemeine Daten über die Unternehmensgruppe, das Unternehmen und die geplanten Vorhaben ab.
B7: Allgemeine Daten
B8: Name der Firma | C8: Ping Zhou Consulting
B9: Steuernummer (lang; 13-stellig)
B10: Steuernummer (kurz)
B11: Bundesland Finanzamt | C11: Baden-Württemberg
B12: Seid ihr ein KMU? | C12: ja
B14: Liste der Vorhaben
B15: Arbeitstitel | C15: Start | D15: Ende
A16: {=IFERROR("#"&_xlfn.SEQUENCE(COUNTA(Vorhaben_1[Arbeitstitel])),"")} -> #1 | B16: Ping-Pong-Roboter | C16: 46024 | D16: 47118 | E16: =IF(C16>D16,"Das Startdatum muss vor dem Enddatum liegen.","")
E17: =IF(C17>D17,"Das Startdatum muss vor dem Enddatum liegen.","")
E18: =IF(C18>D18,"Das Startdatum muss vor dem Enddatum liegen.","")
E19: =IF(C19>D19,"Das Startdatum muss vor dem Enddatum liegen.","")
E20: =IF(C20>D20,"Das Startdatum muss vor dem Enddatum liegen.","")
E21: =IF(C21>D21,"Das Startdatum muss vor dem Enddatum liegen.","")
E22: =IF(C22>D22,"Das Startdatum muss vor dem Enddatum liegen.","")
C23: =C25&C24&" - "&C26&C24 -> 01.012025 - 31.12.2025 | D23: =D25&D24&" - "&D26&D24 -> - | E23: =E25&E24&" - "&E26&E24 -> - | F23: =F25&F24&" - "&F26&F24 -> 01 - 01 | G23: =G25&G24&" - "&G26&G24 -> 02 - 02 | H23: =H25&H24&" - "&H26&H24 -> 03 - 03
B24: Allgemein | C24: 2025 | F24: =E24+1 -> 1 | G24: =F24+1 -> 2 | H24: =G24+1 -> 3
B25: Start Wirtschaftsjahr | C25: 01.01 | F25: =E25 -> 0 | G25: =F25 -> 0 | H25: =G25 -> 0
B26: Ende Wirtschaftsjahr | C26: 31.12. | F26: =E26 -> 0 | G26: =F26 -> 0 | H26: =G26 -> 0
B27: Ist Rumpfwirtschatsjahr | C27: nein
B28: Jahresumsatz [€] | C28: 1
B29: Zahl der Mitarbeitenden [VZÄ] | C29: 1
B30: =_xlfn.LET( _xlpm.VZÄ_Unt_FuE, C32>C29, _xlpm.Personalkosten, C34<Dashboard!E10, _xlpm.Sachkosten, C35<Dashboard!E14, _xlpm.Auftragskosten, C47<Dashboard!E13, _xlpm.Förderung, C40<Dashboard!E15, IF(_xlpm.VZÄ_Unt_FuE,"Die VZÄ aus dem FuE können nicht größer sein, als das ganze Unternehmen.", IF(AND(_xlpm.Personalkosten,_xlpm.Sachkosten,_xlpm.Auftragskosten),"Die Personal- und Sach- und Auftragskosten der Projekte sind höher als die, des FuE Bereichs.", IF(AND(_xlpm.Personalkosten,_xlpm.Sachkosten),"Die Personal- und Sachkosten der Projekte sind höher als die, des FuE Bereichs.", IF(AND(_xlpm.Auftragskosten,_xlpm.Sachkosten),"Die Sach- und Auftragskosten der Projekte sind höher als die, des FuE Bereichs.", IF(AND(_xlpm.Auftragskosten,_xlpm.Personalkosten),"Die Personal- und Auftragskosten der Projekte sind höher als die, des FuE Bereichs.", IF(_xlpm.Personalkosten,"Die Personalkosten der Projekte sind höher als die des FuE Bereichs.", IF(_xlpm.Sachkosten,"Die Sachkosten der Projekte sind höher als die des FuE Bereichs.", IF(_xlpm.Auftragskosten,"Die Auftragskosten der Projekte sind höher als die des FuE Bereichs.", IF(_xlpm.Förderung,"Die sonstige FuE-Förderung der Projekte sind höher als die des FuE Bereichs.", "" ))))))))))
B31: FuE | C31: =C24 -> 2025
B32: Zahl der Mitarbeitenden in FuE [VZÄ]
B33: Interne Aufwendungen [€] | C33: =SUM(C34:C35) -> 0
B34: Personalaufwendungen [€]
B35: Sachaufwendungen und Investitionen [€]
B36: Externe Aufwendungen (FuE gesamt) [€] | C36: =SUM(C37:C38) -> 0
B37: Davon an Auftragnehmer innerhalb der EU/EWR [€]
B38: Davon an Auftragnehmer außerhalb der EU/EWR [€]
B39: Wurden öffentliche Förderungen für FuE in genutzt? | C39: nein
B40: Sonstige Öffentliche Förderungen für FuE [€]
B42: Verbundene Unternehmen
B43: Firmierung / Name | C43: Bundesland | D43: Adresse | E43: Steuernummer (nicht UStID) | F43: Umsatz [€] | G43: Mitarbeiter [VZÄ] | H43: Kosten für die, die Forschungszulage beantragt wurde/wird
F44: =C24 -> 2025 | G44: =C24 -> 2025 | H44: 2022 | I44: =H44+1 -> 2023 | J44: =I44+1 -> 2024 | K44: =J44+1 -> 2025 | L44: =K44+1 -> 2026 | M44: =L44+1 -> 2027
A45: {=IFERROR("#"&_xlfn.SEQUENCE(COUNTA(B45:B56)),"")}
H57: =SUM(H45:H56) -> 0 | I57: =SUM(I45:I56) -> 0 | J57: =SUM(J45:J56) -> 0 | K57: =SUM(K45:K56) -> 0 | L57: =SUM(L45:L56) -> 0 | M57: =SUM(M45:M56) -> 0
B59: Angaben zum Unternehmensverbund | C59: =C24 -> 2025
...

Sheet FuE Vorhaben
A1: 12 | B1: =$B$6 -> 1 | C1: =$B$6 -> 1 | D1: =$B$6 -> 1 | E1: =$B$6 -> 1 | F1: =$B$6 -> 1 | G1: =$B$6 -> 1 | H1: =$B$6 -> 1 | I1: =$B$6 -> 1 | ... L1: =$B$6 -> 1 | N1: =$O$6 -> 2 | O1: =$O$6 -> 2 | P1: =$O$6 -> 2 | Q1: =$O$6 -> 2 | R1: =$O$6 -> 2 | S1: =$O$6 -> 2 | T1: =$O$6 -> 2 | U1: =$O$6 -> 2 | ... Y1: =$O$6 -> 2 | AA1: =$AB$6 -> 3 | AB1: =$AB$6 -> 3 | AC1: =$AB$6 -> 3 | AD1: =$AB$6 -> 3 | AE1: =$AB$6 -> 3 | AF1: =$AB$6 -> 3 | AG1: =$AB$6 -> 3 | AH1: =$AB$6 -> 3 | ... AL1: =$AB$6 -> 3 | AN1: =$AO$6 -> 4 | AO1: =$AO$6 -> 4 | AP1: =$AO$6 -> 4 | AQ1: =$AO$6 -> 4 | AR1: =$AO$6 -> 4 | AS1: =$AO$6 -> 4 | AT1: =$AO$6 -> 4 | AU1: =$AO$6 -> 4 | ... AY1: =$AO$6 -> 4 | BA1: =$BB$6 -> 5 | BB1: =$BB$6 -> 5 | BC1: =$BB$6 -> 5 | BD1: =$BB$6 -> 5 | BE1: =$BB$6 -> 5 | BF1: =$BB$6 -> 5 | BG1: =$BB$6 -> 5 | BH1: =$BB$6 -> 5 | ... BL1: =$BB$6 -> 5 | BN1: =$BO$6 -> 6 | BO1: =$BO$6 -> 6 | BP1: =$BO$6 -> 6 | BQ1: =$BO$6 -> 6 | BR1: =$BO$6 -> 6 | BS1: =$BO$6 -> 6 | BT1: =$BO$6 -> 6 | BU1: =$BO$6 -> 6 | ... BY1: =$BO$6 -> 6 | CA1: =$CB$6 -> 7 | CB1: =$CB$6 -> 7 | CC1: =$CB$6 -> 7 | CD1: =$CB$6 -> 7 | CE1: =$CB$6 -> 7 | CF1: =$CB$6 -> 7 | CG1: =$CB$6 -> 7 | CH1: =$CB$6 -> 7 | ... CJ1: =$CB$6 -> 7 | CL1: =$CB$6 -> 7
B2: ="Angaben zum F&E Vorhaben: "& C6 -> Angaben zum F&E Vorhaben: Ping-Pong-Roboter | O2: ="Angaben zum F&E Vorhaben: "& P6 -> Angaben zum F&E Vorhaben: 0 | AB2: ="Angaben zum F&E Vorhaben: "& AC6 -> Angaben zum F&E Vorhaben: 0 | AO2: ="Angaben zum F&E Vorhaben: "& AP6 -> Angaben zum F&E Vorhaben: 0 | BB2: ="Angaben zum F&E Vorhaben: "& BC6 -> Angaben zum F&E Vorhaben: 0 | BO2: ="Angaben zum F&E Vorhaben: "& BP6 -> Angaben zum F&E Vorhaben: 0 | CB2: ="Angaben zum F&E Vorhaben: "& CC6 -> Angaben zum F&E Vorhaben: 0
B3: Dieses Tabellenblatt beschreibt ein einzelnes FuE-Vorhaben. | O3: Dieses Tabellenblatt beschreibt ein einzelnes FuE-Vorhaben. | AB3: Dieses Tabellenblatt beschreibt ein einzelnes FuE-Vorhaben. | AO3: Dieses Tabellenblatt beschreibt ein einzelnes FuE-Vorhaben. | BB3: Dieses Tabellenblatt beschreibt ein einzelnes FuE-Vorhaben. | BO3: Dieses Tabellenblatt beschreibt ein einzelnes FuE-Vorhaben. | CB3: Dieses Tabellenblatt beschreibt ein einzelnes FuE-Vorhaben.
B5: Allgemein | O5: Allgemein | AB5: Allgemein | AO5: Allgemein | BB5: Allgemein | BO5: Allgemein | CB5: Allgemein
B6: =ROUNDUP(COLUMN(C6)/$A$1,0) -> 1 | C6: {=INDIRECT("proj"&B6)} -> Ping-Pong-Roboter | O6: =ROUNDUP(COLUMN(P6)/$A$1,0) -> 2 | P6: {=INDIRECT("proj"&O6)} -> 0 | AB6: =ROUNDUP(COLUMN(AC6)/$A$1,0) -> 3 | AC6: {=INDIRECT("proj"&AB6)} -> 0 | AO6: =ROUNDUP(COLUMN(AP6)/$A$1,0) -> 4 | AP6: {=INDIRECT("proj"&AO6)} -> 0 | BB6: =ROUNDUP(COLUMN(BC6)/$A$1,0) -> 5 | BC6: {=INDIRECT("proj"&BB6)} -> 0 | BO6: =ROUNDUP(COLUMN(BP6)/$A$1,0) -> 6 | BP6: {=INDIRECT("proj"&BO6)} -> 0 | CB6: =ROUNDUP(COLUMN(CC6)/$A$1,0) -> 7 | CC6: {=INDIRECT("proj"&CB6)} -> 0
B7: Projektstart | C7: {=_xlfn.LET(_xlpm.datum,_xlfn.XLOOKUP(C6,'Ganzes Unternehmen'!$B$16:$B$22,'Ganzes Unternehmen'!$C$16:$C$22,"",0,1),IF(_xlpm.datum=0,"Bei Allg. Angaben eingeben.",_xlpm.datum))} -> 46024 | O7: Projektstart | P7: =_xlfn.LET(_xlpm.datum,_xlfn.XLOOKUP(P6,'Ganzes Unternehmen'!$B$16:$B$22,'Ganzes Unternehmen'!$C$16:$C$22,"",0,1),IF(_xlpm.datum=0,"Bei Allg. Angaben eingeben.",_xlpm.datum)) | AB7: Projektstart | AC7: =_xlfn.LET(_xlpm.datum,_xlfn.XLOOKUP(AC6,'Ganzes Unternehmen'!$B$16:$B$22,'Ganzes Unternehmen'!$C$16:$C$22,"",0,1),IF(_xlpm.datum=0,"Bei Allg. Angaben eingeben.",_xlpm.datum)) | AO7: Projektstart | AP7: =_xlfn.LET(_xlpm.datum,_xlfn.XLOOKUP(AP6,'Ganzes Unternehmen'!$B$16:$B$22,'Ganzes Unternehmen'!$C$16:$C$22,"",0,1),IF(_xlpm.datum=0,"Bei Allg. Angaben eingeben.",_xlpm.datum)) | BB7: Projektstart | BC7: =_xlfn.LET(_xlpm.datum,_xlfn.XLOOKUP(BC6,'Ganzes Unternehmen'!$B$16:$B$22,'Ganzes Unternehmen'!$C$16:$C$22,"",0,1),IF(_xlpm.datum=0,"Bei Allg. Angaben eingeben.",_xlpm.datum)) | BO7: Projektstart | BP7: =_xlfn.LET(_xlpm.datum,_xlfn.XLOOKUP(BP6,'Ganzes Unternehmen'!$B$16:$B$22,'Ganzes Unternehmen'!$C$16:$C$22,"",0,1),IF(_xlpm.datum=0,"Bei Allg. Angaben eingeben.",_xlpm.datum)) | CB7: Projektstart | CC7: =_xlfn.LET(_xlpm.datum,_xlfn.XLOOKUP(CC6,'Ganzes Unternehmen'!$B$16:$B$22,'Ganzes Unternehmen'!$C$16:$C$22,"",0,1),IF(_xlpm.datum=0,"Bei Allg. Angaben eingeben.",_xlpm.datum))
B8: Projektende | C8: {=_xlfn.LET(_xlpm.datum,_xlfn.XLOOKUP(C6,'Ganzes Unternehmen'!$B$16:$B$22,'Ganzes Unternehmen'!$D$16:$D$22,"",0,1),IF(_xlpm.datum&"1"="1","Bei Allg. Angaben eingeben.",_xlpm.datum))} -> 47118 | O8: Projektende | P8: =_xlfn.LET(_xlpm.datum,_xlfn.XLOOKUP(P6,'Ganzes Unternehmen'!$B$16:$B$22,'Ganzes Unternehmen'!$D$16:$D$22,"",0,1),IF(_xlpm.datum&"1"="1","Bei Allg. Angaben eingeben.",_xlpm.datum)) -> Bei Allg. Angaben eingeben. | AB8: Projektende | AC8: =_xlfn.LET(_xlpm.datum,_xlfn.XLOOKUP(AC6,'Ganzes Unternehmen'!$B$16:$B$22,'Ganzes Unternehmen'!$D$16:$D$22,"",0,1),IF(_xlpm.datum&"1"="1","Bei Allg. Angaben eingeben.",_xlpm.datum)) -> Bei Allg. Angaben eingeben. | AO8: Projektende | AP8: =_xlfn.LET(_xlpm.datum,_xlfn.XLOOKUP(AP6,'Ganzes Unternehmen'!$B$16:$B$22,'Ganzes Unternehmen'!$D$16:$D$22,"",0,1),IF(_xlpm.datum&"1"="1","Bei Allg. Angaben eingeben.",_xlpm.datum)) -> Bei Allg. Angaben eingeben. | BB8: Projektende | BC8: =_xlfn.LET(_xlpm.datum,_xlfn.XLOOKUP(BC6,'Ganzes Unternehmen'!$B$16:$B$22,'Ganzes Unternehmen'!$D$16:$D$22,"",0,1),IF(_xlpm.datum&"1"="1","Bei Allg. Angaben eingeben.",_xlpm.datum)) -> Bei Allg. Angaben eingeben. | BO8: Projektende | BP8: =_xlfn.LET(_xlpm.datum,_xlfn.XLOOKUP(BP6,'Ganzes Unternehmen'!$B$16:$B$22,'Ganzes Unternehmen'!$D$16:$D$22,"",0,1),IF(_xlpm.datum&"1"="1","Bei Allg. Angaben eingeben.",_xlpm.datum)) -> Bei Allg. Angaben eingeben. | CB8: Projektende | CC8: =_xlfn.LET(_xlpm.datum,_xlfn.XLOOKUP(CC6,'Ganzes Unternehmen'!$B$16:$B$22,'Ganzes Unternehmen'!$D$16:$D$22,"",0,1),IF(_xlpm.datum&"1"="1","Bei Allg. Angaben eingeben.",_xlpm.datum)) -> Bei Allg. Angaben eingeben.
C9: =IFERROR(AND(C10>=YEAR(C7),C10<=YEAR(C8)),FALSE) -> FALSE | D9: =IFERROR(AND(D10>=YEAR(C7),D10<=YEAR(C8)),FALSE) -> FALSE | E9: =IFERROR(AND(E10>=YEAR(C7),E10<=YEAR(C8)),FALSE) -> FALSE | F9: =IFERROR(AND(F10>=YEAR(C7),F10<=YEAR(C8)),FALSE) -> FALSE | G9: =IFERROR(AND(G10>=YEAR(C7),G10<=YEAR(C8)),FALSE) -> TRUE | H9: =IFERROR(AND(H10>=YEAR(C7),H10<=YEAR(C8)),FALSE) -> TRUE | I9: =IFERROR(AND(I10>=YEAR(C7),I10<=YEAR(C8)),FALSE) -> TRUE | J9: =IFERROR(AND(J10>=YEAR(C7),J10<=YEAR(C8)),FALSE) -> FALSE | P9: =IFERROR(AND(P10>=YEAR(P7),P10<=YEAR(P8)),FALSE) -> FALSE | Q9: =IFERROR(AND(Q10>=YEAR(P7),Q10<=YEAR(P8)),FALSE) -> FALSE | R9: =IFERROR(AND(R10>=YEAR(P7),R10<=YEAR(P8)),FALSE) -> FALSE | S9: =IFERROR(AND(S10>=YEAR(P7),S10<=YEAR(P8)),FALSE) -> FALSE | T9: =IFERROR(AND(T10>=YEAR(P7),T10<=YEAR(P8)),FALSE) -> FALSE | U9: =IFERROR(AND(U10>=YEAR(P7),U10<=YEAR(P8)),FALSE) -> FALSE | V9: =IFERROR(AND(V10>=YEAR(Q7),V10<=YEAR(Q8)),FALSE) -> FALSE | W9: =IFERROR(AND(W10>=YEAR(R7),W10<=YEAR(R8)),FALSE) -> FALSE | AC9: =IFERROR(AND(AC10>=YEAR(AC7),AC10<=YEAR(AC8)),FALSE) -> FALSE | AD9: =IFERROR(AND(AD10>=YEAR(AC7),AD10<=YEAR(AC8)),FALSE) -> FALSE | AE9: =IFERROR(AND(AE10>=YEAR(AC7),AE10<=YEAR(AC8)),FALSE) -> FALSE | AF9: =IFERROR(AND(AF10>=YEAR(AC7),AF10<=YEAR(AC8)),FALSE) -> FALSE | AG9: =IFERROR(AND(AG10>=YEAR(AC7),AG10<=YEAR(AC8)),FALSE) -> FALSE | AH9: =IFERROR(AND(AH10>=YEAR(AC7),AH10<=YEAR(AC8)),FALSE) -> FALSE | AI9: =IFERROR(AND(AI10>=YEAR(AD7),AI10<=YEAR(AD8)),FALSE) -> FALSE | AJ9: =IFERROR(AND(AJ10>=YEAR(AE7),AJ10<=YEAR(AE8)),FALSE) -> FALSE | AP9: =IFERROR(AND(AP10>=YEAR(AP7),AP10<=YEAR(AP8)),FALSE) -> FALSE | AQ9: =IFERROR(AND(AQ10>=YEAR(AP7),AQ10<=YEAR(AP8)),FALSE) -> FALSE | AR9: =IFERROR(AND(AR10>=YEAR(AP7),AR10<=YEAR(AP8)),FALSE) -> FALSE | AS9: =IFERROR(AND(AS10>=YEAR(AP7),AS10<=YEAR(AP8)),FALSE) -> FALSE | AT9: =IFERROR(AND(AT10>=YEAR(AP7),AT10<=YEAR(AP8)),FALSE) -> FALSE | AU9: =IFERROR(AND(AU10>=YEAR(AP7),AU10<=YEAR(AP8)),FALSE) -> FALSE | AV9: =IFERROR(AND(AV10>=YEAR(AQ7),AV10<=YEAR(AQ8)),FALSE) -> FALSE | AW9: =IFERROR(AND(AW10>=YEAR(AR7),AW10<=YEAR(AR8)),FALSE) -> FALSE | BC9: =IFERROR(AND(BC10>=YEAR(BC7),BC10<=YEAR(BC8)),FALSE) -> FALSE | BD9: =IFERROR(AND(BD10>=YEAR(BC7),BD10<=YEAR(BC8)),FALSE) -> FALSE | BE9: =IFERROR(AND(BE10>=YEAR(BC7),BE10<=YEAR(BC8)),FALSE) -> FALSE | BF9: =IFERROR(AND(BF10>=YEAR(BC7),BF10<=YEAR(BC8)),FALSE) -> FALSE | BG9: =IFERROR(AND(BG10>=YEAR(BC7),BG10<=YEAR(BC8)),FALSE) -> FALSE | BH9: =IFERROR(AND(BH10>=YEAR(BC7),BH10<=YEAR(BC8)),FALSE) -> FALSE | BI9: =IFERROR(AND(BI10>=YEAR(BD7),BI10<=YEAR(BD8)),FALSE) -> FALSE | BJ9: =IFERROR(AND(BJ10>=YEAR(BE7),BJ10<=YEAR(BE8)),FALSE) -> FALSE | BP9: =IFERROR(AND(BP10>=YEAR(BP7),BP10<=YEAR(BP8)),FALSE) -> FALSE | BQ9: =IFERROR(AND(BQ10>=YEAR(BP7),BQ10<=YEAR(BP8)),FALSE) -> FALSE | BR9: =IFERROR(AND(BR10>=YEAR(BP7),BR10<=YEAR(BP8)),FALSE) -> FALSE | BS9: =IFERROR(AND(BS10>=YEAR(BP7),BS10<=YEAR(BP8)),FALSE) -> FALSE | BT9: =IFERROR(AND(BT10>=YEAR(BP7),BT10<=YEAR(BP8)),FALSE) -> FALSE | BU9: =IFERROR(AND(BU10>=YEAR(BP7),BU10<=YEAR(BP8)),FALSE) -> FALSE | BV9: =IFERROR(AND(BV10>=YEAR(BQ7),BV10<=YEAR(BQ8)),FALSE) -> FALSE | BW9: =IFERROR(AND(BW10>=YEAR(BR7),BW10<=YEAR(BR8)),FALSE) -> FALSE | CC9: =IFERROR(AND(CC10>=YEAR(CC7),CC10<=YEAR(CC8)),FALSE) -> FALSE | CD9: =IFERROR(AND(CD10>=YEAR(CC7),CD10<=YEAR(CC8)),FALSE) -> FALSE | CE9: =IFERROR(AND(CE10>=YEAR(CC7),CE10<=YEAR(CC8)),FALSE) -> FALSE | CF9: =IFERROR(AND(CF10>=YEAR(CC7),CF10<=YEAR(CC8)),FALSE) -> FALSE | CG9: =IFERROR(AND(CG10>=YEAR(CC7),CG10<=YEAR(CC8)),FALSE) -> FALSE | CH9: =IFERROR(AND(CH10>=YEAR(CC7),CH10<=YEAR(CC8)),FALSE) -> FALSE | CI9: =IFERROR(AND(CI10>=YEAR(CD7),CI10<=YEAR(CD8)),FALSE) -> FALSE | CJ9: =IFERROR(AND(CJ10>=YEAR(CE7),CJ10<=YEAR(CE8)),FALSE) -> FALSE
B10: Finanzieller Rahmen | C10: 2022 | D10: =C10+1 -> 2023 | E10: =D10+1 -> 2024 | F10: =E10+1 -> 2025 | G10: =F10+1 -> 2026 | H10: =G10+1 -> 2027 | I10: =H10+1 -> 2028 | J10: =I10+1 -> 2029 | O10: Finanzieller Rahmen | P10: =C10 -> 2022 | Q10: =P10+1 -> 2023 | R10: =Q10+1 -> 2024 | S10: =R10+1 -> 2025 | T10: =S10+1 -> 2026 | U10: =T10+1 -> 2027 | V10: =U10+1 -> 2028 | W10: =V10+1 -> 2029 | AB10: Finanzieller Rahmen | AC10: =C10 -> 2022 | AD10: =AC10+1 -> 2023 | AE10: =AD10+1 -> 2024 | AF10: =AE10+1 -> 2025 | AG10: =AF10+1 -> 2026 | AH10: =AG10+1 -> 2027 | AI10: =AH10+1 -> 2028 | AJ10: =AI10+1 -> 2029 | AO10: Finanzieller Rahmen | AP10: =C10 -> 2022 | AQ10: =AP10+1 -> 2023 | AR10: =AQ10+1 -> 2024 | AS10: =AR10+1 -> 2025 | AT10: =AS10+1 -> 2026 | AU10: =AT10+1 -> 2027 | AV10: =AU10+1 -> 2028 | AW10: =AV10+1 -> 2029 | BB10: Finanzieller Rahmen | BC10: =C10 -> 2022 | BD10: =BC10+1 -> 2023 | BE10: =BD10+1 -> 2024 | BF10: =BE10+1 -> 2025 | BG10: =BF10+1 -> 2026 | BH10: =BG10+1 -> 2027 | BI10: =BH10+1 -> 2028 | BJ10: =BI10+1 -> 2029 | BO10: Finanzieller Rahmen | BP10: =C10 -> 2022 | BQ10: =BP10+1 -> 2023 | BR10: =BQ10+1 -> 2024 | BS10: =BR10+1 -> 2025 | BT10: =BS10+1 -> 2026 | BU10: =BT10+1 -> 2027 | BV10: =BU10+1 -> 2028 | BW10: =BV10+1 -> 2029 | CB10: Finanzieller Rahmen | CC10: =C10 -> 2022 | CD10: =CC10+1 -> 2023 | CE10: =CD10+1 -> 2024 | CF10: =CE10+1 -> 2025 | CG10: =CF10+1 -> 2026 | CH10: =CG10+1 -> 2027 | CI10: =CH10+1 -> 2028 | CJ10: =CH10+1 -> 2028
B11: Personalkosten [€] | C11: =_xlfn.LET(_xlpm.out,ROUND((1+C13/100)*C12,2), IF(C9,_xlpm.out,0)) -> 0 | D11: =_xlfn.LET(_xlpm.out,ROUND((1+D13/100)*D12,2), IF(D9,_xlpm.out,0)) -> 0 | E11: =_xlfn.LET(_xlpm.out,ROUND((1+E13/100)*E12,2), IF(E9,_xlpm.out,0)) -> 0 | F11: =_xlfn.LET(_xlpm.out,ROUND((1+F13/100)*F12,2), IF(F9,_xlpm.out,0)) -> 0 | G11: {=_xlfn.LET(_xlpm.out,ROUND((1+G13/100)*G12,2), IF(G9,_xlpm.out,0))} -> 2730 | H11: {=_xlfn.LET(_xlpm.out,ROUND((1+H13/100)*H12,2), IF(H9,_xlpm.out,0))} -> 8190 | I11: {=_xlfn.LET(_xlpm.out,ROUND((1+I13/100)*I12,2), IF(I9,_xlpm.out,0))} -> 16380 | J11: {=_xlfn.LET(_xlpm.out,ROUND((1+J13/100)*J12,2), IF(J9,_xlpm.out,0))} -> 0 | O11: Personalkosten [€] | P11: =_xlfn.LET(_xlpm.out,ROUND((1+P13/100)*P12+P14,2), IF(P9,_xlpm.out,0)) -> 0 | Q11: =_xlfn.LET(_xlpm.out,ROUND((1+Q13/100)*Q12+Q14,2), IF(Q9,_xlpm.out,0)) -> 0 | R11: =_xlfn.LET(_xlpm.out,ROUND((1+R13/100)*R12+R14,2), IF(R9,_xlpm.out,0)) -> 0 | S11: =_xlfn.LET(_xlpm.out,ROUND((1+S13/100)*S12+S14,2), IF(S9,_xlpm.out,0)) -> 0 | T11: =_xlfn.LET(_xlpm.out,ROUND((1+T13/100)*T12+T14,2), IF(T9,_xlpm.out,0)) -> 0 | U11: =_xlfn.LET(_xlpm.out,ROUND((1+U13/100)*U12+U14,2), IF(U9,_xlpm.out,0)) -> 0 | V11: =_xlfn.LET(_xlpm.out,ROUND((1+V13/100)*V12+V14,2), IF(V9,_xlpm.out,0)) -> 0 | W11: =_xlfn.LET(_xlpm.out,ROUND((1+W13/100)*W12+W14,2), IF(W9,_xlpm.out,0)) -> 0 | AB11: Personalkosten [€] | AC11: =_xlfn.LET(_xlpm.out,ROUND((1+AC13/100)*AC12+AC14,2), IF(AC9,_xlpm.out,0)) -> 0 | AD11: =_xlfn.LET(_xlpm.out,ROUND((1+AD13/100)*AD12+AD14,2), IF(AD9,_xlpm.out,0)) -> 0 | AE11: =_xlfn.LET(_xlpm.out,ROUND((1+AE13/100)*AE12+AE14,2), IF(AE9,_xlpm.out,0)) -> 0 | AF11: =_xlfn.LET(_xlpm.out,ROUND((1+AF13/100)*AF12+AF14,2), IF(AF9,_xlpm.out,0)) -> 0 | AG11: =_xlfn.LET(_xlpm.out,ROUND((1+AG13/100)*AG12+AG14,2), IF(AG9,_xlpm.out,0)) -> 0 | AH11: =_xlfn.LET(_xlpm.out,ROUND((1+AH13/100)*AH12+AH14,2), IF(AH9,_xlpm.out,0)) -> 0 | AI11: =_xlfn.LET(_xlpm.out,ROUND((1+AI13/100)*AI12+AI14,2), IF(AI9,_xlpm.out,0)) -> 0 | AJ11: =_xlfn.LET(_xlpm.out,ROUND((1+AJ13/100)*AJ12+AJ14,2), IF(AJ9,_xlpm.out,0)) -> 0 | AO11: Personalkosten [€] | AP11: =_xlfn.LET(_xlpm.out,ROUND((1+AP13/100)*AP12+AP14,2), IF(AP9,_xlpm.out,0)) -> 0 | AQ11: =_xlfn.LET(_xlpm.out,ROUND((1+AQ13/100)*AQ12+AQ14,2), IF(AQ9,_xlpm.out,0)) -> 0 | AR11: =_xlfn.LET(_xlpm.out,ROUND((1+AR13/100)*AR12+AR14,2), IF(AR9,_xlpm.out,0)) -> 0 | AS11: =_xlfn.LET(_xlpm.out,ROUND((1+AS13/100)*AS12+AS14,2), IF(AS9,_xlpm.out,0)) -> 0 | AT11: =_xlfn.LET(_xlpm.out,ROUND((1+AT13/100)*AT12+AT14,2), IF(AT9,_xlpm.out,0)) -> 0 | AU11: =_xlfn.LET(_xlpm.out,ROUND((1+AU13/100)*AU12+AU14,2), IF(AU9,_xlpm.out,0)) -> 0 | AV11: =_xlfn.LET(_xlpm.out,ROUND((1+AV13/100)*AV12+AV14,2), IF(AV9,_xlpm.out,0)) -> 0 | AW11: =_xlfn.LET(_xlpm.out,ROUND((1+AW13/100)*AW12+AW14,2), IF(AW9,_xlpm.out,0)) -> 0 | BB11: Personalkosten [€] | BC11: =_xlfn.LET(_xlpm.out,ROUND((1+BC13/100)*BC12+BC14,2), IF(BC9,_xlpm.out,0)) -> 0 | BD11: =_xlfn.LET(_xlpm.out,ROUND((1+BD13/100)*BD12+BD14,2), IF(BD9,_xlpm.out,0)) -> 0 | BE11: =_xlfn.LET(_xlpm.out,ROUND((1+BE13/100)*BE12+BE14,2), IF(BE9,_xlpm.out,0)) -> 0 | BF11: =_xlfn.LET(_xlpm.out,ROUND((1+BF13/100)*BF12+BF14,2), IF(BF9,_xlpm.out,0)) -> 0 | BG11: =_xlfn.LET(_xlpm.out,ROUND((1+BG13/100)*BG12+BG14,2), IF(BG9,_xlpm.out,0)) -> 0 | BH11: =_xlfn.LET(_xlpm.out,ROUND((1+BH13/100)*BH12+BH14,2), IF(BH9,_xlpm.out,0)) -> 0 | BI11: =_xlfn.LET(_xlpm.out,ROUND((1+BI13/100)*BI12+BI14,2), IF(BI9,_xlpm.out,0)) -> 0 | BJ11: =_xlfn.LET(_xlpm.out,ROUND((1+BJ13/100)*BJ12+BJ14,2), IF(BJ9,_xlpm.out,0)) -> 0 | BO11: Personalkosten [€] | BP11: =_xlfn.LET(_xlpm.out,ROUND((1+BP13/100)*BP12+BP14,2), IF(BP9,_xlpm.out,0)) -> 0 | BQ11: =_xlfn.LET(_xlpm.out,ROUND((1+BQ13/100)*BQ12+BQ14,2), IF(BQ9,_xlpm.out,0)) -> 0 | BR11: =_xlfn.LET(_xlpm.out,ROUND((1+BR13/100)*BR12+BR14,2), IF(BR9,_xlpm.out,0)) -> 0 | BS11: =_xlfn.LET(_xlpm.out,ROUND((1+BS13/100)*BS12+BS14,2), IF(BS9,_xlpm.out,0)) -> 0 | BT11: =_xlfn.LET(_xlpm.out,ROUND((1+BT13/100)*BT12+BT14,2), IF(BT9,_xlpm.out,0)) -> 0 | BU11: =_xlfn.LET(_xlpm.out,ROUND((1+BU13/100)*BU12+BU14,2), IF(BU9,_xlpm.out,0)) -> 0 | BV11: =_xlfn.LET(_xlpm.out,ROUND((1+BV13/100)*BV12+BV14,2), IF(BV9,_xlpm.out,0)) -> 0 | BW11: =_xlfn.LET(_xlpm.out,ROUND((1+BW13/100)*BW12+BW14,2), IF(BW9,_xlpm.out,0)) -> 0 | CB11: Personalkosten [€] | CC11: =_xlfn.LET(_xlpm.out,ROUND((1+CC13/100)*CC12+CC14,2), IF(CC9,_xlpm.out,0)) -> 0 | CD11: =_xlfn.LET(_xlpm.out,ROUND((1+CD13/100)*CD12+CD14,2), IF(CD9,_xlpm.out,0)) -> 0 | CE11: =_xlfn.LET(_xlpm.out,ROUND((1+CE13/100)*CE12+CE14,2), IF(CE9,_xlpm.out,0)) -> 0 | CF11: =_xlfn.LET(_xlpm.out,ROUND((1+CF13/100)*CF12+CF14,2), IF(CF9,_xlpm.out,0)) -> 0 | CG11: =_xlfn.LET(_xlpm.out,ROUND((1+CG13/100)*CG12+CG14,2), IF(CG9,_xlpm.out,0)) -> 0 | CH11: =_xlfn.LET(_xlpm.out,ROUND((1+CH13/100)*CH12+CH14,2), IF(CH9,_xlpm.out,0)) -> 0 | CI11: =_xlfn.LET(_xlpm.out,ROUND((1+CI13/100)*CI12+CI14,2), IF(CI9,_xlpm.out,0)) -> 0 | CJ11: =_xlfn.LET(_xlpm.out,ROUND((1+CJ13/100)*CJ12+CJ14,2), IF(CJ9,_xlpm.out,0)) -> 0
B12: Personalkosten kalkuliert [€] | C12: =ROUND(SUMIFS(MitarbeiterFTE[[Kosten]:[Kosten]],MitarbeiterFTE[[Jahr]:[Jahr]],C10,MitarbeiterFTE[[Vorhaben]:[Vorhaben]],C75),2) -> 0 | D12: =ROUND(SUMIFS(MitarbeiterFTE[[Kosten]:[Kosten]],MitarbeiterFTE[[Jahr]:[Jahr]],D10,MitarbeiterFTE[[Vorhaben]:[Vorhaben]],D75),2) -> 0 | E12: =ROUND(SUMIFS(MitarbeiterFTE[[Kosten]:[Kosten]],MitarbeiterFTE[[Jahr]:[Jahr]],E10,MitarbeiterFTE[[Vorhaben]:[Vorhaben]],E75),2) -> 0 | F12: =ROUND(SUMIFS(MitarbeiterFTE[[Kosten]:[Kosten]],MitarbeiterFTE[[Jahr]:[Jahr]],F10,MitarbeiterFTE[[Vorhaben]:[Vorhaben]],F75),2) -> 0 | G12: =ROUND(SUMIFS(MitarbeiterFTE[[Kosten]:[Kosten]],MitarbeiterFTE[[Jahr]:[Jahr]],G10,MitarbeiterFTE[[Vorhaben]:[Vorhaben]],G75),2) -> 2600 | H12: =ROUND(SUMIFS(MitarbeiterFTE[[Kosten]:[Kosten]],MitarbeiterFTE[[Jahr]:[Jahr]],H10,MitarbeiterFTE[[Vorhaben]:[Vorhaben]],H75),2) -> 7800 | I12: =ROUND(SUMIFS(MitarbeiterFTE[[Kosten]:[Kosten]],MitarbeiterFTE[[Jahr]:[Jahr]],I10,MitarbeiterFTE[[Vorhaben]:[Vorhaben]],I75),2) -> 15600 | J12: =ROUND(SUMIFS(MitarbeiterFTE[[Kosten]:[Kosten]],MitarbeiterFTE[[Jahr]:[Jahr]],J10,MitarbeiterFTE[[Vorhaben]:[Vorhaben]],J75),2) -> 0 | O12: Personalkosten kalkuliert [€] | P12: =ROUND(SUMIFS(MitarbeiterFTE[[Kosten]:[Kosten]],MitarbeiterFTE[[Jahr]:[Jahr]],P10,MitarbeiterFTE[[Vorhaben]:[Vorhaben]],P75),2) -> 0 | Q12: =ROUND(SUMIFS(MitarbeiterFTE[[Kosten]:[Kosten]],MitarbeiterFTE[[Jahr]:[Jahr]],Q10,MitarbeiterFTE[[Vorhaben]:[Vorhaben]],Q75),2) -> 0 | R12: =ROUND(SUMIFS(MitarbeiterFTE[[Kosten]:[Kosten]],MitarbeiterFTE[[Jahr]:[Jahr]],R10,MitarbeiterFTE[[Vorhaben]:[Vorhaben]],R75),2) -> 0 | S12: =ROUND(SUMIFS(MitarbeiterFTE[[Kosten]:[Kosten]],MitarbeiterFTE[[Jahr]:[Jahr]],S10,MitarbeiterFTE[[Vorhaben]:[Vorhaben]],S75),2) -> 0 | T12: =ROUND(SUMIFS(MitarbeiterFTE[[Kosten]:[Kosten]],MitarbeiterFTE[[Jahr]:[Jahr]],T10,MitarbeiterFTE[[Vorhaben]:[Vorhaben]],T75),2) -> 0 | U12: =ROUND(SUMIFS(MitarbeiterFTE[[Kosten]:[Kosten]],MitarbeiterFTE[[Jahr]:[Jahr]],U10,MitarbeiterFTE[[Vorhaben]:[Vorhaben]],U75),2) -> 0 | V12: =ROUND(SUMIFS(MitarbeiterFTE[[Kosten]:[Kosten]],MitarbeiterFTE[[Jahr]:[Jahr]],V10,MitarbeiterFTE[[Vorhaben]:[Vorhaben]],V75),2) -> 0 | W12: =ROUND(SUMIFS(MitarbeiterFTE[[Kosten]:[Kosten]],MitarbeiterFTE[[Jahr]:[Jahr]],W10,MitarbeiterFTE[[Vorhaben]:[Vorhaben]],W75),2) -> 0 | AB12: Personalkosten kalkuliert [€] | AC12: =ROUND(SUMIFS(MitarbeiterFTE[[Kosten]:[Kosten]],MitarbeiterFTE[[Jahr]:[Jahr]],AC10,MitarbeiterFTE[[Vorhaben]:[Vorhaben]],AC75),2) -> 0 | AE12: =ROUND(SUMIFS(MitarbeiterFTE[[Kosten]:[Kosten]],MitarbeiterFTE[[Jahr]:[Jahr]],AE10,MitarbeiterFTE[[Vorhaben]:[Vorhaben]],AE75),2) -> 0 | AF12: =ROUND(SUMIFS(MitarbeiterFTE[[Kosten]:[Kosten]],MitarbeiterFTE[[Jahr]:[Jahr]],AF10,MitarbeiterFTE[[Vorhaben]:[Vorhaben]],AF75),2) -> 0 | AG12: =ROUND(SUMIFS(MitarbeiterFTE[[Kosten]:[Kosten]],MitarbeiterFTE[[Jahr]:[Jahr]],AG10,MitarbeiterFTE[[Vorhaben]:[Vorhaben]],AG75),2) -> 0 | AH12: =ROUND(SUMIFS(MitarbeiterFTE[[Kosten]:[Kosten]],MitarbeiterFTE[[Jahr]:[Jahr]],AH10,MitarbeiterFTE[[Vorhaben]:[Vorhaben]],AH75),2) -> 0 | AI12: =ROUND(SUMIFS(MitarbeiterFTE[[Kosten]:[Kosten]],MitarbeiterFTE[[Jahr]:[Jahr]],AI10,MitarbeiterFTE[[Vorhaben]:[Vorhaben]],AI75),2) -> 0 | AJ12: =ROUND(SUMIFS(MitarbeiterFTE[[Kosten]:[Kosten]],MitarbeiterFTE[[Jahr]:[Jahr]],AJ10,MitarbeiterFTE[[Vorhaben]:[Vorhaben]],AJ75),2) -> 0 | AO12: Personalkosten kalkuliert [€] | AP12: =ROUND(SUMIFS(MitarbeiterFTE[[Kosten]:[Kosten]],MitarbeiterFTE[[Jahr]:[Jahr]],AP10,MitarbeiterFTE[[Vorhaben]:[Vorhaben]],AP75),2) -> 0 | AR12: =ROUND(SUMIFS(MitarbeiterFTE[[Kosten]:[Kosten]],MitarbeiterFTE[[Jahr]:[Jahr]],AR10,MitarbeiterFTE[[Vorhaben]:[Vorhaben]],AR75),2) -> 0 | AS12: =ROUND(SUMIFS(MitarbeiterFTE[[Kosten]:[Kosten]],MitarbeiterFTE[[Jahr]:[Jahr]],AS10,MitarbeiterFTE[[Vorhaben]:[Vorhaben]],AS75),2) -> 0 | AT12: =ROUND(SUMIFS(MitarbeiterFTE[[Kosten]:[Kosten]],MitarbeiterFTE[[Jahr]:[Jahr]],AT10,MitarbeiterFTE[[Vorhaben]:[Vorhaben]],AT75),2) -> 0 | AU12: =ROUND(SUMIFS(MitarbeiterFTE[[Kosten]:[Kosten]],MitarbeiterFTE[[Jahr]:[Jahr]],AU10,MitarbeiterFTE[[Vorhaben]:[Vorhaben]],AU75),2) -> 0 | AV12: =ROUND(SUMIFS(MitarbeiterFTE[[Kosten]:[Kosten]],MitarbeiterFTE[[Jahr]:[Jahr]],AV10,MitarbeiterFTE[[Vorhaben]:[Vorhaben]],AV75),2) -> 0 | AW12: =ROUND(SUMIFS(MitarbeiterFTE[[Kosten]:[Kosten]],MitarbeiterFTE[[Jahr]:[Jahr]],AW10,MitarbeiterFTE[[Vorhaben]:[Vorhaben]],AW75),2) -> 0 | BB12: Personalkosten kalkuliert [€] | BC12: =ROUND(SUMIFS(MitarbeiterFTE[[Kosten]:[Kosten]],MitarbeiterFTE[[Jahr]:[Jahr]],BC10,MitarbeiterFTE[[Vorhaben]:[Vorhaben]],BC75),2) -> 0 | BE12: =ROUND(SUMIFS(MitarbeiterFTE[[Kosten]:[Kosten]],MitarbeiterFTE[[Jahr]:[Jahr]],BE10,MitarbeiterFTE[[Vorhaben]:[Vorhaben]],BE75),2) -> 0 | BF12: =ROUND(SUMIFS(MitarbeiterFTE[[Kosten]:[Kosten]],MitarbeiterFTE[[Jahr]:[Jahr]],BF10,MitarbeiterFTE[[Vorhaben]:[Vorhaben]],BF75),2) -> 0 | BG12: =ROUND(SUMIFS(MitarbeiterFTE[[Kosten]:[Kosten]],MitarbeiterFTE[[Jahr]:[Jahr]],BG10,MitarbeiterFTE[[Vorhaben]:[Vorhaben]],BG75),2) -> 0 | BH12: =ROUND(SUMIFS(MitarbeiterFTE[[Kosten]:[Kosten]],MitarbeiterFTE[[Jahr]:[Jahr]],BH10,MitarbeiterFTE[[Vorhaben]:[Vorhaben]],BH75),2) -> 0 | BI12: =ROUND(SUMIFS(MitarbeiterFTE[[Kosten]:[Kosten]],MitarbeiterFTE[[Jahr]:[Jahr]],BI10,MitarbeiterFTE[[Vorhaben]:[Vorhaben]],BI75),2) -> 0 | BJ12: =ROUND(SUMIFS(MitarbeiterFTE[[Kosten]:[Kosten]],MitarbeiterFTE[[Jahr]:[Jahr]],BJ10,MitarbeiterFTE[[Vorhaben]:[Vorhaben]],BJ75),2) -> 0 | BO12: Personalkosten kalkuliert [€] | BP12: =ROUND(SUMIFS(MitarbeiterFTE[[Kosten]:[Kosten]],MitarbeiterFTE[[Jahr]:[Jahr]],BP10,MitarbeiterFTE[[Vorhaben]:[Vorhaben]],BP75),2) -> 0 | BR12: =ROUND(SUMIFS(MitarbeiterFTE[[Kosten]:[Kosten]],MitarbeiterFTE[[Jahr]:[Jahr]],BR10,MitarbeiterFTE[[Vorhaben]:[Vorhaben]],BR75),2) -> 0 | BS12: =ROUND(SUMIFS(MitarbeiterFTE[[Kosten]:[Kosten]],MitarbeiterFTE[[Jahr]:[Jahr]],BS10,MitarbeiterFTE[[Vorhaben]:[Vorhaben]],BS75),2) -> 0 | BT12: =ROUND(SUMIFS(MitarbeiterFTE[[Kosten]:[Kosten]],MitarbeiterFTE[[Jahr]:[Jahr]],BT10,MitarbeiterFTE[[Vorhaben]:[Vorhaben]],BT75),2) -> 0 | BU12: =ROUND(SUMIFS(MitarbeiterFTE[[Kosten]:[Kosten]],MitarbeiterFTE[[Jahr]:[Jahr]],BU10,MitarbeiterFTE[[Vorhaben]:[Vorhaben]],BU75),2) -> 0 | BV12: =ROUND(SUMIFS(MitarbeiterFTE[[Kosten]:[Kosten]],MitarbeiterFTE[[Jahr]:[Jahr]],BV10,MitarbeiterFTE[[Vorhaben]:[Vorhaben]],BV75),2) -> 0 | BW12: =ROUND(SUMIFS(MitarbeiterFTE[[Kosten]:[Kosten]],MitarbeiterFTE[[Jahr]:[Jahr]],BW10,MitarbeiterFTE[[Vorhaben]:[Vorhaben]],BW75),2) -> 0 | CB12: Personalkosten kalkuliert [€] | CC12: =ROUND(SUMIFS(MitarbeiterFTE[[Kosten]:[Kosten]],MitarbeiterFTE[[Jahr]:[Jahr]],CC10,MitarbeiterFTE[[Vorhaben]:[Vorhaben]],CC75),2) -> 0 | CE12: =ROUND(SUMIFS(MitarbeiterFTE[[Kosten]:[Kosten]],MitarbeiterFTE[[Jahr]:[Jahr]],CE10,MitarbeiterFTE[[Vorhaben]:[Vorhaben]],CE75),2) -> 0 | CF12: =ROUND(SUMIFS(MitarbeiterFTE[[Kosten]:[Kosten]],MitarbeiterFTE[[Jahr]:[Jahr]],CF10,MitarbeiterFTE[[Vorhaben]:[Vorhaben]],CF75),2) -> 0 | CG12: 0 | CH12: =ROUND(SUMIFS(MitarbeiterFTE[[Kosten]:[Kosten]],MitarbeiterFTE[[Jahr]:[Jahr]],CH10,MitarbeiterFTE[[Vorhaben]:[Vorhaben]],CH75),2) -> 0 | CI12: =ROUND(SUMIFS(MitarbeiterFTE[[Kosten]:[Kosten]],MitarbeiterFTE[[Jahr]:[Jahr]],CI10,MitarbeiterFTE[[Vorhaben]:[Vorhaben]],CI75),2) -> 0 | CJ12: =ROUND(SUMIFS(MitarbeiterFTE[[Kosten]:[Kosten]],MitarbeiterFTE[[Jahr]:[Jahr]],CJ10,MitarbeiterFTE[[Vorhaben]:[Vorhaben]],CJ75),2) -> 0
B13: Aufschlag für Puffer [%] | C13: =_xlfn.LET( _xlpm.aktuellesJahrt,YEAR(TODAY()), IF(C10<_xlpm.aktuellesJahrt,0,IF(C10=_xlpm.aktuellesJahrt,15,IF(C10>_xlpm.aktuellesJahrt,30))) ) -> 0 | D13: =_xlfn.LET( _xlpm.aktuellesJahrt,YEAR(TODAY()), IF(D10<_xlpm.aktuellesJahrt,0,IF(D10=_xlpm.aktuellesJahrt,15,IF(D10>_xlpm.aktuellesJahrt,30))) ) -> 0 | E13: {=_xlfn.LET( _xlpm.aktuellesJahrt,YEAR(TODAY()), IF(E10<_xlpm.aktuellesJahrt,0,IF(E10=_xlpm.aktuellesJahrt,15,IF(E10>_xlpm.aktuellesJahrt,30))) )} -> 0 | F13: 0 | G13: 5 | H13: 5 | I13: 5 | J13: 5 | O13: Aufschlag für Puffer [%] | P13: =_xlfn.LET( _xlpm.aktuellesJahrt,YEAR(TODAY()), IF(P10<_xlpm.aktuellesJahrt,0,IF(P10=_xlpm.aktuellesJahrt,15,IF(P10>_xlpm.aktuellesJahrt,30))) ) -> 0 | Q13: =_xlfn.LET( _xlpm.aktuellesJahrt,YEAR(TODAY()), IF(Q10<_xlpm.aktuellesJahrt,0,IF(Q10=_xlpm.aktuellesJahrt,15,IF(Q10>_xlpm.aktuellesJahrt,30))) ) -> 0 | R13: =_xlfn.LET( _xlpm.aktuellesJahrt,YEAR(TODAY()), IF(R10<_xlpm.aktuellesJahrt,0,IF(R10=_xlpm.aktuellesJahrt,15,IF(R10>_xlpm.aktuellesJahrt,30))) ) -> 0 | S13: 5 | T13: 5 | U13: 5 | V13: 5 | W13: 5 | AB13: Aufschlag für Puffer [%] | AC13: =_xlfn.LET( _xlpm.aktuellesJahrt,YEAR(TODAY()), IF(AC10<_xlpm.aktuellesJahrt,0,IF(AC10=_xlpm.aktuellesJahrt,15,IF(AC10>_xlpm.aktuellesJahrt,30))) ) -> 0 | AD13: =_xlfn.LET( _xlpm.aktuellesJahrt,YEAR(TODAY()), IF(AD10<_xlpm.aktuellesJahrt,0,IF(AD10=_xlpm.aktuellesJahrt,15,IF(AD10>_xlpm.aktuellesJahrt,30))) ) -> 0 | AE13: =_xlfn.LET( _xlpm.aktuellesJahrt,YEAR(TODAY()), IF(AE10<_xlpm.aktuellesJahrt,0,IF(AE10=_xlpm.aktuellesJahrt,15,IF(AE10>_xlpm.aktuellesJahrt,30))) ) -> 0 | AF13: 5 | AG13: 5 | AH13: 5 | AI13: 5 | AJ13: 5 | AO13: Aufschlag für Puffer [%] | AP13: =_xlfn.LET( _xlpm.aktuellesJahrt,YEAR(TODAY()), IF(AP10<_xlpm.aktuellesJahrt,0,IF(AP10=_xlpm.aktuellesJahrt,15,IF(AP10>_xlpm.aktuellesJahrt,30))) ) -> 0 | AQ13: =_xlfn.LET( _xlpm.aktuellesJahrt,YEAR(TODAY()), IF(AQ10<_xlpm.aktuellesJahrt,0,IF(AQ10=_xlpm.aktuellesJahrt,15,IF(AQ10>_xlpm.aktuellesJahrt,30))) ) -> 0 | AR13: =_xlfn.LET( _xlpm.aktuellesJahrt,YEAR(TODAY()), IF(AR10<_xlpm.aktuellesJahrt,0,IF(AR10=_xlpm.aktuellesJahrt,15,IF(AR10>_xlpm.aktuellesJahrt,30))) ) -> 0 | AS13: 5 | AT13: 5 | AU13: 5 | AV13: 5 | AW13: 5 | BB13: Aufschlag für Puffer [%] | BC13: =_xlfn.LET( _xlpm.aktuellesJahrt,YEAR(TODAY()), IF(BC10<_xlpm.aktuellesJahrt,0,IF(BC10=_xlpm.aktuellesJahrt,15,IF(BC10>_xlpm.aktuellesJahrt,30))) ) -> 0 | BD13: =_xlfn.LET( _xlpm.aktuellesJahrt,YEAR(TODAY()), IF(BD10<_xlpm.aktuellesJahrt,0,IF(BD10=_xlpm.aktuellesJahrt,15,IF(BD10>_xlpm.aktuellesJahrt,30))) ) -> 0 | BE13: =_xlfn.LET( _xlpm.aktuellesJahrt,YEAR(TODAY()), IF(BE10<_xlpm.aktuellesJahrt,0,IF(BE10=_xlpm.aktuellesJahrt,15,IF(BE10>_xlpm.aktuellesJahrt,30))) ) -> 0 | BF13: 5 | BG13: 5 | BH13: 5 | BI13: 5 | BJ13: 5 | BO13: Aufschlag für Puffer [%] | BP13: =_xlfn.LET( _xlpm.aktuellesJahrt,YEAR(TODAY()), IF(BP10<_xlpm.aktuellesJahrt,0,IF(BP10=_xlpm.aktuellesJahrt,15,IF(BP10>_xlpm.aktuellesJahrt,30))) ) -> 0 | BQ13: =_xlfn.LET( _xlpm.aktuellesJahrt,YEAR(TODAY()), IF(BQ10<_xlpm.aktuellesJahrt,0,IF(BQ10=_xlpm.aktuellesJahrt,15,IF(BQ10>_xlpm.aktuellesJahrt,30))) ) -> 0 | BR13: =_xlfn.LET( _xlpm.aktuellesJahrt,YEAR(TODAY()), IF(BR10<_xlpm.aktuellesJahrt,0,IF(BR10=_xlpm.aktuellesJahrt,15,IF(BR10>_xlpm.aktuellesJahrt,30))) ) -> 0 | BS13: 5 | BT13: 5 | BU13: 5 | BV13: 5 | BW13: 5 | CB13: Aufschlag für Puffer [%] | CC13: =_xlfn.LET( _xlpm.aktuellesJahrt,YEAR(TODAY()), IF(CC10<_xlpm.aktuellesJahrt,0,IF(CC10=_xlpm.aktuellesJahrt,15,IF(CC10>_xlpm.aktuellesJahrt,30))) ) -> 0 | CD13: =_xlfn.LET( _xlpm.aktuellesJahrt,YEAR(TODAY()), IF(CD10<_xlpm.aktuellesJahrt,0,IF(CD10=_xlpm.aktuellesJahrt,15,IF(CD10>_xlpm.aktuellesJahrt,30))) ) -> 0 | CE13: =_xlfn.LET( _xlpm.aktuellesJahrt,YEAR(TODAY()), IF(CE10<_xlpm.aktuellesJahrt,0,IF(CE10=_xlpm.aktuellesJahrt,15,IF(CE10>_xlpm.aktuellesJahrt,30))) ) -> 0 | CF13: 5 | CG13: 5 | CH13: 5 | CI13: 5 | CJ13: 5
B14: Kosten aus Eigenleistung [€] (nur bei Einzelunternehmen und Personengesellschaft) | C14: =C15*(IF(C10<2025,40,IF(C10<2026,70,100))) -> 0 | D14: =D15*(IF(D10<2025,40,IF(D10<2026,70,100))) -> 0 | E14: =E15*(IF(E10<2025,40,IF(E10<2026,70,100))) -> 0 | F14: =F15*(IF(F10<2025,40,IF(F10<2026,70,100))) -> 0 | G14: =G15*(IF(G10<2025,40,IF(G10<2026,70,100))) -> 42000 | H14: =H15*(IF(H10<2025,40,IF(H10<2026,70,100))) -> 104000 | I14: =I15*(IF(I10<2025,40,IF(I10<2026,70,100))) -> 104000 | J14: =J15*(IF(J10<2025,40,IF(J10<2026,70,100))) -> 0 | O14: Personalkosten Einzelunternehmen | P14: =P15*(IF(P10<2025,40,IF(P10<2026,70,100))) -> 0 | Q14: =Q15*(IF(Q10<2025,40,IF(Q10<2026,70,100))) -> 0 | R14: =R15*(IF(R10<2025,40,IF(R10<2026,70,100))) -> 0 | S14: =S15*(IF(S10<2025,40,IF(S10<2026,70,100))) -> 0 | T14: =T15*(IF(T10<2025,40,IF(T10<2026,70,100))) -> 0 | U14: =U15*(IF(U10<2025,40,IF(U10<2026,70,100))) -> 0 | V14: =V15*(IF(V10<2025,40,IF(V10<2026,70,100))) -> 0 | W14: =W15*(IF(W10<2025,40,IF(W10<2026,70,100))) -> 0 | AB14: Personalkosten Einzelunternehmen | AC14: =AC15*(IF(AC10<2025,40,IF(AC10<2026,70,100))) -> 0 | AD14: =AD15*(IF(AD10<2025,40,IF(AD10<2026,70,100))) -> 0 | AE14: =AE15*(IF(AE10<2025,40,IF(AE10<2026,70,100))) -> 0 | AF14: =AF15*(IF(AF10<2025,40,IF(AF10<2026,70,100))) -> 0 | AG14: =AG15*(IF(AG10<2025,40,IF(AG10<2026,70,100))) -> 0 | AH14: =AH15*(IF(AH10<2025,40,IF(AH10<2026,70,100))) -> 0 | AI14: =AI15*(IF(AI10<2025,40,IF(AI10<2026,70,100))) -> 0 | AJ14: =AJ15*(IF(AJ10<2025,40,IF(AJ10<2026,70,100))) -> 0 | AO14: Personalkosten Einzelunternehmen | AP14: =AP15*(IF(AP10<2025,40,IF(AP10<2026,70,100))) -> 0 | AQ14: =AQ15*(IF(AQ10<2025,40,IF(AQ10<2026,70,100))) -> 0 | AR14: =AR15*(IF(AR10<2025,40,IF(AR10<2026,70,100))) -> 0 | AS14: =AS15*(IF(AS10<2025,40,IF(AS10<2026,70,100))) -> 0 | AT14: =AT15*(IF(AT10<2025,40,IF(AT10<2026,70,100))) -> 0 | AU14: =AU15*(IF(AU10<2025,40,IF(AU10<2026,70,100))) -> 0 | AV14: =AV15*(IF(AV10<2025,40,IF(AV10<2026,70,100))) -> 0 | AW14: =AW15*(IF(AW10<2025,40,IF(AW10<2026,70,100))) -> 0 | BB14: Personalkosten Einzelunternehmen | BC14: =BC15*(IF(BC10<2025,40,IF(BC10<2026,70,100))) -> 0 | BD14: =BD15*(IF(BD10<2025,40,IF(BD10<2026,70,100))) -> 0 | BE14: =BE15*(IF(BE10<2025,40,IF(BE10<2026,70,100))) -> 0 | BF14: =BF15*(IF(BF10<2025,40,IF(BF10<2026,70,100))) -> 0 | BG14: =BG15*(IF(BG10<2025,40,IF(BG10<2026,70,100))) -> 0 | BH14: =BH15*(IF(BH10<2025,40,IF(BH10<2026,70,100))) -> 0 | BI14: =BI15*(IF(BI10<2025,40,IF(BI10<2026,70,100))) -> 0 | BJ14: =BJ15*(IF(BJ10<2025,40,IF(BJ10<2026,70,100))) -> 0 | BO14: Personalkosten Einzelunternehmen | BP14: =BP15*(IF(BP10<2025,40,IF(BP10<2026,70,100))) -> 0 | BQ14: =BQ15*(IF(BQ10<2025,40,IF(BQ10<2026,70,100))) -> 0 | BR14: =BR15*(IF(BR10<2025,40,IF(BR10<2026,70,100))) -> 0 | BS14: =BS15*(IF(BS10<2025,40,IF(BS10<2026,70,100))) -> 0 | BT14: =BT15*(IF(BT10<2025,40,IF(BT10<2026,70,100))) -> 0 | BU14: =BU15*(IF(BU10<2025,40,IF(BU10<2026,70,100))) -> 0 | BV14: =BV15*(IF(BV10<2025,40,IF(BV10<2026,70,100))) -> 0 | BW14: =BW15*(IF(BW10<2025,40,IF(BW10<2026,70,100))) -> 0 | CB14: Personalkosten Einzelunternehmen | CC14: =CC15*(IF(CC10<2025,40,IF(CC10<2026,70,100))) -> 0 | CD14: =CD15*(IF(CD10<2025,40,IF(CD10<2026,70,100))) -> 0 | CE14: =CE15*(IF(CE10<2025,40,IF(CE10<2026,70,100))) -> 0 | CF14: =CF15*(IF(CF10<2025,40,IF(CF10<2026,70,100))) -> 0 | CG14: =CG15*(IF(CG10<2025,40,IF(CG10<2026,70,100))) -> 0 | CH14: =CH15*(IF(CH10<2025,40,IF(CH10<2026,70,100))) -> 0 | CI14: =CI15*(IF(CI10<2025,40,IF(CI10<2026,70,100))) -> 0 | CJ14: =CJ15*(IF(CJ10<2025,40,IF(CJ10<2026,70,100))) -> 0
B15: Arbeitsstunden aus Eigenleistung gesamt am Projekt | G15: =100+4*20*4 -> 420 | H15: =52*20 -> 1040 | I15: =52*20 -> 1040 | O15: Arbeitsstunden gesamt am Projekt | AB15: Arbeitsstunden gesamt am Projekt | AO15: Arbeitsstunden gesamt am Projekt | BB15: Arbeitsstunden gesamt am Projekt | BO15: Arbeitsstunden gesamt am Projekt | CB15: Arbeitsstunden gesamt am Projekt
B16: Auftragskosten netto (EU/EWR) [€] | C16: =_xlfn.LET(_xlpm.sum,SUM(C17:C26),IF(C9,_xlpm.sum,0)) -> 0 | D16: =_xlfn.LET(_xlpm.sum,SUM(D17:D26),IF(D9,_xlpm.sum,0)) -> 0 | E16: =_xlfn.LET(_xlpm.sum,SUM(E17:E26),IF(E9,_xlpm.sum,0)) -> 0 | F16: {=_xlfn.LET(_xlpm.sum,SUM(F17:F26),IF(F9,_xlpm.sum,0))} -> 0 | G16: =_xlfn.LET(_xlpm.sum,SUM(G17:G26),IF(G9,_xlpm.sum,0)) -> 0 | H16: =_xlfn.LET(_xlpm.sum,SUM(H17:H26),IF(H9,_xlpm.sum,0)) -> 0 | I16: =_xlfn.LET(_xlpm.sum,SUM(I17:I26),IF(I9,_xlpm.sum,0)) -> 0 | J16: =_xlfn.LET(_xlpm.sum,SUM(J17:J26),IF(J9,_xlpm.sum,0)) -> 0 | O16: Auftragskosten netto (EU/EWR) [€] | P16: =_xlfn.LET(_xlpm.sum,SUM(P17:P26),IF(P9,_xlpm.sum,0)) -> 0 | Q16: =_xlfn.LET(_xlpm.sum,SUM(Q17:Q26),IF(Q9,_xlpm.sum,0)) -> 0 | R16: =_xlfn.LET(_xlpm.sum,SUM(R17:R26),IF(R9,_xlpm.sum,0)) -> 0 | S16: =_xlfn.LET(_xlpm.sum,SUM(S17:S26),IF(S9,_xlpm.sum,0)) -> 0 | T16: =_xlfn.LET(_xlpm.sum,SUM(T17:T26),IF(T9,_xlpm.sum,0)) -> 0 | U16: =_xlfn.LET(_xlpm.sum,SUM(U17:U26),IF(U9,_xlpm.sum,0)) -> 0 | V16: =_xlfn.LET(_xlpm.sum,SUM(V17:V26),IF(V9,_xlpm.sum,0)) -> 0 | W16: =_xlfn.LET(_xlpm.sum,SUM(W17:W26),IF(W9,_xlpm.sum,0)) -> 0 | AB16: Auftragskosten netto (EU/EWR) [€] | AC16: =_xlfn.LET(_xlpm.sum,SUM(AC17:AC26),IF(AC9,_xlpm.sum,0)) -> 0 | AD16: =_xlfn.LET(_xlpm.sum,SUM(AD17:AD26),IF(AD9,_xlpm.sum,0)) -> 0 | AE16: =_xlfn.LET(_xlpm.sum,SUM(AE17:AE26),IF(AE9,_xlpm.sum,0)) -> 0 | AF16: =_xlfn.LET(_xlpm.sum,SUM(AF17:AF26),IF(AF9,_xlpm.sum,0)) -> 0 | AG16: =_xlfn.LET(_xlpm.sum,SUM(AG17:AG26),IF(AG9,_xlpm.sum,0)) -> 0 | AH16: =_xlfn.LET(_xlpm.sum,SUM(AH17:AH26),IF(AH9,_xlpm.sum,0)) -> 0 | AI16: =_xlfn.LET(_xlpm.sum,SUM(AI17:AI26),IF(AI9,_xlpm.sum,0)) -> 0 | AJ16: =_xlfn.LET(_xlpm.sum,SUM(AJ17:AJ26),IF(AJ9,_xlpm.sum,0)) -> 0 | AO16: Auftragskosten netto (EU/EWR) [€] | AP16: =_xlfn.LET(_xlpm.sum,SUM(AP17:AP26),IF(AP9,_xlpm.sum,0)) -> 0 | AQ16: =_xlfn.LET(_xlpm.sum,SUM(AQ17:AQ26),IF(AQ9,_xlpm.sum,0)) -> 0 | AR16: =_xlfn.LET(_xlpm.sum,SUM(AR17:AR26),IF(AR9,_xlpm.sum,0)) -> 0 | AS16: =_xlfn.LET(_xlpm.sum,SUM(AS17:AS26),IF(AS9,_xlpm.sum,0)) -> 0 | AT16: =_xlfn.LET(_xlpm.sum,SUM(AT17:AT26),IF(AT9,_xlpm.sum,0)) -> 0 | AU16: =_xlfn.LET(_xlpm.sum,SUM(AU17:AU26),IF(AU9,_xlpm.sum,0)) -> 0 | AV16: =_xlfn.LET(_xlpm.sum,SUM(AV17:AV26),IF(AV9,_xlpm.sum,0)) -> 0 | AW16: =_xlfn.LET(_xlpm.sum,SUM(AW17:AW26),IF(AW9,_xlpm.sum,0)) -> 0 | BB16: Auftragskosten netto (EU/EWR) [€] | BC16: =_xlfn.LET(_xlpm.sum,SUM(BC17:BC26),IF(BC9,_xlpm.sum,0)) -> 0 | BD16: =_xlfn.LET(_xlpm.sum,SUM(BD17:BD26),IF(BD9,_xlpm.sum,0)) -> 0 | BE16: =_xlfn.LET(_xlpm.sum,SUM(BE17:BE26),IF(BE9,_xlpm.sum,0)) -> 0 | BF16: =_xlfn.LET(_xlpm.sum,SUM(BF17:BF26),IF(BF9,_xlpm.sum,0)) -> 0 | BG16: =_xlfn.LET(_xlpm.sum,SUM(BG17:BG26),IF(BG9,_xlpm.sum,0)) -> 0 | BH16: =_xlfn.LET(_xlpm.sum,SUM(BH17:BH26),IF(BH9,_xlpm.sum,0)) -> 0 | BI16: =_xlfn.LET(_xlpm.sum,SUM(BI17:BI26),IF(BI9,_xlpm.sum,0)) -> 0 | BJ16: =_xlfn.LET(_xlpm.sum,SUM(BJ17:BJ26),IF(BJ9,_xlpm.sum,0)) -> 0 | BO16: Auftragskosten netto (EU/EWR) [€] | BP16: =_xlfn.LET(_xlpm.sum,SUM(BP17:BP26),IF(BP9,_xlpm.sum,0)) -> 0 | BQ16: =_xlfn.LET(_xlpm.sum,SUM(BQ17:BQ26),IF(BQ9,_xlpm.sum,0)) -> 0 | BR16: =_xlfn.LET(_xlpm.sum,SUM(BR17:BR26),IF(BR9,_xlpm.sum,0)) -> 0 | BS16: =_xlfn.LET(_xlpm.sum,SUM(BS17:BS26),IF(BS9,_xlpm.sum,0)) -> 0 | BT16: =_xlfn.LET(_xlpm.sum,SUM(BT17:BT26),IF(BT9,_xlpm.sum,0)) -> 0 | BU16: =_xlfn.LET(_xlpm.sum,SUM(BU17:BU26),IF(BU9,_xlpm.sum,0)) -> 0 | BV16: =_xlfn.LET(_xlpm.sum,SUM(BV17:BV26),IF(BV9,_xlpm.sum,0)) -> 0 | BW16: =_xlfn.LET(_xlpm.sum,SUM(BW17:BW26),IF(BW9,_xlpm.sum,0)) -> 0 | CB16: Auftragskosten netto (EU/EWR) [€] | CC16: =_xlfn.LET(_xlpm.sum,SUM(CC17:CC26),IF(CC9,_xlpm.sum,0)) -> 0 | CD16: =_xlfn.LET(_xlpm.sum,SUM(CD17:CD26),IF(CD9,_xlpm.sum,0)) -> 0 | CE16: =_xlfn.LET(_xlpm.sum,SUM(CE17:CE26),IF(CE9,_xlpm.sum,0)) -> 0 | CF16: =_xlfn.LET(_xlpm.sum,SUM(CF17:CF26),IF(CF9,_xlpm.sum,0)) -> 0 | CG16: =_xlfn.LET(_xlpm.sum,SUM(CG17:CG26),IF(CG9,_xlpm.sum,0)) -> 0 | CH16: =_xlfn.LET(_xlpm.sum,SUM(CH17:CH26),IF(CH9,_xlpm.sum,0)) -> 0 | CI16: =_xlfn.LET(_xlpm.sum,SUM(CI17:CI26),IF(CI9,_xlpm.sum,0)) -> 0 | CJ16: =_xlfn.LET(_xlpm.sum,SUM(CJ17:CJ26),IF(CJ9,_xlpm.sum,0)) -> 0
B17: Auftragnehmer 1 | O17: Auftragnehmer 1 | AB17: Auftragnehmer 1 | AO17: Auftragnehmer 1 | BB17: Auftragnehmer 1 | BO17: Auftragnehmer 1 | CB17: Auftragnehmer 1
B18: Auftragnehmer 2 | O18: Auftragnehmer 2 | AB18: Auftragnehmer 2 | AO18: Auftragnehmer 2 | BB18: Auftragnehmer 2 | BO18: Auftragnehmer 2 | CB18: Auftragnehmer 2
B19: Auftragnehmer 3 | O19: Auftragnehmer 3 | AB19: Auftragnehmer 3 | AO19: Auftragnehmer 3 | BB19: Auftragnehmer 3 | BO19: Auftragnehmer 3 | CB19: Auftragnehmer 3
B20: Auftragnehmer 4 | O20: Auftragnehmer 4 | AB20: Auftragnehmer 4 | AO20: Auftragnehmer 4 | BB20: Auftragnehmer 4 | BO20: Auftragnehmer 4 | CB20: Auftragnehmer 4
B21: Auftragnehmer 5 | O21: Auftragnehmer 5 | AB21: Auftragnehmer 5 | AO21: Auftragnehmer 5 | BB21: Auftragnehmer 5 | BO21: Auftragnehmer 5 | CB21: Auftragnehmer 5
B22: Auftragnehmer 6 | O22: Auftragnehmer 6 | AB22: Auftragnehmer 6 | AO22: Auftragnehmer 6 | BB22: Auftragnehmer 6 | BO22: Auftragnehmer 6 | CB22: Auftragnehmer 6
B23: Auftragnehmer 7 | O23: Auftragnehmer 7 | AB23: Auftragnehmer 7 | AO23: Auftragnehmer 7 | BB23: Auftragnehmer 7 | BO23: Auftragnehmer 7 | CB23: Auftragnehmer 7
B24: Auftragnehmer 8 | O24: Auftragnehmer 8 | AB24: Auftragnehmer 8 | AO24: Auftragnehmer 8 | BB24: Auftragnehmer 8 | BO24: Auftragnehmer 8 | CB24: Auftragnehmer 8
B25: Auftragnehmer 9 | O25: Auftragnehmer 9 | AB25: Auftragnehmer 9 | AO25: Auftragnehmer 9 | BB25: Auftragnehmer 9 | BO25: Auftragnehmer 9 | CB25: Auftragnehmer 9
B26: Auftragnehmer 10 | O26: Auftragnehmer 10 | AB26: Auftragnehmer 10 | AO26: Auftragnehmer 10 | BB26: Auftragnehmer 10 | BO26: Auftragnehmer 10 | CB26: Auftragnehmer 10
B27: Materialkosten netto (nicht förderfähig) [€] | O27: Materialkosten netto (nicht förderfähig) [€] | AB27: Materialkosten netto (nicht förderfähig) [€] | AO27: Materialkosten netto (nicht förderfähig) [€] | BB27: Materialkosten netto (nicht förderfähig) [€] | BO27: Materialkosten netto (nicht förderfähig) [€] | CB27: Materialkosten netto (nicht förderfähig) [€]
B28: Abschreibungswert Sachanlagen (förderfähig ab Projektstart am 28.03.2024) [€] | C28: =SUM(C29:C33) -> 0 | D28: =SUM(D29:D33) -> 0 | E28: =SUM(E29:E33) -> 0 | F28: =SUM(F29:F33) -> 0 | G28: =SUM(G29:G33) -> 0 | H28: =SUM(H29:H33) -> 0 | I28: =SUM(I29:I33) -> 0 | J28: =SUM(J29:J33) -> 0 | O28: Sachanlagen (förderfähig ab 28.03.2024) [€] | P28: =SUM(P29:P33) -> 0 | Q28: =SUM(Q29:Q33) -> 0 | R28: =SUM(R29:R33) -> 0 | S28: =SUM(S29:S33) -> 0 | T28: =SUM(T29:T33) -> 0 | U28: =SUM(U29:U33) -> 0 | V28: =SUM(V29:V33) -> 0 | W28: =SUM(W29:W33) -> 0 | AB28: Sachanlagen (förderfähig ab 28.03.2024) [€] | AC28: =SUM(AC29:AC33) -> 0 | AD28: =SUM(AD29:AD33) -> 0 | AE28: =SUM(AE29:AE33) -> 0 | AF28: =SUM(AF29:AF33) -> 0 | AG28: =SUM(AG29:AG33) -> 0 | AH28: =SUM(AH29:AH33) -> 0 | AI28: =SUM(AI29:AI33) -> 0 | AJ28: =SUM(AJ29:AJ33) -> 0 | AO28: Sachanlagen (förderfähig ab 28.03.2024) [€] | AP28: =SUM(AP29:AP33) -> 0 | AQ28: =SUM(AQ29:AQ33) -> 0 | AR28: =SUM(AR29:AR33) -> 0 | AS28: =SUM(AS29:AS33) -> 0 | AT28: =SUM(AT29:AT33) -> 0 | AU28: =SUM(AU29:AU33) -> 0 | AV28: =SUM(AV29:AV33) -> 0 | AW28: =SUM(AW29:AW33) -> 0 | BB28: Sachanlagen (förderfähig ab 28.03.2024) [€] | BC28: =SUM(BC29:BC33) -> 0 | BD28: =SUM(BD29:BD33) -> 0 | BE28: =SUM(BE29:BE33) -> 0 | BF28: =SUM(BF29:BF33) -> 0 | BG28: =SUM(BG29:BG33) -> 0 | BH28: =SUM(BH29:BH33) -> 0 | BI28: =SUM(BI29:BI33) -> 0 | BJ28: =SUM(BJ29:BJ33) -> 0 | BO28: Sachanlagen (förderfähig ab 28.03.2024) [€] | BP28: =SUM(BP29:BP33) -> 0 | BQ28: =SUM(BQ29:BQ33) -> 0 | BR28: =SUM(BR29:BR33) -> 0 | BS28: =SUM(BS29:BS33) -> 0 | BT28: =SUM(BT29:BT33) -> 0 | BU28: =SUM(BU29:BU33) -> 0 | BV28: =SUM(BV29:BV33) -> 0 | BW28: =SUM(BW29:BW33) -> 0 | CB28: Sachanlagen (förderfähig ab 28.03.2024) [€] | CC28: =SUM(CC29:CC33) -> 0 | CD28: =SUM(CD29:CD33) -> 0 | CE28: =SUM(CE29:CE33) -> 0 | CF28: =SUM(CF29:CF33) -> 0 | CG28: =SUM(CG29:CG33) -> 0 | CH28: =SUM(CH29:CH33) -> 0 | CI28: =SUM(CI29:CI33) -> 0 | CJ28: =SUM(CJ29:CJ33) -> 0
B29: Sachanlage 1 | O29: Sachanlage 1 | AB29: Sachanlage 1 | AO29: Sachanlage 1 | BB29: Sachanlage 1 | BO29: Sachanlage 1 | CB29: Sachanlage 1
B30: Sachanlage 2 | O30: Sachanlage 2 | AB30: Sachanlage 2 | AO30: Sachanlage 2 | BB30: Sachanlage 2 | BO30: Sachanlage 2 | CB30: Sachanlage 2
B31: Sachanlage 3 | O31: Sachanlage 3 | AB31: Sachanlage 3 | AO31: Sachanlage 3 | BB31: Sachanlage 3 | BO31: Sachanlage 3 | CB31: Sachanlage 3
B32: Sachanlage 4 | O32: Sachanlage 4 | AB32: Sachanlage 4 | AO32: Sachanlage 4 | BB32: Sachanlage 4 | BO32: Sachanlage 4 | CB32: Sachanlage 4
B33: Sachanlage 5 | O33: Sachanlage 5 | AB33: Sachanlage 5 | AO33: Sachanlage 5 | BB33: Sachanlage 5 | BO33: Sachanlage 5 | CB33: Sachanlage 5
B34: Gesamtkosten [€] | C34: =C27+C16+C11+C28 -> 0 | D34: =D27+D16+D11+D28 -> 0 | E34: =E27+E16+E11+E28 -> 0 | F34: =F27+F16+F11+F28 -> 0 | G34: =G27+G16+G11+G28 -> 2730 | H34: =H27+H16+H11+H28 -> 8190 | I34: =I27+I16+I11+I28 -> 16380 | J34: =J27+J16+J11+J28 -> 0 | O34: Gesamtkosten [€] | P34: =P27+P16+P11+P28 -> 0 | Q34: =Q27+Q16+Q11+Q28 -> 0 | R34: =R27+R16+R11+R28 -> 0 | S34: =S27+S16+S11+S28 -> 0 | T34: =T27+T16+T11+T28 -> 0 | U34: =U27+U16+U11+U28 -> 0 | V34: =V27+V16+V11+V28 -> 0 | W34: =W27+W16+W11+W28 -> 0 | AB34: Gesamtkosten [€] | AC34: =AC27+AC16+AC11+AC28 -> 0 | AD34: =AD27+AD16+AD11+AD28 -> 0 | AE34: =AE27+AE16+AE11+AE28 -> 0 | AF34: =AF27+AF16+AF11+AF28 -> 0 | AG34: =AG27+AG16+AG11+AG28 -> 0 | AH34: =AH27+AH16+AH11+AH28 -> 0 | AI34: =AI27+AI16+AI11+AI28 -> 0 | AJ34: =AJ27+AJ16+AJ11+AJ28 -> 0 | AO34: Gesamtkosten [€] | AP34: =AP27+AP16+AP11+AP28 -> 0 | AQ34: =AQ27+AQ16+AQ11+AQ28 -> 0 | AR34: =AR27+AR16+AR11+AR28 -> 0 | AS34: =AS27+AS16+AS11+AS28 -> 0 | AT34: =AT27+AT16+AT11+AT28 -> 0 | AU34: =AU27+AU16+AU11+AU28 -> 0 | AV34: =AV27+AV16+AV11+AV28 -> 0 | AW34: =AW27+AW16+AW11+AW28 -> 0 | BB34: Gesamtkosten [€] | BC34: =BC27+BC16+BC11+BC28 -> 0 | BD34: =BD27+BD16+BD11+BD28 -> 0 | BE34: =BE27+BE16+BE11+BE28 -> 0 | BF34: =BF27+BF16+BF11+BF28 -> 0 | BG34: =BG27+BG16+BG11+BG28 -> 0 | BH34: =BH27+BH16+BH11+BH28 -> 0 | BI34: =BI27+BI16+BI11+BI28 -> 0 | BJ34: =BJ27+BJ16+BJ11+BJ28 -> 0 | BO34: Gesamtkosten [€] | BP34: =BP27+BP16+BP11+BP28 -> 0 | BQ34: =BQ27+BQ16+BQ11+BQ28 -> 0 | BR34: =BR27+BR16+BR11+BR28 -> 0 | BS34: =BS27+BS16+BS11+BS28 -> 0 | BT34: =BT27+BT16+BT11+BT28 -> 0 | BU34: =BU27+BU16+BU11+BU28 -> 0 | BV34: =BV27+BV16+BV11+BV28 -> 0 | BW34: =BW27+BW16+BW11+BW28 -> 0 | CB34: Gesamtkosten [€] | CC34: =CC27+CC16+CC11+CC28 -> 0 | CD34: =CD27+CD16+CD11+CD28 -> 0 | CE34: =CE27+CE16+CE11+CE28 -> 0 | CF34: =CF27+CF16+CF11+CF28 -> 0 | CG34: =CG27+CG16+CG11+CG28 -> 0 | CH34: =CH27+CH16+CH11+CH28 -> 0 | CI34: =CI27+CI16+CI11+CI28 -> 0 | CJ34: =CJ27+CJ16+CJ11+CJ28 -> 0
B35: Wurden/Werden die Personalkosten und/oder Auftragskosten für Aufträge innerhalb der EU/des EWR für dieses FuE-Vorhaben im Rahmen anderer Förderungen oder staatlicher Beihilfen gefördert? | E35: nein | G35: nein | H35: nein | I35: nein | O35: Wurden/Werden die Personalkosten und/oder Auftragskosten für Aufträge innerhalb der EU/des EWR für dieses FuE-Vorhaben im Rahmen anderer Förderungen oder staatlicher Beihilfen gefördert? | AB35: Wurden/Werden die Personalkosten und/oder Auftragskosten für Aufträge innerhalb der EU/des EWR für dieses FuE-Vorhaben im Rahmen anderer Förderungen oder staatlicher Beihilfen gefördert? | AO35: Wurden/Werden die Personalkosten und/oder Auftragskosten für Aufträge innerhalb der EU/des EWR für dieses FuE-Vorhaben im Rahmen anderer Förderungen oder staatlicher Beihilfen gefördert? | BB35: Wurden/Werden die Personalkosten und/oder Auftragskosten für Aufträge innerhalb der EU/des EWR für dieses FuE-Vorhaben im Rahmen anderer Förderungen oder staatlicher Beihilfen gefördert? | BO35: Wurden/Werden die Personalkosten und/oder Auftragskosten für Aufträge innerhalb der EU/des EWR für dieses FuE-Vorhaben im Rahmen anderer Förderungen oder staatlicher Beihilfen gefördert? | CB35: Wurden/Werden die Personalkosten und/oder Auftragskosten für Aufträge innerhalb der EU/des EWR für dieses FuE-Vorhaben im Rahmen anderer Förderungen oder staatlicher Beihilfen gefördert?
B36: Öffentliche Förderungen für dieses FuE-Vorhaben [€] | K36: Summe | O36: Öffentliche Förderungen für dieses FuE-Vorhaben [€] | X36: Summe | AB36: Öffentliche Förderungen für dieses FuE-Vorhaben [€] | AK36: Summe | AO36: Öffentliche Förderungen für dieses FuE-Vorhaben [€] | AX36: Summe | BB36: Öffentliche Förderungen für dieses FuE-Vorhaben [€] | BK36: Summe | BO36: Öffentliche Förderungen für dieses FuE-Vorhaben [€] | BX36: Summe | CB36: Öffentliche Förderungen für dieses FuE-Vorhaben [€] | CK36: Summe
B37: Gesamtkosten | C37: =IF(C9,C11+C14+C16,0) -> 0 | D37: =IF(D9,D11+D14+D16,0) -> 0 | E37: =IF(E9,E11+E14+E16,0) -> 0 | F37: =IF(F9,F11+F14+F16,0) -> 0 | G37: =IF(G9,G11+G14+G16,0) -> 44730 | H37: =IF(H9,H11+H14+H16,0) -> 112190 | I37: =IF(I9,I11+I14+I16,0) -> 120380 | J37: =IF(J9,J11+J14+J16+J28,0) -> 0 | K37: =SUM(C37:J37) -> 277300 | O37: Gesamtkosten | P37: =IF(P9,P11+P14+P16,0) -> 0 | Q37: =IF(Q9,Q11+Q14+Q16,0) -> 0 | R37: =IF(R9,R11+R14+R16,0) -> 0 | S37: =IF(S9,S11+S14+S16,0) -> 0 | T37: =IF(T9,T11+T14+T16,0) -> 0 | U37: =IF(U9,U11+U14+U16,0) -> 0 | V37: =IF(V9,V11+V14+V16,0) -> 0 | W37: =IF(W9,W11+W14+W16+W28,0) -> 0 | X37: =SUM(P37:W37) -> 0 | AB37: Gesamtkosten | AC37: =IF(AC9,AC11+AC14+AC16,0) -> 0 | AD37: =IF(AD9,AD11+AD14+AD16,0) -> 0 | AE37: =IF(AE9,AE11+AE14+AE16,0) -> 0 | AF37: =IF(AF9,AF11+AF14+AF16,0) -> 0 | AG37: =IF(AG9,AG11+AG14+AG16,0) -> 0 | AH37: =IF(AH9,AH11+AH14+AH16,0) -> 0 | AI37: =IF(AI9,AI11+AI14+AI16,0) -> 0 | AJ37: =IF(AJ9,AJ11+AJ14+AJ16+AJ28,0) -> 0 | AK37: =SUM(AC37:AJ37) -> 0 | AO37: Gesamtkosten | AP37: =IF(AP9,AP11+AP14+AP16,0) -> 0 | AQ37: =IF(AQ9,AQ11+AQ14+AQ16,0) -> 0 | AR37: =IF(AR9,AR11+AR14+AR16,0) -> 0 | AS37: =IF(AS9,AS11+AS14+AS16,0) -> 0 | AT37: =IF(AT9,AT11+AT14+AT16,0) -> 0 | AU37: =IF(AU9,AU11+AU14+AU16,0) -> 0 | AV37: =IF(AV9,AV11+AV14+AV16,0) -> 0 | AW37: =IF(AW9,AW11+AW14+AW16+AW28,0) -> 0 | AX37: =SUM(AP37:AW37) -> 0 | BB37: Gesamtkosten | BC37: =IF(BC9,BC11+BC14+BC16,0) -> 0 | BD37: =IF(BD9,BD11+BD14+BD16,0) -> 0 | BE37: =IF(BE9,BE11+BE14+BE16,0) -> 0 | BF37: =IF(BF9,BF11+BF14+BF16,0) -> 0 | BG37: =IF(BG9,BG11+BG14+BG16,0) -> 0 | BH37: =IF(BH9,BH11+BH14+BH16,0) -> 0 | BI37: =IF(BI9,BI11+BI14+BI16,0) -> 0 | BJ37: =IF(BJ9,BJ11+BJ14+BJ16+BJ28,0) -> 0 | BK37: =SUM(BC37:BJ37) -> 0 | BO37: Gesamtkosten | BP37: =IF(BP9,BP11+BP14+BP16,0) -> 0 | BQ37: =IF(BQ9,BQ11+BQ14+BQ16,0) -> 0 | BR37: =IF(BR9,BR11+BR14+BR16,0) -> 0 | BS37: =IF(BS9,BS11+BS14+BS16,0) -> 0 | BT37: =IF(BT9,BT11+BT14+BT16,0) -> 0 | BU37: =IF(BU9,BU11+BU14+BU16,0) -> 0 | BV37: =IF(BV9,BV11+BV14+BV16,0) -> 0 | BW37: =IF(BW9,BW11+BW14+BW16+BW28,0) -> 0 | BX37: =SUM(BP37:BW37) -> 0 | CB37: Gesamtkosten | CC37: =IF(CC9,CC11+CC14+CC16,0) -> 0 | CD37: =IF(CD9,CD11+CD14+CD16,0) -> 0 | CE37: =IF(CE9,CE11+CE14+CE16,0) -> 0 | CF37: =IF(CF9,CF11+CF14+CF16,0) -> 0 | CG37: =IF(CG9,CG11+CG14+CG16,0) -> 0 | CH37: =IF(CH9,CH11+CH14+CH16,0) -> 0 | CI37: =IF(CI9,CI11+CI14+CI16,0) -> 0 | CJ37: =IF(CJ9,CJ11+CJ14+CJ16+CJ28,0) -> 0 | CK37: =SUM(CC37:CJ37) -> 0
B38: Anteil förderfähiger Auftragnehmerkosten | C38: =IF(C7>=DATE(2024,3,27),70%,60%) -> 0.7 | D38: =IF(C7>=DATE(2024,3,27),70%,60%) -> 0.7 | E38: =IF(C7>=DATE(2024,3,27),70%,60%) -> 0.7 | F38: =IF(C7>=DATE(2024,3,27),70%,60%) -> 0.7 | G38: =IF(C7>=DATE(2024,3,27),70%,60%) -> 0.7 | H38: =IF(C7>=DATE(2024,3,27),70%,60%) -> 0.7 | I38: =IF(C7>=DATE(2024,3,27),70%,60%) -> 0.7 | J38: =IF(C7>=DATE(2024,3,27),70%,60%) -> 0.7 | O38: Anteil förderfähiger Auftragnehmerkosten | P38: =IF(P7>=DATE(2024,3,27),70%,60%) -> 0.7 | Q38: =IF(P7>=DATE(2024,3,27),70%,60%) -> 0.7 | R38: =IF(P7>=DATE(2024,3,27),70%,60%) -> 0.7 | S38: =IF(P7>=DATE(2024,3,27),70%,60%) -> 0.7 | T38: =IF(P7>=DATE(2024,3,27),70%,60%) -> 0.7 | U38: =IF(P7>=DATE(2024,3,27),70%,60%) -> 0.7 | V38: =IF(P7>=DATE(2024,3,27),70%,60%) -> 0.7 | W38: =IF(P7>=DATE(2024,3,27),70%,60%) -> 0.7 | AB38: Anteil förderfähiger Auftragnehmerkosten | AC38: =IF(AC7>=DATE(2024,3,27),70%,60%) -> 0.7 | AD38: =IF(AC7>=DATE(2024,3,27),70%,60%) -> 0.7 | AE38: =IF(AC7>=DATE(2024,3,27),70%,60%) -> 0.7 | AF38: =IF(AC7>=DATE(2024,3,27),70%,60%) -> 0.7 | AG38: =IF(AC7>=DATE(2024,3,27),70%,60%) -> 0.7 | AH38: =IF(AC7>=DATE(2024,3,27),70%,60%) -> 0.7 | AI38: =IF(AC7>=DATE(2024,3,27),70%,60%) -> 0.7 | AJ38: =IF(AC7>=DATE(2024,3,27),70%,60%) -> 0.7 | AO38: Anteil förderfähiger Auftragnehmerkosten | AP38: =IF(AP7>=DATE(2024,3,27),70%,60%) -> 0.7 | AQ38: =IF(AP7>=DATE(2024,3,27),70%,60%) -> 0.7 | AR38: =IF(AP7>=DATE(2024,3,27),70%,60%) -> 0.7 | AS38: =IF(AP7>=DATE(2024,3,27),70%,60%) -> 0.7 | AT38: =IF(AP7>=DATE(2024,3,27),70%,60%) -> 0.7 | AU38: =IF(AP7>=DATE(2024,3,27),70%,60%) -> 0.7 | AV38: =IF(AP7>=DATE(2024,3,27),70%,60%) -> 0.7 | AW38: =IF(AP7>=DATE(2024,3,27),70%,60%) -> 0.7 | BB38: Anteil förderfähiger Auftragnehmerkosten | BC38: =IF(BC7>=DATE(2024,3,27),70%,60%) -> 0.7 | BD38: =IF(BC7>=DATE(2024,3,27),70%,60%) -> 0.7 | BE38: =IF(BC7>=DATE(2024,3,27),70%,60%) -> 0.7 | BF38: =IF(BC7>=DATE(2024,3,27),70%,60%) -> 0.7 | BG38: =IF(BC7>=DATE(2024,3,27),70%,60%) -> 0.7 | BH38: =IF(BC7>=DATE(2024,3,27),70%,60%) -> 0.7 | BI38: =IF(BC7>=DATE(2024,3,27),70%,60%) -> 0.7 | BJ38: =IF(BC7>=DATE(2024,3,27),70%,60%) -> 0.7 | BO38: Anteil förderfähiger Auftragnehmerkosten | BP38: =IF(BP7>=DATE(2024,3,27),70%,60%) -> 0.7 | BQ38: =IF(BP7>=DATE(2024,3,27),70%,60%) -> 0.7 | BR38: =IF(BP7>=DATE(2024,3,27),70%,60%) -> 0.7 | BS38: =IF(BP7>=DATE(2024,3,27),70%,60%) -> 0.7 | BT38: =IF(BP7>=DATE(2024,3,27),70%,60%) -> 0.7 | BU38: =IF(BP7>=DATE(2024,3,27),70%,60%) -> 0.7 | BV38: =IF(BP7>=DATE(2024,3,27),70%,60%) -> 0.7 | BW38: =IF(BP7>=DATE(2024,3,27),70%,60%) -> 0.7 | CB38: Anteil förderfähiger Auftragnehmerkosten | CC38: =IF(CC7>=DATE(2024,3,27),70%,60%) -> 0.7 | CD38: =IF(CC7>=DATE(2024,3,27),70%,60%) -> 0.7 | CE38: =IF(CC7>=DATE(2024,3,27),70%,60%) -> 0.7 | CF38: =IF(CC7>=DATE(2024,3,27),70%,60%) -> 0.7 | CG38: =IF(CC7>=DATE(2024,3,27),70%,60%) -> 0.7 | CH38: =IF(CC7>=DATE(2024,3,27),70%,60%) -> 0.7 | CI38: =IF(CC7>=DATE(2024,3,27),70%,60%) -> 0.7 | CJ38: =IF(CC7>=DATE(2024,3,27),70%,60%) -> 0.7
B39: Förderfähige Projektkosten | C39: =IF(C9,C11+C14+C16*C38,0) -> 0 | D39: =IF(D9,D11+D14+D16*D38,0) -> 0 | E39: =IF(E9,E11+E14+E16*E38+E28,0) -> 0 | F39: =IF(F9,F11+F14+F16*F38+F28,0) -> 0 | G39: =IF(G9,G11+G14+G16*G38+G28,0) -> 44730 | H39: =IF(H9,H11+H14+H16*H38+H28,0) -> 112190 | I39: =IF(I9,I11+I14+I16*I38+I28,0) -> 120380 | J39: =IF(J9,J11+J14+J16*J38+J28,0) -> 0 | O39: Förderfähige Projektkosten | P39: =IF(P9,P11+P14+P16*P38,0) -> 0 | Q39: =IF(Q9,Q11+Q14+Q16*Q38,0) -> 0 | R39: =IF(R9,R11+R14+R16*R38+R28,0) -> 0 | S39: =IF(S9,S11+S14+S16*S38+S28,0) -> 0 | T39: =IF(T9,T11+T14+T16*T38+T28,0) -> 0 | U39: =IF(U9,U11+U14+U16*U38+U28,0) -> 0 | V39: =IF(V9,V11+V14+V16*V38+V28,0) -> 0 | W39: =IF(W9,W11+W14+W16*W38+W28,0) -> 0 | AB39: Förderfähige Projektkosten | AC39: =IF(AC9,AC11+AC14+AC16*AC38,0) -> 0 | AD39: =IF(AD9,AD11+AD14+AD16*AD38,0) -> 0 | AE39: =IF(AE9,AE11+AE14+AE16*AE38+AE28,0) -> 0 | AF39: =IF(AF9,AF11+AF14+AF16*AF38+AF28,0) -> 0 | AG39: =IF(AG9,AG11+AG14+AG16*AG38+AG28,0) -> 0 | AH39: =IF(AH9,AH11+AH14+AH16*AH38+AH28,0) -> 0 | AI39: =IF(AI9,AI11+AI14+AI16*AI38+AI28,0) -> 0 | AJ39: =IF(AJ9,AJ11+AJ14+AJ16*AJ38+AJ28,0) -> 0 | AO39: Förderfähige Projektkosten | AP39: =IF(AP9,AP11+AP14+AP16*AP38,0) -> 0 | AQ39: =IF(AQ9,AQ11+AQ14+AQ16*AQ38,0) -> 0 | AR39: =IF(AR9,AR11+AR14+AR16*AR38+AR28,0) -> 0 | AS39: =IF(AS9,AS11+AS14+AS16*AS38+AS28,0) -> 0 | AT39: =IF(AT9,AT11+AT14+AT16*AT38+AT28,0) -> 0 | AU39: =IF(AU9,AU11+AU14+AU16*AU38+AU28,0) -> 0 | AV39: =IF(AV9,AV11+AV14+AV16*AV38+AV28,0) -> 0 | AW39: =IF(AW9,AW11+AW14+AW16*AW38+AW28,0) -> 0 | BB39: Förderfähige Projektkosten | BC39: =IF(BC9,BC11+BC14+BC16*BC38,0) -> 0 | BD39: =IF(BD9,BD11+BD14+BD16*BD38,0) -> 0 | BE39: =IF(BE9,BE11+BE14+BE16*BE38+BE28,0) -> 0 | BF39: =IF(BF9,BF11+BF14+BF16*BF38+BF28,0) -> 0 | BG39: =IF(BG9,BG11+BG14+BG16*BG38+BG28,0) -> 0 | BH39: =IF(BH9,BH11+BH14+BH16*BH38+BH28,0) -> 0 | BI39: =IF(BI9,BI11+BI14+BI16*BI38+BI28,0) -> 0 | BJ39: =IF(BJ9,BJ11+BJ14+BJ16*BJ38+BJ28,0) -> 0 | BO39: Förderfähige Projektkosten | BP39: =IF(BP9,BP11+BP14+BP16*BP38,0) -> 0 | BQ39: =IF(BQ9,BQ11+BQ14+BQ16*BQ38,0) -> 0 | BR39: =IF(BR9,BR11+BR14+BR16*BR38+BR28,0) -> 0 | BS39: =IF(BS9,BS11+BS14+BS16*BS38+BS28,0) -> 0 | BT39: =IF(BT9,BT11+BT14+BT16*BT38+BT28,0) -> 0 | BU39: =IF(BU9,BU11+BU14+BU16*BU38+BU28,0) -> 0 | BV39: =IF(BV9,BV11+BV14+BV16*BV38+BV28,0) -> 0 | BW39: =IF(BW9,BW11+BW14+BW16*BW38+BW28,0) -> 0 | CB39: Förderfähige Projektkosten | CC39: =IF(CC9,CC11+CC14+CC16*CC38,0) -> 0 | CD39: =IF(CD9,CD11+CD14+CD16*CD38,0) -> 0 | CE39: =IF(CE9,CE11+CE14+CE16*CE38+CE28,0) -> 0 | CF39: =IF(CF9,CF11+CF14+CF16*CF38+CF28,0) -> 0 | CG39: =IF(CG9,CG11+CG14+CG16*CG38+CG28,0) -> 0 | CH39: =IF(CH9,CH11+CH14+CH16*CH38+CH28,0) -> 0 | CI39: =IF(CI9,CI11+CI14+CI16*CI38+CI28,0) -> 0 | CJ39: =IF(CJ9,CJ11+CJ14+CJ16*CJ38+CJ28,0) -> 0
